Workbook

Sheet 작성 규칙
A1: 작성 규칙
A2: 탭 구성 | B2: 작성 규칙 / 변경 이력 / 요약 / 사용자 / 입력 / 분석 / 챗봇 / 실천·보상 / 마스터 — 규칙과 변경 이력을 먼저 확인한 뒤 영역(담당자)별 탭을 수정
A3: 다이어그램 | B3: 같은 폴더의 ERD_6기_5팀_v1.0.dbml을 dbdiagram.io에 붙여넣으면 관계도가 그려짐. 테이블 · 필드를 바꾸면 dbml과 이 엑셀을 함께 고침
A4: 키 | B4: PK 기본키 · FK 외래키(참조 칸에 대상 테이블.필드) · UQ 유일값
A5: 필수 | B5: Y = NOT NULL 또는 PK / N = 비어 있어도 됨
A6: 변경 | B6: v0.1 대비 — 기존 / 수정 (노란 배경) / 신규 (파란 배경)
A7: 최종 수정 | B7: 그 필드가 마지막으로 바뀐 버전. 바꿀 때마다 변경 이력 탭에 버전 요약 한 줄 + 위치 · 현행(As-Is) · 개정(To-Be) 세부 행을 추가 — 현행에는 바꾸기 전 정의(타입 · 키 · 필수 · 설명)를 그대로 적음
A8: 확인 필요 | B8: 🟡 = 담당자 확인 필요 (설명에 누구 확인인지 적음)
A9: 설계 원칙 | B9: 1. 외부 공공데이터는 "마스터"로 분리해 사전 적재 (요청 시 API 호출 안 함) 2. DUR 규칙은 성분 단위로 정규화 (제품 87만행 → 성분 9.7만쌍) 3. 민감정보는 최소 저장 (원본 이미지 미저장, 식별정보 마스킹) 4. 조인 키: 심평원 제품코드(EDI) = 식약처 EDI_CODE 5. 안전성 경고는 DB 조회 결과만 저장 (AI 생성 아님)

Sheet 변경 이력
A1: 변경 이력
A2: ※ 왼쪽 행 번호 옆 [+] / [-] 버튼으로 세부사항을 펼치고 접을 수 있습니다. 바꿀 때마다 버전 요약 한 줄 + 아래에 위치 · 현행(As-Is) · 개정(To-Be)을 적고, 현행에는 바꾸기 전 값을 그대로 남겨 주세요.
A3: 버전 | B3: 일자 | C3: 변경 내용 | E3: 담당
A4: v0.1 | B4: 2026-09-22 | C4: 최초 작성 — 마스터 영역 확정, 사용자 · 입력 · 분석 · 챗봇 영역 초안 (dbml) | E4: 이형준
A5: v1.0 | B5: 2026-09-24 | C5: 통합 와이어프레임(45개 화면) · API 명세서 v1.0 · 요구사항 v1.0 기준 반영 — 테이블 9개 신규(실천 · 보상 4개 포함), 분석:처방전 1:N, 처방전 질병코드 N개, analyses 단계 · 재시도, 로그인 잠금 · 동의 기록 등 | E5: 이형준
B6: 위치 | C6: 현행 (As-Is) | D6: 개정 (To-Be)
B7: users / login_id — 설명 변경 | C7: login_id varchar(100) · UQ · NOT NULL — 이메일 또는 소셜 ID | D7: login_id varchar(100) · UQ · NOT NULL — 이메일 사유: 소셜 로그인 제외, 이메일 가입만
B8: users / password_hash — 정의 변경 | C8: password_hash varchar(255) — 소셜 로그인 시 null | D8: password_hash varchar(255) · NOT NULL 사유: 소셜 로그인 제외 → 항상 필요
B9: users / nickname — 설명 변경 | C9: nickname varchar(50) | D9: nickname varchar(50) — 선택 입력. 홈 인사말용
B10: users / birth_year — 정의 변경 | C10: birth_year smallint — 생년월일 대신 출생연도만 (최소 수집) | D10: birth_year smallint · NOT NULL — 생년월일 대신 출생연도만 (최소 수집) · 노인주의 · 연령금기 판정
B11: users / sex — 정의 변경 | C11: sex varchar(1) — M / F | D11: sex varchar(1) · NOT NULL — M / F
B12: users / failed_login_count — 필드 추가 | C12: (없음) | D12: failed_login_count smallint · 기본값 0 — v1.0 · 5회 실패 시 잠금 (CM-01-E1) 사유: A-2 · REQ-002 — 5회 실패 10분 잠금
B13: users / locked_until — 필드 추가 | C13: (없음) | D13: locked_until timestamp — v1.0 · 잠금 해제 시각 (CM-01-E2) 사유: A-2 · REQ-002
B14: users / updated_at — 필드 추가 | C14: (없음) | D14: updated_at timestamp
B15: users / deleted_at — 설명 변경 | C15: deleted_at timestamp — 탈퇴 시 소프트 삭제 후 개인정보 파기 | D15: deleted_at timestamp — 탈퇴 시 개인정보 파기 후 시각만 남김 (CM-07)
B16: users (회원) / 테이블 설명 | C16: 개인 식별정보는 최소로 수집. 성명·주민번호·연락처 미수집 | D16: 성명 · 주민번호 · 연락처 미수집
B17: user_consents (동의 기록) — 테이블 신규 | C17: (없음) | D17: 필드 6개: id, user_id, consent_type, agreed, agreed_at, withdrawn_at v1.0 신규 · CM-02 가입 동의, CM-05 동의 내역 사유: U-4 · U-5 · REQ-005 · 007 — 민감정보 별도 동의 기록
... B87: rewards (포인트) — 테이블 신규 | C87: (없음) | D87: 필드 7개: id, user_id, record_id, reward_type, points, reward_date, created_at 사유: REQ-113 [성규 확인 필요]

Sheet 요약
A1: ERD v1.0 · 5팀 · 진료 기록 기반 복약 안내 및 생활습관 개선 가이드 자동 생성 시스템
A2: 작성 2026-09-24 · 영역별로 담당자가 관리 · 테이블 수 · 필드 수는 각 탭에서 자동 집계 (행을 추가해도 반영됨)
A4: 탭 | B4: 담당 · 범위 | C4: 테이블 | D4: 필드 | E4: 신규 필드 | F4: 수정 필드
A5: 사용자 | B5: 형준 · 회원 · 동의 | C5: =SUMPRODUCT(('사용자'!$A$5:$A$300<>"")/COUNTIF('사용자'!$A$5:$A$300,'사용자'!$A$5:$A$300&"")) | D5: =COUNTA('사용자'!$C$5:$C$300) | E5: =COUNTIF('사용자'!$L$5:$L$300,"신규") | F5: =COUNTIF('사용자'!$L$5:$L$300,"수정")
A6: 입력 | B6: 채연 · 처방전 · 약봉투 · OCR · 약품 매칭 | C6: =SUMPRODUCT(('입력'!$A$5:$A$300<>"")/COUNTIF('입력'!$A$5:$A$300,'입력'!$A$5:$A$300&"")) | D6: =COUNTA('입력'!$C$5:$C$300) | E6: =COUNTIF('입력'!$L$5:$L$300,"신규") | F6: =COUNTIF('입력'!$L$5:$L$300,"수정")
A7: 분석 | B7: 형준 · 분석 작업 · 안전성 경고 · 안내문 · 피드백 | C7: =SUMPRODUCT(('분석'!$A$5:$A$300<>"")/COUNTIF('분석'!$A$5:$A$300,'분석'!$A$5:$A$300&"")) | D7: =COUNTA('분석'!$C$5:$C$300) | E7: =COUNTIF('분석'!$L$5:$L$300,"신규") | F7: =COUNTIF('분석'!$L$5:$L$300,"수정")
A8: 챗봇 | B8: 수인 · 대화 · 메시지 | C8: =SUMPRODUCT(('챗봇'!$A$5:$A$300<>"")/COUNTIF('챗봇'!$A$5:$A$300,'챗봇'!$A$5:$A$300&"")) | D8: =COUNTA('챗봇'!$C$5:$C$300) | E8: =COUNTIF('챗봇'!$L$5:$L$300,"신규") | F8: =COUNTIF('챗봇'!$L$5:$L$300,"수정")
A9: 실천·보상 | B9: 성규 · 추천 · 목표 · 기록 · 포인트 | C9: =SUMPRODUCT(('실천·보상'!$A$5:$A$300<>"")/COUNTIF('실천·보상'!$A$5:$A$300,'실천·보상'!$A$5:$A$300&"")) | D9: =COUNTA('실천·보상'!$C$5:$C$300) | E9: =COUNTIF('실천·보상'!$L$5:$L$300,"신규") | F9: =COUNTIF('실천·보상'!$L$5:$L$300,"수정")
A10: 마스터 | B10: 형준 · 공공데이터 사전 적재 (의약품 · DUR · 중복 · 질병 · 생활습관) | C10: =SUMPRODUCT(('마스터'!$A$5:$A$300<>"")/COUNTIF('마스터'!$A$5:$A$300,'마스터'!$A$5:$A$300&"")) | D10: =COUNTA('마스터'!$C$5:$C$300) | E10: =COUNTIF('마스터'!$L$5:$L$300,"신규") | F10: =COUNTIF('마스터'!$L$5:$L$300,"수정")
A11: 합계 | C11: =SUM(C5:C10) | D11: =SUM(D5:D10) | E11: =SUM(E5:E10) | F11: =SUM(F5:F10)

Sheet 사용자
A1: ERD v1.0 · 사용자
A2: 형준 · 회원 · 동의
A4: 테이블 (영문) | B4: 테이블 (한글) | C4: 필드 (영문) | D4: 필드 (한글) | E4: 타입 | F4: 키 | G4: 참조 | H4: 필수 | I4: 기본값 | J4: 설명 | K4: 관련 화면 · API | L4: 변경 | M4: 최종 수정 | N4: 비고 (테이블 설명)
A5: users | B5: 회원 | C5: id | D5: ID | E5: bigint | F5: PK | H5: Y | K5: CM-01~07 · A-1~3 · U-1~3 | L5: 기존 | M5: v0.1 | N5: 성명 · 주민번호 · 연락처 미수집
A6: users | B6: 회원 | C6: login_id | D6: 로그인 ID (이메일) | E6: varchar(100) | F6: UQ | H6: Y | J6: 이메일 | K6: CM-01~07 · A-1~3 · U-1~3 | L6: 수정 | M6: v1.0
A7: users | B7: 회원 | C7: password_hash | D7: 비밀번호 해시 | E7: varchar(255) | H7: Y | K7: CM-01~07 · A-1~3 · U-1~3 | L7: 수정 | M7: v1.0
A8: users | B8: 회원 | C8: nickname | D8: 이름 (별명) | E8: varchar(50) | H8: N | J8: 선택 입력. 홈 인사말용 | K8: CM-01~07 · A-1~3 · U-1~3 | L8: 수정 | M8: v1.0
A9: users | B9: 회원 | C9: birth_year | D9: 출생연도 | E9: smallint | H9: Y | J9: 생년월일 대신 출생연도만 (최소 수집) · 노인주의 · 연령금기 판정 | K9: CM-01~07 · A-1~3 · U-1~3 | L9: 수정 | M9: v1.0
A10: users | B10: 회원 | C10: sex | D10: 성별 | E10: varchar(1) | H10: Y | J10: M / F | K10: CM-01~07 · A-1~3 · U-1~3 | L10: 수정 | M10: v1.0
A11: users | B11: 회원 | C11: failed_login_count | D11: 로그인 실패 횟수 | E11: smallint | H11: N | I11: 0 | J11: 5회 실패 시 잠금 (CM-01-E1) | K11: CM-01~07 · A-1~3 · U-1~3 | L11: 신규 | M11: v1.0
A12: users | B12: 회원 | C12: locked_until | D12: 잠금 해제 시각 | E12: timestamp | H12: N | J12: 잠금 해제 시각 (CM-01-E2) | K12: CM-01~07 · A-1~3 · U-1~3 | L12: 신규 | M12: v1.0
A13: users | B13: 회원 | C13: created_at | D13: 생성 일시 | E13: timestamp | H13: N | I13: now() | K13: CM-01~07 · A-1~3 · U-1~3 | L13: 기존 | M13: v0.1
A14: users | B14: 회원 | C14: updated_at | D14: 수정 일시 | E14: timestamp | H14: N | K14: CM-01~07 · A-1~3 · U-1~3 | L14: 신규 | M14: v1.0
A15: users | B15: 회원 | C15: deleted_at | D15: 탈퇴 일시 | E15: timestamp | H15: N | J15: 탈퇴 시 개인정보 파기 후 시각만 남김 (CM-07) | K15: CM-01~07 · A-1~3 · U-1~3 | L15: 수정 | M15: v1.0
A16: user_consents | B16: 동의 기록 | C16: id | D16: ID | E16: bigint | F16: PK | H16: Y | K16: CM-02 · CM-05 · A-1 · U-4 · U-5 | L16: 신규 | M16: v1.0 | N16: v1.0 신규 · CM-02 가입 동의, CM-05 동의 내역
A17: user_consents | B17: 동의 기록 | C17: user_id | D17: 사용자 ID | E17: bigint | F17: FK | G17: users.id | H17: Y | K17: CM-02 · CM-05 · A-1 · U-4 · U-5 | L17: 신규 | M17: v1.0
A18: user_consents | B18: 동의 기록 | C18: consent_type | D18: 동의 종류 | E18: varchar(30) | H18: Y | J18: terms / privacy / sensitive_health | K18: CM-02 · CM-05 · A-1 · U-4 · U-5 | L18: 신규 | M18: v1.0
A19: user_consents | B19: 동의 기록 | C19: agreed | D19: 동의 여부 | E19: boolean | H19: Y | K19: CM-02 · CM-05 · A-1 · U-4 · U-5 | L19: 신규 | M19: v1.0
A20: user_consents | B20: 동의 기록 | C20: agreed_at | D20: 동의 일시 | E20: timestamp | H20: N | K20: CM-02 · CM-05 · A-1 · U-4 · U-5 | L20: 신규 | M20: v1.0
A21: user_consents | B21: 동의 기록 | C21: withdrawn_at | D21: 철회 일시 | E21: timestamp | H21: N | J21: 철회 시각. sensitive_health 철회 시 업로드 · 분석 불가 (🟡 기존 기록 처리 팀 결정) | K21: CM-02 · CM-05 · A-1 · U-4 · U-5 | L21: 신규 | M21: v1.0 | N21: 인덱스: (user_id, consent_type) [unique]

Sheet 입력
A1: ERD v1.0 · 입력
A2: 채연 · 처방전 · 약봉투 · OCR · 약품 매칭
A4: 테이블 (영문) | B4: 테이블 (한글) | C4: 필드 (영문) | D4: 필드 (한글) | E4: 타입 | F4: 키 | G4: 참조 | H4: 필수 | I4: 기본값 | J4: 설명 | K4: 관련 화면 · API | L4: 변경 | M4: 최종 수정 | N4: 비고 (테이블 설명)
A5: prescriptions | B5: 처방전 · 약봉투 | C5: id | D5: ID | E5: bigint | F5: PK | H5: Y | K5: OC-01 · OC-02 · O-1 · O-2 | L5: 기존 | M5: v0.1 | N5: 사진 1장 = 1행. 업로드된 원본 이미지는 OCR 처리 후 즉시 폐기
A6: prescriptions | B6: 처방전 · 약봉투 | C6: user_id | D6: 사용자 ID | E6: bigint | F6: FK | G6: users.id | H6: Y | K6: OC-01 · OC-02 · O-1 · O-2 | L6: 기존 | M6: v0.1
A7: prescriptions | B7: 처방전 · 약봉투 | C7: doc_type | D7: 문서 종류 | E7: varchar(20) | H7: Y | J7: prescription(처방전) / pill_bag(약봉투). 약봉투는 질병코드 없음 → RG-05-E1 | K7: OC-01 · OC-02 · O-1 · O-2 | L7: 신규 | M7: v1.0
A8: prescriptions | B8: 처방전 · 약봉투 | C8: issued_date | D8: 처방 교부일 | E8: date | H8: N | J8: 처방 교부일 | K8: OC-01 · OC-02 · O-1 · O-2 | L8: 기존 | M8: v0.1
A9: prescriptions | B9: 처방전 · 약봉투 | C9: hospital_name | D9: 병원 이름 | E9: varchar(200) | H9: N | K9: OC-01 · OC-02 · O-1 · O-2 | L9: 기존 | M9: v0.1
A10: prescriptions | B10: 처방전 · 약봉투 | C10: ocr_raw_text | D10: OCR 원문 | E10: text | H10: N | J10: OCR 원문 (원본 이미지는 저장하지 않음) · 암호화 | K10: OC-01 · OC-02 · O-1 · O-2 | L10: 수정 | M10: v1.0
A11: prescriptions | B11: 처방전 · 약봉투 | C11: ocr_confidence | D11: OCR 신뢰도 | E11: decimal(5,4) | H11: N | K11: OC-01 · OC-02 · O-1 · O-2 | L11: 기존 | M11: v0.1
A12: prescriptions | B12: 처방전 · 약봉투 | C12: quality_flag | D12: 사진 품질 표시 | E12: varchar(20) | H12: N | J12: ok / low (OC-01-E1에서 "그래도 계속 진행" 시) | K12: OC-01 · OC-02 · O-1 · O-2 | L12: 신규 | M12: v1.0
A13: prescriptions | B13: 처방전 · 약봉투 | C13: created_at | D13: 생성 일시 | E13: timestamp | H13: N | I13: now() | K13: OC-01 · OC-02 · O-1 · O-2 | L13: 기존 | M13: v0.1
A14: prescription_diseases | B14: 처방전 질병코드 | C14: prescription_id | D14: 처방전 ID | E14: bigint | F14: PK · FK | G14: prescriptions.id | H14: Y | K14: O-2 · R-4 | L14: 신규 | M14: v1.0 | N14: v1.0 신규 · 처방전 질병분류기호는 주상병 + 부상병 여러 개
A15: prescription_diseases | B15: 처방전 질병코드 | C15: disease_code | D15: 상병 코드 | E15: varchar(10) | F15: PK · FK | G15: diseases.code | H15: Y | K15: O-2 · R-4 | L15: 신규 | M15: v1.0
A16: prescription_diseases | B16: 처방전 질병코드 | C16: is_main | D16: 주상병 여부 | E16: boolean | H16: N | J16: 주상병 여부 | K16: O-2 · R-4 | L16: 신규 | M16: v1.0
A17: prescription_items | B17: 처방 약품 | C17: id | D17: ID | E17: bigint | F17: PK | H17: Y | K17: OC-02 · O-2 · O-3 | L17: 기존 | M17: v0.1 | N17: needs_confirm · unmatched가 남아 있으면 분석 시작 불가 (REQ-033). 1일 총량 = dose_per_time * times_per_day
A18: prescription_items | B18: 처방 약품 | C18: prescription_id | D18: 처방전 ID | E18: bigint | F18: FK | G18: prescriptions.id | H18: Y | K18: OC-02 · O-2 · O-3 | L18: 기존 | M18: v0.1
A19: prescription_items | B19: 처방 약품 | C19: edi_code | D19: EDI 제품코드 | E19: varchar(9) | F19: FK | G19: drug_products.edi_code | H19: N | J19: 매칭 실패 · 제외 시 null | K19: OC-02 · O-2 · O-3 | L19: 수정 | M19: v1.0
A20: prescription_items | B20: 처방 약품 | C20: raw_name | D20: 인식된 약품명 | E20: varchar(300) | H20: Y | J20: OCR이 읽은 원문 약품명 | K20: OC-02 · O-2 · O-3 | L20: 기존 | M20: v0.1
A21: prescription_items | B21: 처방 약품 | C21: match_score | D21: 매칭 점수 | E21: decimal(5,4) | H21: N | K21: OC-02 · O-2 · O-3 | L21: 수정 | M21: v1.0
A22: prescription_items | B22: 처방 약품 | C22: match_status | D22: 매칭 상태 | E22: varchar(20) | H22: Y | J22: auto / needs_confirm / user_confirmed / unmatched / excluded(빼고 진행) | K22: OC-02 · O-2 · O-3 | L22: 수정 | M22: v1.0
A23: prescription_items | B23: 처방 약품 | C23: dose_per_time | D23: 1회 투여량 | E23: decimal(10,3) | H23: N | K23: OC-02 · O-2 · O-3 | L23: 수정 | M23: v1.0
A24: prescription_items | B24: 처방 약품 | C24: times_per_day | D24: 1일 투여 횟수 | E24: smallint | H24: N | K24: OC-02 · O-2 · O-3 | L24: 수정 | M24: v1.0
A25: prescription_items | B25: 처방 약품 | C25: total_days | D25: 총 투약일수 | E25: smallint | H25: N | K25: OC-02 · O-2 · O-3 | L25: 수정 | M25: v1.0
A26: prescription_items | B26: 처방 약품 | C26: timing | D26: 복용 시점 | E26: varchar(50) | H26: N | J26: 아침 식후 등 | K26: OC-02 · O-2 · O-3 | L26: 수정 | M26: v1.0
A27: prescription_item_candidates | B27: 약품 매칭 후보 | C27: item_id | D27: 처방 약품 ID | E27: bigint | F27: PK · FK | G27: prescription_items.id | H27: Y | K27: OC-02 · O-3 | L27: 신규 | M27: v1.0 | N27: v1.0 신규 🟡 채연 확인 · OC-02 후보 목록. 매칭 정확도(1순위 적중률 · 5순위 내 포함률) 측정에 필요
A28: prescription_item_candidates | B28: 약품 매칭 후보 | C28: rank | D28: 순위 | E28: smallint | F28: PK | H28: Y | K28: OC-02 · O-3 | L28: 신규 | M28: v1.0
A29: prescription_item_candidates | B29: 약품 매칭 후보 | C29: edi_code | D29: EDI 제품코드 | E29: varchar(9) | F29: FK | G29: drug_products.edi_code | H29: N | K29: OC-02 · O-3 | L29: 신규 | M29: v1.0
A30: prescription_item_candidates | B30: 약품 매칭 후보 | C30: score | D30: 매칭 점수 | E30: decimal(5,4) | H30: N | K30: OC-02 · O-3 | L30: 신규 | M30: v1.0
A31: health_checkups | B31: 건강검진 (보류) | C31: id | D31: ID | E31: bigint | F31: PK | H31: Y | K31: REQ-015 | L31: 기존 | M31: v0.1 | N31: 보류 (REQ-015 · 멘토링 확인 후 결정)
A32: health_checkups | B32: 건강검진 (보류) | C32: user_id | D32: 사용자 ID | E32: bigint | F32: FK | G32: users.id | H32: Y | K32: REQ-015 | L32: 기존 | M32: v0.1
A33: health_checkups | B33: 건강검진 (보류) | C33: checkup_date | D33: 검진일 | E33: date | H33: N | K33: REQ-015 | L33: 기존 | M33: v0.1
A34: health_checkups | B34: 건강검진 (보류) | C34: ocr_raw_text | D34: OCR 원문 | E34: text | H34: N | K34: REQ-015 | L34: 기존 | M34: v0.1
A35: health_checkups | B35: 건강검진 (보류) | C35: created_at | D35: 생성 일시 | E35: timestamp | H35: N | I35: now() | K35: REQ-015 | L35: 기존 | M35: v0.1
A36: checkup_results | B36: 건강검진 결과 (보류) | C36: id | D36: ID | E36: bigint | F36: PK | H36: Y | K36: REQ-015 | L36: 기존 | M36: v0.1 | N36: 보류 (REQ-015)
A37: checkup_results | B37: 건강검진 결과 (보류) | C37: checkup_id | D37: 건강검진 ID | E37: bigint | F37: FK | G37: health_checkups.id | H37: Y | K37: REQ-015 | L37: 기존 | M37: v0.1
A38: checkup_results | B38: 건강검진 결과 (보류) | C38: item_code | D38: 검사 항목 코드 | E38: varchar(8) | F38: FK | G38: checkup_items.code | H38: N | K38: REQ-015 | L38: 수정 | M38: v1.0
A39: checkup_results | B39: 건강검진 결과 (보류) | C39: value_num | D39: 결과 수치 | E39: decimal(12,3) | H39: N | K39: REQ-015 | L39: 수정 | M39: v1.0
A40: checkup_results | B40: 건강검진 결과 (보류) | C40: value_text | D40: 결과 판정 | E40: varchar(200) | H40: N | K40: REQ-015 | L40: 수정 | M40: v1.0

Sheet 분석
A1: ERD v1.0 · 분석
A2: 형준 · 분석 작업 · 안전성 경고 · 안내문 · 피드백
A4: 테이블 (영문) | B4: 테이블 (한글) | C4: 필드 (영문) | D4: 필드 (한글) | E4: 타입 | F4: 키 | G4: 참조 | H4: 필수 | I4: 기본값 | J4: 설명 | K4: 관련 화면 · API | L4: 변경 | M4: 최종 수정 | N4: 비고 (테이블 설명)
A5: analyses | B5: 분석 작업 | C5: id | D5: ID | E5: bigint | F5: PK | H5: Y | K5: RG-01 · RG-01-E1 · CM-04 · R-1~3 · R-7 · R-8 | L5: 기존 | M5: v0.1 | N5: v1.0 · prescription_id 칸 삭제 → analysis_prescriptions로 1:N. job_id 대신 id로 폴링
A6: analyses | B6: 분석 작업 | C6: user_id | D6: 사용자 ID | E6: bigint | F6: FK | G6: users.id | H6: Y | K6: RG-01 · RG-01-E1 · CM-04 · R-1~3 · R-7 · R-8 | L6: 기존 | M6: v0.1
A7: analyses | B7: 분석 작업 | C7: status | D7: 상태 | E7: varchar(20) | H7: Y | J7: queued / running / done / failed | K7: RG-01 · RG-01-E1 · CM-04 · R-1~3 · R-7 · R-8 | L7: 수정 | M7: v1.0
A8: analyses | B8: 분석 작업 | C8: current_step | D8: 진행 단계 | E8: varchar(30) | H8: N | J8: drug_info / safety_check / guide_generation (RG-01 진행 단계) | K8: RG-01 · RG-01-E1 · CM-04 · R-1~3 · R-7 · R-8 | L8: 신규 | M8: v1.0
A9: analyses | B9: 분석 작업 | C9: failed_step | D9: 실패 단계 | E9: varchar(30) | H9: N | J9: 실패한 단계 (RG-01-E1) | K9: RG-01 · RG-01-E1 · CM-04 · R-1~3 · R-7 · R-8 | L9: 신규 | M9: v1.0
A10: analyses | B10: 분석 작업 | C10: error_code | D10: 에러 코드 | E10: varchar(50) | H10: N | J10: GUIDE_GENERATION_FAILED / SAFETY_CHECK_FAILED / TIMEOUT | K10: RG-01 · RG-01-E1 · CM-04 · R-1~3 · R-7 · R-8 | L10: 신규 | M10: v1.0
A11: analyses | B11: 분석 작업 | C11: retry_count | D11: 재시도 횟수 | E11: smallint | H11: N | I11: 0 | J11: 3회 초과 시 재시도 막음 (REQ-055) | K11: RG-01 · RG-01-E1 · CM-04 · R-1~3 · R-7 · R-8 | L11: 신규 | M11: v1.0
A12: analyses | B12: 분석 작업 | C12: user_birth_year | D12: 분석 시점 출생연도 | E12: smallint | H12: N | J12: 분석 시점 출생연도 스냅샷 — 정보 수정해도 지난 결과는 그대로 (CM-06) | K12: RG-01 · RG-01-E1 · CM-04 · R-1~3 · R-7 · R-8 | L12: 신규 | M12: v1.0
A13: analyses | B13: 분석 작업 | C13: started_at | D13: 시작 일시 | E13: timestamp | H13: N | K13: RG-01 · RG-01-E1 · CM-04 · R-1~3 · R-7 · R-8 | L13: 기존 | M13: v0.1
A14: analyses | B14: 분석 작업 | C14: finished_at | D14: 종료 일시 | E14: timestamp | H14: N | K14: RG-01 · RG-01-E1 · CM-04 · R-1~3 · R-7 · R-8 | L14: 기존 | M14: v0.1
A15: analyses | B15: 분석 작업 | C15: created_at | D15: 생성 일시 | E15: timestamp | H15: N | I15: now() | K15: RG-01 · RG-01-E1 · CM-04 · R-1~3 · R-7 · R-8 | L15: 신규 | M15: v1.0
A16: analysis_prescriptions | B16: 분석-처방전 연결 | C16: analysis_id | D16: 분석 ID | E16: bigint | F16: PK · FK | G16: analyses.id | H16: Y | K16: R-1 | L16: 신규 | M16: v1.0 | N16: v1.0 신규 · 여러 병원 처방전을 한 번에 점검 (최대 5장, REQ-013)
A17: analysis_prescriptions | B17: 분석-처방전 연결 | C17: prescription_id | D17: 처방전 ID | E17: bigint | F17: PK · FK | G17: prescriptions.id | H17: Y | K17: R-1 | L17: 신규 | M17: v1.0
A18: analysis_diseases | B18: 분석 질환 | C18: analysis_id | D18: 분석 ID | E18: bigint | F18: PK · FK | G18: analyses.id | H18: Y | K18: RG-05 · RG-05-E1 · R-6 | L18: 신규 | M18: v1.0 | N18: v1.0 신규 · 생활습관 가이드 조회 기준
A19: analysis_diseases | B19: 분석 질환 | C19: disease_code | D19: 상병 코드 | E19: varchar(10) | F19: PK · FK | G19: diseases.code | H19: Y | K19: RG-05 · RG-05-E1 · R-6 | L19: 신규 | M19: v1.0
A20: analysis_diseases | B20: 분석 질환 | C20: origin | D20: 출처 구분 | E20: varchar(20) | H20: Y | J20: prescription(처방전 코드) / user(RG-05-E1에서 직접 선택) | K20: RG-05 · RG-05-E1 · R-6 | L20: 신규 | M20: v1.0
A21: analysis_warnings | B21: 안전성 경고 | C21: id | D21: ID | E21: bigint | F21: PK | H21: Y | K21: RG-02 · RG-02-E1 · RG-03 · R-4 · R-5 | L21: 기존 | M21: v0.1 | N21: DB 조회로 결정적으로 산출. 0건이면 RG-02-E1
A22: analysis_warnings | B22: 안전성 경고 | C22: analysis_id | D22: 분석 ID | E22: bigint | F22: FK | G22: analyses.id | H22: Y | K22: RG-02 · RG-02-E1 · RG-03 · R-4 · R-5 | L22: 기존 | M22: v0.1
A23: analysis_warnings | B23: 안전성 경고 | C23: warning_type | D23: 경고 종류 | E23: varchar(30) | H23: Y | J23: interaction / duplicate_ingredient / duplicate_efficacy / elderly / age / pregnancy / dose_exceed / polypharmacy(v1.0 🟡) | K23: RG-02 · RG-02-E1 · RG-03 · R-4 · R-5 | L23: 수정 | M23: v1.0
A24: analysis_warnings | B24: 안전성 경고 | C24: severity | D24: 경고 등급 | E24: varchar(10) | H24: Y | J24: danger / caution / info | K24: RG-02 · RG-02-E1 · RG-03 · R-4 · R-5 | L24: 수정 | M24: v1.0
A25: analysis_warnings | B25: 안전성 경고 | C25: item_id_a | D25: 대상 약 항목 ID | E25: bigint | F25: FK | G25: prescription_items.id | H25: N | J25: 약 이름 대신 항목 참조 (처방 병원 표시용) | K25: RG-02 · RG-02-E1 · RG-03 · R-4 · R-5 | L25: 신규 | M25: v1.0
A26: analysis_warnings | B26: 안전성 경고 | C26: item_id_b | D26: 상대 약 항목 ID | E26: bigint | F26: FK | G26: prescription_items.id | H26: N | J26: 상대 약 (병용금기 · 중복) | K26: RG-02 · RG-02-E1 · RG-03 · R-4 · R-5 | L26: 신규 | M26: v1.0
A27: analysis_warnings | B27: 안전성 경고 | C27: reason | D27: 사유 | E27: text | H27: N | J27: DUR 금기 사유 원문 | K27: RG-02 · RG-02-E1 · RG-03 · R-4 · R-5 | L27: 수정 | M27: v1.0
A28: analysis_warnings | B28: 안전성 경고 | C28: summary | D28: 화면 표시 문장 | E28: text | H28: N | J28: 화면 표시 문장 (템플릿, AI 생성 아님 · NFR-032) | K28: RG-02 · RG-02-E1 · RG-03 · R-4 · R-5 | L28: 신규 | M28: v1.0
A29: analysis_warnings | B29: 안전성 경고 | C29: source | D29: 고시명 | E29: varchar(100) | H29: N | J29: 식약처 고시명 | K29: RG-02 · RG-02-E1 · RG-03 · R-4 · R-5 | L29: 수정 | M29: v1.0
A30: analysis_warnings | B30: 안전성 경고 | C30: notice_date | D30: 고시일 | E30: date | H30: N | K30: RG-02 · RG-02-E1 · RG-03 · R-4 · R-5 | L30: 신규 | M30: v1.0
A31: analysis_warnings | B31: 안전성 경고 | C31: daily_total | D31: 1일 총 복용량 | E31: decimal(12,3) | H31: N | J31: 1일 최대용량 초과일 때만 | K31: RG-02 · RG-02-E1 · RG-03 · R-4 · R-5 | L31: 신규 | M31: v1.0
A32: analysis_warnings | B32: 안전성 경고 | C32: max_daily | D32: 1일 최대 기준량 | E32: decimal(12,3) | H32: N | K32: RG-02 · RG-02-E1 · RG-03 · R-4 · R-5 | L32: 신규 | M32: v1.0
A33: guides | B33: 복약 · 생활습관 안내문 | C33: id | D33: ID | E33: bigint | F33: PK | H33: Y | K33: RG-04 · RG-05 · R-4 · R-10 | L33: 기존 | M33: v0.1
A34: guides | B34: 복약 · 생활습관 안내문 | C34: analysis_id | D34: 분석 ID | E34: bigint | F34: FK | G34: analyses.id | H34: Y | K34: RG-04 · RG-05 · R-4 · R-10 | L34: 기존 | M34: v0.1
A35: guides | B35: 복약 · 생활습관 안내문 | C35: section | D35: 안내 구분 | E35: varchar(30) | H35: N | J35: medication / lifestyle | K35: RG-04 · RG-05 · R-4 · R-10 | L35: 수정 | M35: v1.0
A36: guides | B36: 복약 · 생활습관 안내문 | C36: status | D36: 상태 | E36: varchar(20) | H36: N | J36: done / failed (부분 결과 RG-01-E1 → RG-04 · RG-05 "만들지 못했어요") | K36: RG-04 · RG-05 · R-4 · R-10 | L36: 신규 | M36: v1.0
A37: guides | B37: 복약 · 생활습관 안내문 | C37: content | D37: 안내 내용 (JSON) | E37: jsonb | H37: N | J37: 항목 고정 JSON (약별 purpose · howToTake · caution · source) — 결과 일관성 NFR-030 | K37: RG-04 · RG-05 · R-4 · R-10 | L37: 수정 | M37: v1.0
A38: guides | B38: 복약 · 생활습관 안내문 | C38: prompt_ver | D38: 프롬프트 버전 | E38: varchar(20) | H38: N | K38: RG-04 · RG-05 · R-4 · R-10 | L38: 수정 | M38: v1.0
A39: guides | B39: 복약 · 생활습관 안내문 | C39: model_name | D39: 모델 이름 | E39: varchar(50) | H39: N | K39: RG-04 · RG-05 · R-4 · R-10 | L39: 수정 | M39: v1.0
A40: guides | B40: 복약 · 생활습관 안내문 | C40: tts_url | D40: 음성 파일 주소 | E40: varchar(500) | H40: N | J40: 선택 구현 (REQ-100) | K40: RG-04 · RG-05 · R-4 · R-10 | L40: 수정 | M40: v1.0
A41: guides | B41: 복약 · 생활습관 안내문 | C41: created_at | D41: 생성 일시 | E41: timestamp | H41: N | I41: now() | K41: RG-04 · RG-05 · R-4 · R-10 | L41: 기존 | M41: v0.1
...

Sheet 챗봇
A1: ERD v1.0 · 챗봇
A2: 수인 · 대화 · 메시지
A4: 테이블 (영문) | B4: 테이블 (한글) | C4: 필드 (영문) | D4: 필드 (한글) | E4: 타입 | F4: 키 | G4: 참조 | H4: 필수 | I4: 기본값 | J4: 설명 | K4: 관련 화면 · API | L4: 변경 | M4: 최종 수정 | N4: 비고 (테이블 설명)
A5: chat_sessions | B5: 대화 | C5: id | D5: ID | E5: bigint | F5: PK | H5: Y | K5: CB-01~03 · H-1 · H-4 · H-5 | L5: 기존 | M5: v0.1 | N5: 날짜별 여러 대화 구조로 갈지 팀 확정 필요 (REQ-077)
A6: chat_sessions | B6: 대화 | C6: user_id | D6: 사용자 ID | E6: bigint | F6: FK | G6: users.id | H6: Y | K6: CB-01~03 · H-1 · H-4 · H-5 | L6: 기존 | M6: v0.1
A7: chat_sessions | B7: 대화 | C7: analysis_id | D7: 분석 ID | E7: bigint | F7: FK | G7: analyses.id | H7: N | J7: null이면 일반 질문 모드 (분석 전) | K7: CB-01~03 · H-1 · H-4 · H-5 | L7: 수정 | M7: v1.0
A8: chat_sessions | B8: 대화 | C8: context_type | D8: 시작 맥락 종류 | E8: varchar(20) | H8: N | J8: warning / drug (CB-01-E2에서 무엇을 알고 시작했는지) | K8: CB-01~03 · H-1 · H-4 · H-5 | L8: 신규 | M8: v1.0
A9: chat_sessions | B9: 대화 | C9: context_ref | D9: 시작 맥락 ID | E9: bigint | H9: N | J9: analysis_warnings.id 또는 prescription_items.id | K9: CB-01~03 · H-1 · H-4 · H-5 | L9: 신규 | M9: v1.0
A10: chat_sessions | B10: 대화 | C10: title | D10: 대화 제목 | E10: varchar(100) | H10: N | J10: 🟡 수인 확인 · 대화 제목 자동 생성 · 수정 (CB-03) | K10: CB-01~03 · H-1 · H-4 · H-5 | L10: 신규 | M10: v1.0
A11: chat_sessions | B11: 대화 | C11: summary | D11: 대화 요약 | E11: text | H11: N | J11: 🟡 수인 확인 · 오래된 대화 요약 (맥락 압축) | K11: CB-01~03 · H-1 · H-4 · H-5 | L11: 신규 | M11: v1.0
A12: chat_sessions | B12: 대화 | C12: created_at | D12: 생성 일시 | E12: timestamp | H12: N | I12: now() | K12: CB-01~03 · H-1 · H-4 · H-5 | L12: 기존 | M12: v0.1
A13: chat_sessions | B13: 대화 | C13: updated_at | D13: 수정 일시 | E13: timestamp | H13: N | K13: CB-01~03 · H-1 · H-4 · H-5 | L13: 신규 | M13: v1.0
A14: chat_messages | B14: 대화 메시지 | C14: id | D14: ID | E14: bigint | F14: PK | H14: Y | K14: CB-01 · H-2 · H-3 | L14: 기존 | M14: v0.1
A15: chat_messages | B15: 대화 메시지 | C15: session_id | D15: 대화 ID | E15: bigint | F15: FK | G15: chat_sessions.id | H15: Y | K15: CB-01 · H-2 · H-3 | L15: 기존 | M15: v0.1
A16: chat_messages | B16: 대화 메시지 | C16: role | D16: 발화자 | E16: varchar(10) | H16: N | J16: user / assistant | K16: CB-01 · H-2 · H-3 | L16: 기존 | M16: v0.1
A17: chat_messages | B17: 대화 메시지 | C17: content | D17: 메시지 내용 | E17: text | H17: N | K17: CB-01 · H-2 · H-3 | L17: 기존 | M17: v0.1
A18: chat_messages | B18: 대화 메시지 | C18: answer_type | D18: 답변 종류 | E18: varchar(20) | H18: N | J18: answered / refused_medical(의료진 상담 필요) / no_evidence(확인이 어렵습니다) | K18: CB-01 · H-2 · H-3 | L18: 신규 | M18: v1.0
A19: chat_messages | B19: 대화 메시지 | C19: sources | D19: 답변 출처 | E19: jsonb | H19: N | J19: 답변 근거 출처 | K19: CB-01 · H-2 · H-3 | L19: 신규 | M19: v1.0
A20: chat_messages | B20: 대화 메시지 | C20: created_at | D20: 생성 일시 | E20: timestamp | H20: N | I20: now() | K20: CB-01 · H-2 · H-3 | L20: 기존 | M20: v0.1

Sheet 실천·보상
A1: ERD v1.0 · 실천·보상
A2: 성규 · 추천 · 목표 · 기록 · 포인트
A4: 테이블 (영문) | B4: 테이블 (한글) | C4: 필드 (영문) | D4: 필드 (한글) | E4: 타입 | F4: 키 | G4: 참조 | H4: 필수 | I4: 기본값 | J4: 설명 | K4: 관련 화면 · API | L4: 변경 | M4: 최종 수정 | N4: 비고 (테이블 설명)
A5: recommendations | B5: 생활습관 추천 | C5: id | D5: ID | E5: bigint | F5: PK | H5: Y | K5: RW-01 · RG-05 · P-1 | L5: 신규 | M5: v1.0 | N5: AI 추천만으로는 목표가 되지 않음 — 사용자가 골라야 habit_goals 생성 (REQ-110)
A6: recommendations | B6: 생활습관 추천 | C6: analysis_id | D6: 분석 ID | E6: bigint | F6: FK | G6: analyses.id | H6: Y | K6: RW-01 · RG-05 · P-1 | L6: 신규 | M6: v1.0
A7: recommendations | B7: 생활습관 추천 | C7: guide_id | D7: 생활습관 팩트 ID | E7: bigint | F7: FK | G7: lifestyle_guides.id | H7: N | J7: 질환 기준 추천일 때 | K7: RW-01 · RG-05 · P-1 | L7: 신규 | M7: v1.0
A8: recommendations | B8: 생활습관 추천 | C8: medication_link_id | D8: 약-생활수칙 연결 ID | E8: bigint | F8: FK | G8: lifestyle_medication_links.id | H8: N | J8: 약 기준 추천일 때 | K8: RW-01 · RG-05 · P-1 | L8: 신규 | M8: v1.0
A9: recommendations | B9: 생활습관 추천 | C9: title | D9: 제목 | E9: varchar(100) | H9: Y | J9: 국물 남기기 등 | K9: RW-01 · RG-05 · P-1 | L9: 신규 | M9: v1.0
A10: recommendations | B10: 생활습관 추천 | C10: reason_label | D10: 추천 이유 라벨 | E10: varchar(50) | H10: N | J10: 고혈압 / 약과 함께 등 (화면 라벨) | K10: RW-01 · RG-05 · P-1 | L10: 신규 | M10: v1.0
A11: recommendations | B11: 생활습관 추천 | C11: goal_type | D11: 목표 유형 | E11: varchar(20) | H11: N | J11: check / quantity | K11: RW-01 · RG-05 · P-1 | L11: 신규 | M11: v1.0
A12: recommendations | B12: 생활습관 추천 | C12: target_value | D12: 목표 수치 | E12: decimal(10,2) | H12: N | J12: 수량형 목표 (예: 30) | K12: RW-01 · RG-05 · P-1 | L12: 신규 | M12: v1.0
A13: recommendations | B13: 생활습관 추천 | C13: unit | D13: 단위 | E13: varchar(20) | H13: N | J13: 분 등 | K13: RW-01 · RG-05 · P-1 | L13: 신규 | M13: v1.0
A14: recommendations | B14: 생활습관 추천 | C14: rank | D14: 순위 | E14: smallint | H14: N | K14: RW-01 · RG-05 · P-1 | L14: 신규 | M14: v1.0
A15: habit_goals | B15: 실천 목표 | C15: id | D15: ID | E15: bigint | F15: PK | H15: Y | K15: RW-02 · P-2 · P-3 | L15: 신규 | M15: v1.0 | N15: 최대 3개 활성 (REQ-111)
A16: habit_goals | B16: 실천 목표 | C16: user_id | D16: 사용자 ID | E16: bigint | F16: FK | G16: users.id | H16: Y | K16: RW-02 · P-2 · P-3 | L16: 신규 | M16: v1.0
A17: habit_goals | B17: 실천 목표 | C17: recommendation_id | D17: 추천 ID | E17: bigint | F17: FK | G17: recommendations.id | H17: N | K17: RW-02 · P-2 · P-3 | L17: 신규 | M17: v1.0
A18: habit_goals | B18: 실천 목표 | C18: title | D18: 제목 | E18: varchar(100) | H18: Y | K18: RW-02 · P-2 · P-3 | L18: 신규 | M18: v1.0
A19: habit_goals | B19: 실천 목표 | C19: goal_type | D19: 목표 유형 | E19: varchar(20) | H19: Y | J19: check / quantity | K19: RW-02 · P-2 · P-3 | L19: 신규 | M19: v1.0
A20: habit_goals | B20: 실천 목표 | C20: target_value | D20: 목표 수치 | E20: decimal(10,2) | H20: N | K20: RW-02 · P-2 · P-3 | L20: 신규 | M20: v1.0
A21: habit_goals | B21: 실천 목표 | C21: unit | D21: 단위 | E21: varchar(20) | H21: N | K21: RW-02 · P-2 · P-3 | L21: 신규 | M21: v1.0
A22: habit_goals | B22: 실천 목표 | C22: start_date | D22: 시작일 | E22: date | H22: Y | K22: RW-02 · P-2 · P-3 | L22: 신규 | M22: v1.0
A23: habit_goals | B23: 실천 목표 | C23: end_date | D23: 종료일 | E23: date | H23: N | J23: 주 단위 (REQ-116 재선택 흐름 🟡) | K23: RW-02 · P-2 · P-3 | L23: 신규 | M23: v1.0
A24: habit_goals | B24: 실천 목표 | C24: status | D24: 상태 | E24: varchar(20) | H24: N | J24: active / ended | K24: RW-02 · P-2 · P-3 | L24: 신규 | M24: v1.0
A25: habit_goals | B25: 실천 목표 | C25: created_at | D25: 생성 일시 | E25: timestamp | H25: N | I25: now() | K25: RW-02 · P-2 · P-3 | L25: 신규 | M25: v1.0
A26: habit_records | B26: 실천 기록 | C26: id | D26: ID | E26: bigint | F26: PK | H26: Y | K26: RW-03 · RW-04 · P-4 · P-5 | L26: 신규 | M26: v1.0
A27: habit_records | B27: 실천 기록 | C27: goal_id | D27: 목표 ID | E27: bigint | F27: FK | G27: habit_goals.id | H27: Y | K27: RW-03 · RW-04 · P-4 · P-5 | L27: 신규 | M27: v1.0
A28: habit_records | B28: 실천 기록 | C28: record_date | D28: 기록일 | E28: date | H28: Y | K28: RW-03 · RW-04 · P-4 · P-5 | L28: 신규 | M28: v1.0
A29: habit_records | B29: 실천 기록 | C29: value | D29: 기록 수치 | E29: decimal(10,2) | H29: N | J29: 수량형 누적값 | K29: RW-03 · RW-04 · P-4 · P-5 | L29: 신규 | M29: v1.0
A30: habit_records | B30: 실천 기록 | C30: completed | D30: 완료 여부 | E30: boolean | H30: Y | I30: false | K30: RW-03 · RW-04 · P-4 · P-5 | L30: 신규 | M30: v1.0
A31: habit_records | B31: 실천 기록 | C31: created_at | D31: 생성 일시 | E31: timestamp | H31: N | I31: now() | K31: RW-03 · RW-04 · P-4 · P-5 | L31: 신규 | M31: v1.0 | N31: 인덱스: (goal_id, record_date) [unique, note: '같은 날 중복 완료 방지']
A32: rewards | B32: 포인트 | C32: id | D32: ID | E32: bigint | F32: PK | H32: Y | K32: RW-05 · RW-06 · P-6 | L32: 신규 | M32: v1.0
A33: rewards | B33: 포인트 | C33: user_id | D33: 사용자 ID | E33: bigint | F33: FK | G33: users.id | H33: Y | K33: RW-05 · RW-06 · P-6 | L33: 신규 | M33: v1.0
A34: rewards | B34: 포인트 | C34: record_id | D34: 실천 기록 ID | E34: bigint | F34: FK | G34: habit_records.id | H34: N | J34: 목표 완료 보상일 때 | K34: RW-05 · RW-06 · P-6 | L34: 신규 | M34: v1.0
A35: rewards | B35: 포인트 | C35: reward_type | D35: 보상 종류 | E35: varchar(20) | H35: Y | J35: goal_done / all_done(하루 전체 완료 보너스) | K35: RW-05 · RW-06 · P-6 | L35: 신규 | M35: v1.0
A36: rewards | B36: 포인트 | C36: points | D36: 포인트 | E36: int | H36: Y | K36: RW-05 · RW-06 · P-6 | L36: 신규 | M36: v1.0
A37: rewards | B37: 포인트 | C37: reward_date | D37: 지급일 | E37: date | H37: Y | K37: RW-05 · RW-06 · P-6 | L37: 신규 | M37: v1.0
A38: rewards | B38: 포인트 | C38: created_at | D38: 생성 일시 | E38: timestamp | H38: N | I38: now() | K38: RW-05 · RW-06 · P-6 | L38: 신규 | M38: v1.0 | N38: 인덱스: (user_id, reward_date, reward_type, record_id) [unique, note: '중복 지급 방지 (REQ-113)']

Sheet 마스터
A1: ERD v1.0 · 마스터
A2: 형준 · 공공데이터 사전 적재 (의약품 · DUR · 중복 · 질병 · 생활습관)
A4: 테이블 (영문) | B4: 테이블 (한글) | C4: 필드 (영문) | D4: 필드 (한글) | E4: 타입 | F4: 키 | G4: 참조 | H4: 필수 | I4: 기본값 | J4: 설명 | K4: 관련 화면 · API | L4: 변경 | M4: 최종 수정 | N4: 비고 (테이블 설명)
A5: drug_products | B5: 의약품 제품 | C5: edi_code | D5: EDI 제품코드 | E5: varchar(9) | F5: PK | H5: Y | J5: 심평원 제품코드 = 식약처 EDI_CODE ← 조인 키 | K5: O-3 · O-4 | L5: 기존 | M5: v0.1 | N5: 약제급여목록 22,041품목 기준. 규격·단위는 복용 총량 계산에 사용
A6: drug_products | B6: 의약품 제품 | C6: item_seq | D6: 품목기준코드 | E6: varchar(9) | H6: N | J6: 식약처 품목기준코드 | K6: O-3 · O-4 | L6: 기존 | M6: v0.1
A7: drug_products | B7: 의약품 제품 | C7: item_name | D7: 제품명 | E7: varchar(300) | H7: Y | K7: O-3 · O-4 | L7: 기존 | M7: v0.1
A8: drug_products | B8: 의약품 제품 | C8: item_name_norm | D8: 정규화 제품명 | E8: varchar(300) | H8: N | J8: 정규화된 이름 (괄호·규격 제거) — 매칭용 인덱스 | K8: O-3 · O-4 | L8: 기존 | M8: v0.1
A9: drug_products | B9: 의약품 제품 | C9: entp_name | D9: 업체명 | E9: varchar(200) | H9: N | K9: O-3 · O-4 | L9: 기존 | M9: v0.1
A10: drug_products | B10: 의약품 제품 | C10: ingr_code | D10: 성분 코드 | E10: varchar(9) | F10: FK | G10: drug_ingredients.ingr_code | H10: N | J10: 심평원 주성분코드 | K10: O-3 · O-4 | L10: 기존 | M10: v0.1
A11: drug_products | B11: 의약품 제품 | C11: ingr_group | D11: 동일성분 그룹 | E11: varchar(9) | H11: N | J11: 주성분코드_동일제형 — 제형 무관 동일성분 그룹 | K11: O-3 · O-4 | L11: 기존 | M11: v0.1
A12: drug_products | B12: 의약품 제품 | C12: etc_otc | D12: 전문/일반 | E12: varchar(10) | H12: N | J12: 전문 / 일반 | K12: O-3 · O-4 | L12: 기존 | M12: v0.1
A13: drug_products | B13: 의약품 제품 | C13: class_code | D13: 약효분류 | E13: varchar(10) | H13: N | J13: 약효분류 | K13: O-3 · O-4 | L13: 기존 | M13: v0.1
A14: drug_products | B14: 의약품 제품 | C14: spec_value | D14: 규격 | E14: decimal(12,3) | H14: N | J14: 규격 (예: 5) | K14: O-3 · O-4 | L14: 기존 | M14: v0.1
A15: drug_products | B15: 의약품 제품 | C15: spec_unit | D15: 규격 단위 | E15: varchar(30) | H15: N | J15: 단위 (예: mg/정) | K15: O-3 · O-4 | L15: 기존 | M15: v0.1
A16: drug_products | B16: 의약품 제품 | C16: price | D16: 급여 상한금액 | E16: int | H16: N | J16: 급여 상한금액 | K16: O-3 · O-4 | L16: 기존 | M16: v0.1
A17: drug_products | B17: 의약품 제품 | C17: route | D17: 투여 경로 | E17: varchar(10) | H17: N | J17: 내복 / 주사 / 외용 | K17: O-3 · O-4 | L17: 기존 | M17: v0.1
A18: drug_ingredients | B18: 의약품 성분 | C18: ingr_code | D18: 성분 코드 | E18: varchar(9) | F18: PK | H18: Y | J18: 앞6=성분, 뒤3=제형 (ATB정제 ACH캡슐 BIJ주사) | K18: — | L18: 기존 | M18: v0.1
A19: drug_ingredients | B19: 의약품 성분 | C19: ingr_name | D19: 성분명 (영문) | E19: varchar(300) | H19: N | J19: 영문 성분명 | K19: — | L19: 기존 | M19: v0.1
A20: drug_ingredients | B20: 의약품 성분 | C20: ingr_name_kr | D20: 성분명 (한글) | E20: varchar(300) | H20: N | K20: — | L20: 기존 | M20: v0.1
A21: drug_details | B21: 의약품 상세 (허가정보) | C21: edi_code | D21: EDI 제품코드 | E21: varchar(9) | F21: PK · FK | G21: drug_products.edi_code | H21: Y | K21: R-4 (RAG 검색) | L21: 기존 | M21: v0.1 | N21: XML 파싱 시 <ARTICLE title="..."> 속성과 CDATA 양쪽에서 내용 추출 필요
A22: drug_details | B22: 의약품 상세 (허가정보) | C22: efficacy | D22: 효능효과 | E22: text | H22: N | J22: 효능효과 (식약처 EE_DOC_DATA 파싱) | K22: R-4 (RAG 검색) | L22: 기존 | M22: v0.1
A23: drug_details | B23: 의약품 상세 (허가정보) | C23: usage_dose | D23: 용법용량 | E23: text | H23: N | J23: 용법용량 (UD_DOC_DATA) | K23: R-4 (RAG 검색) | L23: 기존 | M23: v0.1
A24: drug_details | B24: 의약품 상세 (허가정보) | C24: precautions | D24: 사용상 주의사항 | E24: text | H24: N | J24: 사용상의주의사항 (NB_DOC_DATA) | K24: R-4 (RAG 검색) | L24: 기존 | M24: v0.1
A25: drug_details | B25: 의약품 상세 (허가정보) | C25: storage | D25: 보관법 | E25: varchar(300) | H25: N | J25: 보관법 | K25: R-4 (RAG 검색) | L25: 기존 | M25: v0.1
A26: drug_details | B26: 의약품 상세 (허가정보) | C26: chart | D26: 성상 | E26: varchar(300) | H26: N | J26: 성상 — 낱알 식별에 활용 가능 | K26: R-4 (RAG 검색) | L26: 기존 | M26: v0.1
A27: drug_details | B27: 의약품 상세 (허가정보) | C27: embedding_id | D27: 벡터DB 문서 ID | E27: varchar(100) | H27: N | J27: 벡터DB 문서 ID (RAG 검색용) | K27: R-4 (RAG 검색) | L27: 기존 | M27: v0.1
A28: dur_interaction | B28: DUR 병용금기 | C28: ingr_code_a | D28: 성분 코드 A | E28: varchar(9) | F28: PK | H28: Y | J28: 정렬 후 저장 (A<B) — 양방향 중복 제거 | K28: R-4 · R-5 | L28: 기존 | M28: v0.1 | N28: m.db TBJBD43 기준 성분쌍 97,326건 (제품 단위 CSV 873,147행을 정규화)
A29: dur_interaction | B29: DUR 병용금기 | C29: ingr_code_b | D29: 성분 코드 B | E29: varchar(9) | F29: PK | H29: Y | K29: R-4 · R-5 | L29: 기존 | M29: v0.1
A30: dur_interaction | B30: DUR 병용금기 | C30: effective_from | D30: 적용 시작일 | E30: date | H30: N | K30: R-4 · R-5 | L30: 기존 | M30: v0.1
A31: dur_interaction | B31: DUR 병용금기 | C31: effective_to | D31: 적용 종료일 | E31: date | H31: N | J31: 99991231 = 현행 | K31: R-4 · R-5 | L31: 기존 | M31: v0.1
A32: dur_interaction | B32: DUR 병용금기 | C32: reason | D32: 사유 | E32: text | H32: N | J32: 금기 사유 (DUR_SD_EFT) | K32: R-4 · R-5 | L32: 기존 | M32: v0.1
A33: dur_interaction | B33: DUR 병용금기 | C33: notice_date | D33: 고시일 | E33: date | H33: N | J33: 고시일자 | K33: R-4 · R-5 | L33: 기존 | M33: v0.1
A34: dur_interaction | B34: DUR 병용금기 | C34: notice_no | D34: 고시 번호 | E34: varchar(10) | H34: N | K34: R-4 · R-5 | L34: 기존 | M34: v0.1
A35: dur_interaction_exception | B35: DUR 병용금기 예외 | C35: ingr_code_a | D35: 성분 코드 A | E35: varchar(9) | F35: PK | H35: Y | K35: R-4 | L35: 기존 | M35: v0.1 | N35: m.db TBJBD46. CSV에는 없는 데이터 — 없으면 오탐 발생
A36: dur_interaction_exception | B36: DUR 병용금기 예외 | C36: ingr_code_b | D36: 성분 코드 B | E36: varchar(9) | F36: PK | H36: Y | K36: R-4 | L36: 기존 | M36: v0.1
A37: dur_interaction_exception | B37: DUR 병용금기 예외 | C37: edi_code | D37: EDI 제품코드 | E37: varchar(9) | F37: PK | H37: Y | J37: 이 제품은 금기에서 제외 | K37: R-4 | L37: 기존 | M37: v0.1
A38: dur_elderly | B38: DUR 노인주의 | C38: ingr_code | D38: 성분 코드 | E38: varchar(9) | F38: PK | H38: Y | K38: R-4 | L38: 기존 | M38: v0.1 | N38: m.db TBDUC230 + 노인주의 CSV. 고령 타겟의 핵심
A39: dur_elderly | B39: DUR 노인주의 | C39: min_age | D39: 기준 나이 | E39: smallint | H39: N | J39: 통상 65 | K39: R-4 | L39: 기존 | M39: v0.1
A40: dur_elderly | B40: DUR 노인주의 | C40: reason | D40: 사유 | E40: text | H40: N | K40: R-4 | L40: 기존 | M40: v0.1
A41: dur_elderly | B41: DUR 노인주의 | C41: notice_date | D41: 고시일 | E41: date | H41: N | K41: R-4 | L41: 기존 | M41: v0.1
...
