Workbook

Sheet 작성 규칙
A1: 작성 규칙
A2: 탭 구성 | B2: 작성 규칙 / 변경 이력 / 요약 / 사용자 / 입력 / 분석 / 챗봇 / 실천·보상 / 마스터 / FHIR 대응 — 규칙과 변경 이력을 먼저 확인한 뒤 영역(담당자)별 탭을 수정
A3: 다이어그램 | B3: 같은 폴더의 ERD_6기_5팀_v1.3.dbml을 dbdiagram.io에 붙여넣으면 관계도가 그려짐. 테이블 · 필드를 바꾸면 dbml과 이 엑셀을 함께 고침
A4: 키 | B4: PK 기본키 · FK 외래키(참조 칸에 대상 테이블.필드) · UQ 유일값
A5: 필수 | B5: Y = NOT NULL 또는 PK / N = 비어 있어도 됨
A6: 변경 | B6: v0.1 대비 — 기존 / 수정 (노란 배경) / 신규 (파란 배경)
A7: 최종 수정 | B7: 그 필드가 마지막으로 바뀐 버전. 바꿀 때마다 변경 이력 탭에 버전 요약 한 줄 + 위치 · 현행(As-Is) · 개정(To-Be) 세부 행을 추가 — 현행에는 바꾸기 전 정의(타입 · 키 · 필수 · 설명)를 그대로 적음
A8: 확인 필요 | B8: 🟡 = 담당자 확인 필요 (설명에 누구 확인인지 적음)
A9: 설계 원칙 | B9: 1. 외부 공공데이터는 "마스터"로 분리해 사전 적재 (요청 시 API 호출 안 함) 2. DUR 규칙은 성분 단위로 정규화 (제품 87만행 → 성분 9.7만쌍) 3. 민감정보는 최소 저장 (원본 이미지 미저장, 식별정보 마스킹) 4. 조인 키: 심평원 제품코드(EDI) = 식약처 EDI_CODE 5. 안전성 경고는 DB 조회 결과만 저장 (AI 생성 아님)
A10: FHIR 대응 | B10: 테이블 · 필드를 추가하거나 바꾸면 FHIR 대응 탭에도 같은 행을 추가 · 수정 (대응 수준: 일치 / 변환 / 확장 / FHIR 외)

Sheet 변경 이력
A1: 변경 이력
A2: ※ 왼쪽 행 번호 옆 [+] / [-] 버튼으로 세부사항을 펼치고 접을 수 있습니다. 바꿀 때마다 버전 요약 한 줄 + 아래에 위치 · 현행(As-Is) · 개정(To-Be)을 적고, 현행에는 바꾸기 전 값을 그대로 남겨 주세요.
A3: 버전 | B3: 일자 | C3: 변경 내용 | E3: 담당
A4: v0.1 | B4: 2026-09-22 | C4: 최초 작성 — 마스터 영역 확정, 사용자 · 입력 · 분석 · 챗봇 영역 초안 (dbml) | E4: 이형준
A5: v1.0 | B5: 2026-09-24 | C5: 통합 와이어프레임(45개 화면) · API 명세서 v1.0 · 요구사항 v1.0 기준 반영 — 테이블 9개 신규(실천 · 보상 4개 포함), 분석:처방전 1:N, 처방전 질병코드 N개, analyses 단계 · 재시도, 로그인 잠금 · 동의 기록 등 | E5: 이형준
B6: 위치 | C6: 현행 (As-Is) | D6: 개정 (To-Be)
B7: users / login_id — 설명 변경 | C7: login_id varchar(100) · UQ · NOT NULL — 이메일 또는 소셜 ID | D7: login_id varchar(100) · UQ · NOT NULL — 이메일 사유: 소셜 로그인 제외, 이메일 가입만
B8: users / password_hash — 정의 변경 | C8: password_hash varchar(255) — 소셜 로그인 시 null | D8: password_hash varchar(255) · NOT NULL 사유: 소셜 로그인 제외 → 항상 필요
B9: users / nickname — 설명 변경 | C9: nickname varchar(50) | D9: nickname varchar(50) — 선택 입력. 홈 인사말용
B10: users / birth_year — 정의 변경 | C10: birth_year smallint — 생년월일 대신 출생연도만 (최소 수집) | D10: birth_year smallint · NOT NULL — 생년월일 대신 출생연도만 (최소 수집) · 노인주의 · 연령금기 판정
B11: users / sex — 정의 변경 | C11: sex varchar(1) — M / F | D11: sex varchar(1) · NOT NULL — M / F
B12: users / failed_login_count — 필드 추가 | C12: (없음) | D12: failed_login_count smallint · 기본값 0 — v1.0 · 5회 실패 시 잠금 (CM-01-E1) 사유: A-2 · REQ-002 — 5회 실패 10분 잠금
B13: users / locked_until — 필드 추가 | C13: (없음) | D13: locked_until timestamp — v1.0 · 잠금 해제 시각 (CM-01-E2) 사유: A-2 · REQ-002
B14: users / updated_at — 필드 추가 | C14: (없음) | D14: updated_at timestamp
B15: users / deleted_at — 설명 변경 | C15: deleted_at timestamp — 탈퇴 시 소프트 삭제 후 개인정보 파기 | D15: deleted_at timestamp — 탈퇴 시 개인정보 파기 후 시각만 남김 (CM-07)
B16: users (회원) / 테이블 설명 | C16: 개인 식별정보는 최소로 수집. 성명·주민번호·연락처 미수집 | D16: 성명 · 주민번호 · 연락처 미수집
B17: user_consents (동의 기록) — 테이블 신규 | C17: (없음) | D17: 필드 6개: id, user_id, consent_type, agreed, agreed_at, withdrawn_at v1.0 신규 · CM-02 가입 동의, CM-05 동의 내역 사유: U-4 · U-5 · REQ-005 · 007 — 민감정보 별도 동의 기록
... B87: rewards (포인트) — 테이블 신규 | C87: (없음) | D87: 필드 7개: id, user_id, record_id, reward_type, points, reward_date, created_at 사유: REQ-113 [성규 확인 필요]
A88: v1.1 | B88: 2026-09-25 | C88: FHIR R4 대응 탭 추가 — 테이블 35개 · 주요 필드를 FHIR 리소스 · 요소에 대응 (75행). 스키마 변경 없음 | E88: 이형준
B89: 위치 | C89: 현행 (As-Is) | D89: 개정 (To-Be)
B90: FHIR 대응 탭 — 신규 | C90: (없음) — FHIR 대응 정보 없음. 국내 공공데이터 코드(KCD · 심평원 EDI · 식약처 DUR) 기준으로만 설계 | D90: FHIR 대응 탭 75행: 영역 · 테이블 · 필드 · FHIR 리소스 · 요소 경로 · 값 변환 · 대응 수준(일치 / 변환 / 확장 / FHIR 외) · 비고 사유: 표준 대응 근거를 미리 정리 (나중에 찾아 넣기 어려움), 참여기업 · 멘토 질의 대비
B91: 작성 규칙 / 탭 구성 | C91: 작성 규칙 / 변경 이력 / 요약 / 사용자 / 입력 / 분석 / 챗봇 / 실천·보상 / 마스터 | D91: … / 마스터 / FHIR 대응
B92: 작성 규칙 / FHIR 대응 — 신규 행 | C92: (없음) | D92: 테이블 · 필드를 바꾸면 FHIR 대응 탭도 같이 수정
B93: 파일 이름 · 탭 제목 버전 | C93: ERD_6기_5팀_v1.0.xlsx · "ERD v1.0" · dbml 헤더의 이력 위치 "ERD_6기_5팀_v1.0.xlsx" | D93: ERD_6기_5팀_v1.1.xlsx · "ERD v1.1" · dbml 헤더도 "ERD_6기_5팀_v1.1.xlsx"로 수정 (dbml 스키마는 그대로라 파일명 v1.0 유지)
A94: v1.2 | B94: 2026-09-28 | C94: 리뷰 반영 — 생활습관 근거를 실천 항목별 출처 테이블로 분리, 칼륨 등 "의료진 확인" 표시 추가, OCR 비동기 작업 테이블 추가 | E94: 이형준
B95: 위치 | C95: 현행 (As-Is) | D95: 개정 (To-Be)
B96: ocr_jobs (OCR 작업) — 테이블 신규 | C96: (없음) — O-1 업로드가 201로 바로 prescriptionIds 반환 | D96: 필드 7개: id, user_id, status(queued / running / done / failed), file_count, error_code, created_at, finished_at 사유: OCR 처리 시간이 NFR-001 P95 3초와 충돌할 수 있어 202 + 작업 ID 구조로 (리뷰 지적 · 채연 확인 필요)
B97: prescriptions / ocr_job_id — 필드 추가 | C97: (없음) | D97: ocr_job_id bigint · FK · → ocr_jobs.id
B98: prescriptions / file_index — 필드 추가 | C98: (없음) | D98: file_index smallint — 작업 안에서 몇 번째 사진인지 (실패 사진 안내용)
B99: lifestyle_guides / actions — 삭제 | C99: actions text — 실천 방법 (JSON 배열) | D99: 삭제 → lifestyle_guide_actions 테이블로 분리 사유: 실천 항목마다 출처를 따로 달아야 검증 · 갱신 가능 (리뷰 지적 5)
B100: lifestyle_guides / source — 삭제 | C100: source varchar(300) — 근거 출처 (예: "질병관리청 · 관련 학회 지침의 권고 수치를 정리") | D100: 삭제 → source_id (FK → lifestyle_guide_sources)
B101: lifestyle_guides / source_id — 필드 추가 | C101: (없음) | D101: source_id bigint · FK · → lifestyle_guide_sources.id — 목표 수치의 근거
B102: lifestyle_guide_actions (생활습관 실천 항목) — 테이블 신규 | C102: (없음) | D102: 필드 6개: id, guide_id, action_text, source_id(NOT NULL), goal_eligible(기본 true), sort_order
B103: lifestyle_guide_sources (생활습관 근거 출처) — 테이블 신규 | C103: (없음) | D103: 필드 8개: id, org, title, edition, published_date, url, identifier, accessed_date
B104: lifestyle_medication_links / source_id — 필드 추가 | C104: (없음) | D104: source_id bigint · FK · → lifestyle_guide_sources.id
B105: lifestyle_medication_links / requires_clinician — 필드 추가 | C105: (없음) | D105: requires_clinician boolean · NOT NULL · 기본값 false — true면 "의료진 확인" 안내로만 표시 사유: 이뇨제 · ACE억제제/ARB와 칼륨 권고는 신장 기능 · 병용 약에 따라 위험 (리뷰 지적 3, lifestyle_guide_facts.json v0.2와 같은 규칙)
B106: lifestyle_medication_links / goal_eligible — 필드 추가 | C106: (없음) | D106: goal_eligible boolean · NOT NULL · 기본값 true — false면 실천 목표로 만들지 않음
... B110: 파일 이름 · 탭 제목 · dbml | C110: ERD_6기_5팀_v1.1.xlsx · "ERD v1.1" · ERD_6기_5팀_v1.0.dbml (헤더 "ERD v1.0", 기준 "API v1.0 · 요구사항 v1.0") | D110: ERD_6기_5팀_v1.2.xlsx · "ERD v1.2" · ERD_6기_5팀_v1.2.dbml (헤더 "ERD v1.2", 기준 "API v1.1 · 요구사항 v1.3") — 스키마가 바뀌어 dbml도 같은 버전으로
A111: v1.3 | B111: 2026-10-06 | C111: 챗봇 1단계 반영 (PR #3 · API v1.3) — answer_type 7가지, 요청 번호(client_request_id) · 맥락 카드(context_card) 필드 추가, 날짜별 여러 대화 구조 확정 / 담당 변경 (사용자 수인 · 분석 · 마스터 채연) / 긴급 기록 테이블은 팀 확인 후 / 코드 맞춤: 복합 PK 2곳 → id + unique, prescription_diseases.disease_id, 상병 21,299개 · 규격 칸 설명 / 성규 리뷰(10/6): 추천이 지워지면 목표 연결 비움(SET NULL) · 하루 보너스(all_done) 중복 방지 / 허가정보 키를 item_seq로 · 급여목록에 없는 약 담기 · 약봉투 조제일 (수인 PR #48 리뷰 10/6) | E111: 김채연
B112: 위치 | C112: 현행 (As-Is) | D112: 개정 (To-Be)
...

Sheet 요약
A1: ERD v1.3 · 5팀 · 진료 기록 기반 복약 안내 및 생활습관 개선 가이드 자동 생성 시스템
A2: 작성 2026-09-24 · 영역별로 담당자가 관리 · 테이블 수 · 필드 수는 각 탭에서 자동 집계 (행을 추가해도 반영됨)
A4: 탭 | B4: 담당 · 범위 | C4: 테이블 | D4: 필드 | E4: 신규 필드 | F4: 수정 필드
A5: 사용자 | B5: 수인 · 회원 · 동의 | C5: =SUMPRODUCT(('사용자'!$A$5:$A$300<>"")/COUNTIF('사용자'!$A$5:$A$300,'사용자'!$A$5:$A$300&"")) | D5: =COUNTA('사용자'!$C$5:$C$300) | E5: =COUNTIF('사용자'!$L$5:$L$300,"신규") | F5: =COUNTIF('사용자'!$L$5:$L$300,"수정")
A6: 입력 | B6: 채연 · 처방전 · 약봉투 · OCR · 약품 매칭 | C6: =SUMPRODUCT(('입력'!$A$5:$A$300<>"")/COUNTIF('입력'!$A$5:$A$300,'입력'!$A$5:$A$300&"")) | D6: =COUNTA('입력'!$C$5:$C$300) | E6: =COUNTIF('입력'!$L$5:$L$300,"신규") | F6: =COUNTIF('입력'!$L$5:$L$300,"수정")
A7: 분석 | B7: 채연 · 분석 작업 · 안전성 경고 · 안내문 · 피드백 | C7: =SUMPRODUCT(('분석'!$A$5:$A$300<>"")/COUNTIF('분석'!$A$5:$A$300,'분석'!$A$5:$A$300&"")) | D7: =COUNTA('분석'!$C$5:$C$300) | E7: =COUNTIF('분석'!$L$5:$L$300,"신규") | F7: =COUNTIF('분석'!$L$5:$L$300,"수정")
A8: 챗봇 | B8: 수인 · 대화 · 메시지 | C8: =SUMPRODUCT(('챗봇'!$A$5:$A$300<>"")/COUNTIF('챗봇'!$A$5:$A$300,'챗봇'!$A$5:$A$300&"")) | D8: =COUNTA('챗봇'!$C$5:$C$300) | E8: =COUNTIF('챗봇'!$L$5:$L$300,"신규") | F8: =COUNTIF('챗봇'!$L$5:$L$300,"수정")
A9: 실천·보상 | B9: 성규 · 추천 · 목표 · 기록 · 포인트 | C9: =SUMPRODUCT(('실천·보상'!$A$5:$A$300<>"")/COUNTIF('실천·보상'!$A$5:$A$300,'실천·보상'!$A$5:$A$300&"")) | D9: =COUNTA('실천·보상'!$C$5:$C$300) | E9: =COUNTIF('실천·보상'!$L$5:$L$300,"신규") | F9: =COUNTIF('실천·보상'!$L$5:$L$300,"수정")
A10: 마스터 | B10: 채연 · 공공데이터 사전 적재 (의약품 · DUR · 중복 · 질병 · 생활습관) | C10: =SUMPRODUCT(('마스터'!$A$5:$A$300<>"")/COUNTIF('마스터'!$A$5:$A$300,'마스터'!$A$5:$A$300&"")) | D10: =COUNTA('마스터'!$C$5:$C$300) | E10: =COUNTIF('마스터'!$L$5:$L$300,"신규") | F10: =COUNTIF('마스터'!$L$5:$L$300,"수정")
A11: 합계 | C11: =SUM(C5:C10) | D11: =SUM(D5:D10) | E11: =SUM(E5:E10) | F11: =SUM(F5:F10)

Sheet 사용자
A1: ERD v1.3 · 사용자
A2: 수인 · 회원 · 동의
A4: 테이블 (영문) | B4: 테이블 (한글) | C4: 필드 (영문) | D4: 필드 (한글) | E4: 타입 | F4: 키 | G4: 참조 | H4: 필수 | I4: 기본값 | J4: 설명 | K4: 관련 화면 · API | L4: 변경 | M4: 최종 수정 | N4: 비고 (테이블 설명)
A5: users | B5: 회원 | C5: id | D5: ID | E5: bigint | F5: PK | H5: Y | K5: CM-01~07 · A-1~3 · U-1~3 | L5: 기존 | M5: v0.1 | N5: 성명 · 주민번호 · 연락처 미수집
A6: users | B6: 회원 | C6: login_id | D6: 로그인 ID (이메일) | E6: varchar(100) | F6: UQ | H6: Y | J6: 이메일 | K6: CM-01~07 · A-1~3 · U-1~3 | L6: 수정 | M6: v1.0
A7: users | B7: 회원 | C7: password_hash | D7: 비밀번호 해시 | E7: varchar(255) | H7: Y | K7: CM-01~07 · A-1~3 · U-1~3 | L7: 수정 | M7: v1.0
A8: users | B8: 회원 | C8: birth_year | D8: 출생연도 | E8: smallint | H8: Y | J8: 생년월일 대신 출생연도만 (최소 수집) · 노인주의 · 연령금기 판정 | K8: CM-01~07 · A-1~3 · U-1~3 | L8: 수정 | M8: v1.0
A9: users | B9: 회원 | C9: sex | D9: 성별 | E9: varchar(1) | H9: Y | J9: M / F | K9: CM-01~07 · A-1~3 · U-1~3 | L9: 수정 | M9: v1.0
A10: users | B10: 회원 | C10: failed_login_count | D10: 로그인 실패 횟수 | E10: smallint | H10: N | I10: 0 | J10: 5회 실패 시 잠금 (CM-01-E1) | K10: CM-01~07 · A-1~3 · U-1~3 | L10: 신규 | M10: v1.0
A11: users | B11: 회원 | C11: locked_until | D11: 잠금 해제 시각 | E11: timestamp | H11: N | J11: 잠금 해제 시각 (CM-01-E2) | K11: CM-01~07 · A-1~3 · U-1~3 | L11: 신규 | M11: v1.0
A12: users | B12: 회원 | C12: created_at | D12: 생성 일시 | E12: timestamp | H12: N | I12: now() | K12: CM-01~07 · A-1~3 · U-1~3 | L12: 기존 | M12: v0.1
A13: users | B13: 회원 | C13: updated_at | D13: 수정 일시 | E13: timestamp | H13: N | K13: CM-01~07 · A-1~3 · U-1~3 | L13: 신규 | M13: v1.0
A14: users | B14: 회원 | C14: deleted_at | D14: 탈퇴 일시 | E14: timestamp | H14: N | J14: 탈퇴 시 개인정보 파기 후 시각만 남김 (CM-07) | K14: CM-01~07 · A-1~3 · U-1~3 | L14: 수정 | M14: v1.0
A15: user_consents | B15: 동의 기록 | C15: id | D15: ID | E15: bigint | F15: PK | H15: Y | K15: CM-02 · CM-05 · A-1 · U-4 · U-5 | L15: 신규 | M15: v1.0 | N15: v1.0 신규 · CM-02 가입 동의, CM-05 동의 내역
A16: user_consents | B16: 동의 기록 | C16: user_id | D16: 사용자 ID | E16: bigint | F16: FK | G16: users.id | H16: Y | K16: CM-02 · CM-05 · A-1 · U-4 · U-5 | L16: 신규 | M16: v1.0
A17: user_consents | B17: 동의 기록 | C17: consent_type | D17: 동의 종류 | E17: varchar(30) | H17: Y | J17: terms / privacy / sensitive_health | K17: CM-02 · CM-05 · A-1 · U-4 · U-5 | L17: 신규 | M17: v1.0
A18: user_consents | B18: 동의 기록 | C18: agreed | D18: 동의 여부 | E18: boolean | H18: Y | K18: CM-02 · CM-05 · A-1 · U-4 · U-5 | L18: 신규 | M18: v1.0
A19: user_consents | B19: 동의 기록 | C19: agreed_at | D19: 동의 일시 | E19: timestamp | H19: N | K19: CM-02 · CM-05 · A-1 · U-4 · U-5 | L19: 신규 | M19: v1.0
A20: user_consents | B20: 동의 기록 | C20: withdrawn_at | D20: 철회 일시 | E20: timestamp | H20: N | J20: 철회 시각. sensitive_health 철회 시 업로드 · 분석 불가 (🟡 기존 기록 처리 팀 결정) | K20: CM-02 · CM-05 · A-1 · U-4 · U-5 | L20: 신규 | M20: v1.0 | N20: 인덱스: (user_id, consent_type) [unique]
A21: user_health_profiles | B21: 건강 정보 | C21: user_id | D21: 사용자 ID | E21: bigint | F21: PK, FK | G21: users.id | H21: Y | J21: users와 1:1. 가입 때 함께 만듦 | K21: CM-02, CM-05, CM-06, A-1, U-1, U-2, U-3, U-5 | L21: 신규 | M21: v1.5 | N21: v1.5 신규. 민감정보(sensitive_health 동의 범위). 동의 철회(U-5), 탈퇴(U-3) 때 줄째 삭제 (탈퇴는 users 행을 남기므로 따로 지움)
A22: user_health_profiles | B22: 건강 정보 | C22: smoking | D22: 흡연 | E22: varchar(20) | H22: Y | J22: daily / sometimes / past / never / unknown. 국민건강영양조사 BS3_1에 "잘 모르겠어요"를 더함. 가입 때 필수 (10/19 수인, 채연 확인 필요) | K22: CM-02, CM-05, CM-06, A-1, U-1, U-2, U-3, U-5 | L22: 신규 | M22: v1.5
A23: user_health_profiles | B23: 건강 정보 | C23: drinking | D23: 음주 빈도 | E23: varchar(20) | H23: Y | J23: none / lt_monthly / monthly / 2_4_monthly / 2_3_weekly / 4plus_weekly / unknown. 국민건강영양조사 BD1_11(최근 1년 음주 빈도)에 "잘 모르겠어요"를 더함. 가입 때 필수 (10/19 수인, 채연 확인 필요) | K23: CM-02, CM-05, CM-06, A-1, U-1, U-2, U-3, U-5 | L23: 신규 | M23: v1.5
A24: user_health_profiles | B24: 건강 정보 | C24: diseases | D24: 질환 | E24: jsonb | H24: Y | J24: 빈 목록은 앱이 넣음(DB 기본값 없음). 생활습관 질환 lifestyle_diseases.id 목록(HTN, DM2, DLP, CKD, IHD, STROKE, AF, COPD, OP, OA. 10/14 회의 3번 채연 안). 내 정보에서 선택. 분석은 처방전에 질병분류기호가 없을 때만 이 값으로 채움(출처 profile, 팩트표 kcd로 이음). 챗봇은 둘 다 씀 (10/19 수인 제안, 채연 확인 필요) | K24: CM-02, CM-05, CM-06, A-1, U-1, U-2, U-3, U-5 | L24: 신규 | M24: v1.5
A25: user_health_profiles | B25: 건강 정보 | C25: pregnant | D25: 임신 여부 | E25: varchar(10) | H25: N | J25: yes / no. 여성만 내 정보에서 선택. 성별을 M으로 바꾸면 비움. 비어 있으면 임신 금기 점검을 건너뛰고 결과에 알림 (10/14 디코) | K25: CM-02, CM-05, CM-06, A-1, U-1, U-2, U-3, U-5 | L25: 신규 | M25: v1.5
A26: user_health_profiles | B26: 건강 정보 | C26: dialysis | D26: 투석 여부 | E26: varchar(10) | H26: N | J26: yes / no / unknown. 팩트표 applies_when: dialysis (10/8 디코 채연 제안, 10/19 받기로 함) | K26: CM-02, CM-05, CM-06, A-1, U-1, U-2, U-3, U-5 | L26: 신규 | M26: v1.5
A27: user_health_profiles | B27: 건강 정보 | C27: height_cm | D27: 키 (cm) | E27: smallint | H27: N | J27: 내 정보에서 선택 (10/14 디코) | K27: CM-02, CM-05, CM-06, A-1, U-1, U-2, U-3, U-5 | L27: 신규 | M27: v1.5
A28: user_health_profiles | B28: 건강 정보 | C28: weight_kg | D28: 몸무게 (kg) | E28: numeric(4,1) | H28: N | J28: 내 정보에서 선택 (10/14 디코) | K28: CM-02, CM-05, CM-06, A-1, U-1, U-2, U-3, U-5 | L28: 신규 | M28: v1.5
A29: user_health_profiles | B29: 건강 정보 | C29: upcoming_exams | D29: 예정 검사 | E29: jsonb | H29: Y | J29: 빈 목록은 앱이 넣음(DB 기본값 없음). [{ name, date }]. name은 50자 이내, date는 YYYY-MM-DD. 내 정보에서 선택 (10/14 회의 3번) | K29: CM-02, CM-05, CM-06, A-1, U-1, U-2, U-3, U-5 | L29: 신규 | M29: v1.5
A30: user_health_profiles | B30: 건강 정보 | C30: created_at | D30: 생성 일시 | E30: timestamp | H30: N | I30: now() | K30: CM-02, CM-05, CM-06, A-1, U-1, U-2, U-3, U-5 | L30: 신규 | M30: v1.5
A31: user_health_profiles | B31: 건강 정보 | C31: updated_at | D31: 수정 일시 | E31: timestamp | H31: N | K31: CM-02, CM-05, CM-06, A-1, U-1, U-2, U-3, U-5 | L31: 신규 | M31: v1.5

Sheet 입력
A1: ERD v1.3 · 입력
A2: 채연 · 처방전 · 약봉투 · OCR · 약품 매칭
A4: 테이블 (영문) | B4: 테이블 (한글) | C4: 필드 (영문) | D4: 필드 (한글) | E4: 타입 | F4: 키 | G4: 참조 | H4: 필수 | I4: 기본값 | J4: 설명 | K4: 관련 화면 · API | L4: 변경 | M4: 최종 수정 | N4: 비고 (테이블 설명)
A5: ocr_jobs | B5: OCR 작업 | C5: id | D5: ID | E5: bigint | F5: PK | H5: Y | K5: OC-01 · O-1 · O-5 | L5: 신규 | M5: v1.2 | N5: v1.2 신규 · O-1 업로드는 202 + 작업 ID 반환, O-5로 상태 조회 (NFR-001 P95 3초 · NFR-002)
A6: ocr_jobs | B6: OCR 작업 | C6: user_id | D6: 사용자 ID | E6: bigint | F6: FK | G6: users.id | H6: Y | K6: OC-01 · O-1 · O-5 | L6: 신규 | M6: v1.2
A7: ocr_jobs | B7: OCR 작업 | C7: status | D7: 상태 | E7: varchar(20) | H7: Y | J7: queued / running / done / failed | K7: OC-01 · O-1 · O-5 | L7: 신규 | M7: v1.2
A8: ocr_jobs | B8: OCR 작업 | C8: file_count | D8: 사진 수 | E8: smallint | H8: Y | J8: 한 번에 올린 사진 수 (최대 5) | K8: OC-01 · O-1 · O-5 | L8: 신규 | M8: v1.2
A9: ocr_jobs | B9: OCR 작업 | C9: error_code | D9: 에러 코드 | E9: varchar(50) | H9: N | J9: 전체 실패 시 OCR_FAILED 등 | K9: OC-01 · O-1 · O-5 | L9: 신규 | M9: v1.2
A10: ocr_jobs | B10: OCR 작업 | C10: created_at | D10: 생성 일시 | E10: timestamp | H10: N | I10: now() | K10: OC-01 · O-1 · O-5 | L10: 신규 | M10: v1.2
A11: ocr_jobs | B11: OCR 작업 | C11: finished_at | D11: 종료 일시 | E11: timestamp | H11: N | K11: OC-01 · O-1 · O-5 | L11: 신규 | M11: v1.2
A12: ocr_jobs | B12: OCR 작업 | C12: duplicates | D12: 중복 사진 | E12: jsonb | H12: N | J12: 이미 있는 처방전이라 새로 저장하지 않은 사진 [{fileIndex, prescriptionId}] (10/14 중복 처방전 처리). 없으면 null | K12: OC-01 / O-1 / O-5 | L12: 신규 | M12: v1.5
A13: prescriptions | B13: 처방전 · 약봉투 | C13: id | D13: ID | E13: bigint | F13: PK | H13: Y | K13: OC-01 · OC-02 · O-1 · O-2 | L13: 기존 | M13: v0.1 | N13: 사진 1장 = 1행. 업로드된 원본 이미지는 OCR 처리 후 즉시 폐기
A14: prescriptions | B14: 처방전 · 약봉투 | C14: user_id | D14: 사용자 ID | E14: bigint | F14: FK | G14: users.id | H14: Y | K14: OC-01 · OC-02 · O-1 · O-2 | L14: 기존 | M14: v0.1
A15: prescriptions | B15: 처방전 · 약봉투 | C15: ocr_job_id | D15: OCR 작업 ID | E15: bigint | F15: FK | G15: ocr_jobs.id | H15: N | J15: 어느 업로드 작업에서 나온 사진인지 | K15: OC-01 · OC-02 · O-1 · O-2 | L15: 신규 | M15: v1.2
A16: prescriptions | B16: 처방전 · 약봉투 | C16: file_index | D16: 사진 순번 | E16: smallint | H16: N | J16: 작업 안에서 몇 번째 사진인지 (실패 사진 안내용) | K16: OC-01 · OC-02 · O-1 · O-2 | L16: 신규 | M16: v1.2
A17: prescriptions | B17: 처방전 · 약봉투 | C17: doc_type | D17: 문서 종류 | E17: varchar(20) | H17: Y | J17: prescription(처방전) / pill_bag(약봉투). 약봉투는 질병코드 없음 → RG-05-E1 | K17: OC-01 · OC-02 · O-1 · O-2 | L17: 신규 | M17: v1.0
A18: prescriptions | B18: 처방전 · 약봉투 | C18: issued_date | D18: 처방 교부일 · 조제일 | E18: date | H18: N | J18: 처방 교부일 (약봉투는 조제일) — 약봉투에는 교부일이 없고, 조제일이 약을 받은 날 | K18: OC-01 · OC-02 · O-1 · O-2 | L18: 수정 | M18: v1.3
A19: prescriptions | B19: 처방전 · 약봉투 | C19: hospital_name | D19: 병원 이름 | E19: varchar(200) | H19: N | K19: OC-01 · OC-02 · O-1 · O-2 | L19: 기존 | M19: v0.1
A20: prescriptions | B20: 처방전 · 약봉투 | C20: ocr_raw_text | D20: OCR 원문 | E20: text | H20: N | J20: OCR 원문 — 저장하지 않음 (10/15 결정, 칸은 남겨 두고 비워 둠) · 원본 이미지도 저장하지 않음 | K20: OC-01 · OC-02 · O-1 · O-2 | L20: 수정 | M20: v1.3
A21: prescriptions | B21: 처방전 · 약봉투 | C21: ocr_confidence | D21: OCR 신뢰도 | E21: decimal(5,4) | H21: N | K21: OC-01 · OC-02 · O-1 · O-2 | L21: 기존 | M21: v0.1
A22: prescriptions | B22: 처방전 · 약봉투 | C22: quality_flag | D22: 사진 품질 표시 | E22: varchar(20) | H22: N | J22: ok / low (OC-01-E1에서 "그래도 계속 진행" 시) | K22: OC-01 · OC-02 · O-1 · O-2 | L22: 신규 | M22: v1.0
A23: prescriptions | B23: 처방전 · 약봉투 | C23: notices | D23: 읽기 확인 표시 | E23: jsonb | H23: N | J23: 사진을 읽을 때 사용자가 확인해야 할 점 문장 목록 (줄 수 불일치 · 칸 순서 추정 · 날짜 이상 등). 없으면 null | K23: OC-01 · OC-02 · O-1 · O-2 | L23: 신규 | M23: v1.3
A24: prescriptions | B24: 처방전 · 약봉투 | C24: content_key | D24: 같은 처방전 판별값 | E24: varchar(64) | H24: N | J24: 같은 처방전인지 가리는 해시 (병원, 교부일, 약 목록). 인덱스 | K24: OC-01 / O-1 / O-5 | L24: 신규 | M24: v1.5
A25: prescriptions | B25: 처방전 · 약봉투 | C25: created_at | D25: 생성 일시 | E25: timestamp | H25: N | I25: now() | K25: OC-01 · OC-02 · O-1 · O-2 | L25: 기존 | M25: v0.1
A26: prescription_diseases | B26: 처방전 질병코드 | C26: id | D26: ID | E26: bigint | F26: PK | H26: Y | J26: 코드 구현 맞춤 — Tortoise는 복합 PK를 지원하지 않아 id를 PK로 두고 원래 PK 두 칸은 unique로 | K26: O-2 · R-4 | L26: 신규 | M26: v1.3 | N26: v1.0 신규 · 처방전 질병분류기호는 주상병 + 부상병 여러 개 · v1.3 id PK + (prescription_id, disease_id) UQ
A27: prescription_diseases | B27: 처방전 질병코드 | C27: prescription_id | D27: 처방전 ID | E27: bigint | F27: FK | G27: prescriptions.id | H27: Y | K27: O-2 · R-4 | L27: 신규 | M27: v1.3
A28: prescription_diseases | B28: 처방전 질병코드 | C28: disease_id | D28: 상병 코드 | E28: varchar(10) | F28: FK | G28: diseases.code | H28: Y | J28: 값은 상병기호 (예: I10). (prescription_id, disease_id) UQ — 칸 이름은 Tortoise 규칙에 맞춤 | K28: O-2 · R-4 | L28: 신규 | M28: v1.3
A29: prescription_diseases | B29: 처방전 질병코드 | C29: is_main | D29: 주상병 여부 | E29: boolean | H29: N | J29: 주상병 여부 | K29: O-2 · R-4 | L29: 신규 | M29: v1.0
A30: prescription_items | B30: 처방 약품 | C30: id | D30: ID | E30: bigint | F30: PK | H30: Y | K30: OC-02 · O-2 · O-3 | L30: 기존 | M30: v0.1 | N30: needs_confirm · unmatched가 남아 있으면 분석 시작 불가 (REQ-033). 1일 총량 = dose_per_time * times_per_day. 약이 정해졌으면(auto · user_confirmed) edi_code · item_seq 중 하나는 있음
A31: prescription_items | B31: 처방 약품 | C31: prescription_id | D31: 처방전 ID | E31: bigint | F31: FK | G31: prescriptions.id | H31: Y | K31: OC-02 · O-2 · O-3 | L31: 기존 | M31: v0.1
A32: prescription_items | B32: 처방 약품 | C32: edi_code | D32: EDI 제품코드 | E32: varchar(9) | F32: FK | G32: drug_products.edi_code | H32: N | J32: 매칭 실패 · 제외 · 급여목록에 없는 약이면 null | K32: OC-02 · O-2 · O-3 | L32: 수정 | M32: v1.3
A33: prescription_items | B33: 처방 약품 | C33: item_seq | D33: 품목기준코드 | E33: varchar(9) | F33: FK | G33: drug_details.item_seq | H33: N | J33: 급여목록에 없는 약(일반약 등)만 채움 — 있는 약은 edi_code로 약 정보까지 이어짐 | K33: OC-02 · O-2 · O-3 | L33: 신규 | M33: v1.3
A34: prescription_items | B34: 처방 약품 | C34: raw_name | D34: 인식된 약품명 | E34: varchar(300) | H34: Y | J34: OCR이 읽은 원문 약품명 | K34: OC-02 · O-2 · O-3 | L34: 기존 | M34: v0.1
A35: prescription_items | B35: 처방 약품 | C35: match_score | D35: 매칭 점수 | E35: decimal(5,4) | H35: N | K35: OC-02 · O-2 · O-3 | L35: 수정 | M35: v1.0
A36: prescription_items | B36: 처방 약품 | C36: match_status | D36: 매칭 상태 | E36: varchar(20) | H36: Y | J36: auto / needs_confirm / user_confirmed / unmatched / excluded(빼고 진행) | K36: OC-02 · O-2 · O-3 | L36: 수정 | M36: v1.0
A37: prescription_items | B37: 처방 약품 | C37: dose_per_time | D37: 1회 투여량 | E37: decimal(10,3) | H37: N | K37: OC-02 · O-2 · O-3 | L37: 수정 | M37: v1.0
A38: prescription_items | B38: 처방 약품 | C38: times_per_day | D38: 1일 투여 횟수 | E38: smallint | H38: N | K38: OC-02 · O-2 · O-3 | L38: 수정 | M38: v1.0
A39: prescription_items | B39: 처방 약품 | C39: total_days | D39: 총 투약일수 | E39: smallint | H39: N | K39: OC-02 · O-2 · O-3 | L39: 수정 | M39: v1.0
A40: prescription_items | B40: 처방 약품 | C40: timing | D40: 복용 시점 | E40: varchar(50) | H40: N | J40: 아침 식후 등 | K40: OC-02 · O-2 · O-3 | L40: 수정 | M40: v1.0
A41: prescription_items | B41: 처방 약품 | C41: guidance | D41: 약국 인쇄 복약 안내 | E41: jsonb | H41: N | J41: 약봉투만 채움, 마스킹 후 저장. 없으면 null | K41: OC-02 · O-2 · O-3 | L41: 신규 | M41: v1.3
...

Sheet 분석
A1: ERD v1.3 · 분석
A2: 채연 · 분석 작업 · 안전성 경고 · 안내문 · 피드백
A4: 테이블 (영문) | B4: 테이블 (한글) | C4: 필드 (영문) | D4: 필드 (한글) | E4: 타입 | F4: 키 | G4: 참조 | H4: 필수 | I4: 기본값 | J4: 설명 | K4: 관련 화면 · API | L4: 변경 | M4: 최종 수정 | N4: 비고 (테이블 설명)
A5: analyses | B5: 분석 작업 | C5: id | D5: ID | E5: bigint | F5: PK | H5: Y | K5: RG-01 · RG-01-E1 · CM-04 · R-1~3 · R-7 · R-8 | L5: 기존 | M5: v0.1 | N5: v1.0 · prescription_id 칸 삭제 → analysis_prescriptions로 1:N. job_id 대신 id로 폴링
A6: analyses | B6: 분석 작업 | C6: user_id | D6: 사용자 ID | E6: bigint | F6: FK | G6: users.id | H6: Y | K6: RG-01 · RG-01-E1 · CM-04 · R-1~3 · R-7 · R-8 | L6: 기존 | M6: v0.1
A7: analyses | B7: 분석 작업 | C7: status | D7: 상태 | E7: varchar(20) | H7: Y | J7: queued / running / done / failed | K7: RG-01 · RG-01-E1 · CM-04 · R-1~3 · R-7 · R-8 | L7: 수정 | M7: v1.0
A8: analyses | B8: 분석 작업 | C8: current_step | D8: 진행 단계 | E8: varchar(30) | H8: N | J8: drug_info / safety_check / guide_generation (RG-01 진행 단계) | K8: RG-01 · RG-01-E1 · CM-04 · R-1~3 · R-7 · R-8 | L8: 신규 | M8: v1.0
A9: analyses | B9: 분석 작업 | C9: failed_step | D9: 실패 단계 | E9: varchar(30) | H9: N | J9: 실패한 단계 (RG-01-E1) | K9: RG-01 · RG-01-E1 · CM-04 · R-1~3 · R-7 · R-8 | L9: 신규 | M9: v1.0
A10: analyses | B10: 분석 작업 | C10: error_code | D10: 에러 코드 | E10: varchar(50) | H10: N | J10: GUIDE_GENERATION_FAILED / SAFETY_CHECK_FAILED / TIMEOUT | K10: RG-01 · RG-01-E1 · CM-04 · R-1~3 · R-7 · R-8 | L10: 신규 | M10: v1.0
A11: analyses | B11: 분석 작업 | C11: retry_count | D11: 재시도 횟수 | E11: smallint | H11: N | I11: 0 | J11: 3회 초과 시 재시도 막음 (REQ-055) | K11: RG-01 · RG-01-E1 · CM-04 · R-1~3 · R-7 · R-8 | L11: 신규 | M11: v1.0
A12: analyses | B12: 분석 작업 | C12: user_birth_year | D12: 분석 시점 출생연도 | E12: smallint | H12: N | J12: 분석 시점 출생연도 스냅샷 — 정보 수정해도 지난 결과는 그대로 (CM-06) | K12: RG-01 · RG-01-E1 · CM-04 · R-1~3 · R-7 · R-8 | L12: 신규 | M12: v1.0
A13: analyses | B13: 분석 작업 | C13: health_snapshot | D13: 분석 시점 건강 정보 | E13: jsonb | H13: N | J13: 분석 시점 건강 정보(user_health_profiles) 스냅샷. 정보를 고쳐도 지난 결과는 그대로 (10/14 회의 3번 채연 안, 이슈 #101) | K13: RG-01 · RG-01-E1 · CM-04 · R-1~3 · R-7 · R-8 | L13: 신규 | M13: v1.5
A14: analyses | B14: 분석 작업 | C14: started_at | D14: 시작 일시 | E14: timestamp | H14: N | K14: RG-01 · RG-01-E1 · CM-04 · R-1~3 · R-7 · R-8 | L14: 기존 | M14: v0.1
A15: analyses | B15: 분석 작업 | C15: finished_at | D15: 종료 일시 | E15: timestamp | H15: N | K15: RG-01 · RG-01-E1 · CM-04 · R-1~3 · R-7 · R-8 | L15: 기존 | M15: v0.1
A16: analyses | B16: 분석 작업 | C16: created_at | D16: 생성 일시 | E16: timestamp | H16: N | I16: now() | K16: RG-01 · RG-01-E1 · CM-04 · R-1~3 · R-7 · R-8 | L16: 신규 | M16: v1.0
A17: analysis_prescriptions | B17: 분석-처방전 연결 | C17: analysis_id | D17: 분석 ID | E17: bigint | F17: PK · FK | G17: analyses.id | H17: Y | K17: R-1 | L17: 신규 | M17: v1.0 | N17: v1.0 신규 · 여러 병원 처방전을 한 번에 점검 (최대 5장, REQ-013)
A18: analysis_prescriptions | B18: 분석-처방전 연결 | C18: prescription_id | D18: 처방전 ID | E18: bigint | F18: PK · FK | G18: prescriptions.id | H18: Y | K18: R-1 | L18: 신규 | M18: v1.0
A19: analysis_diseases | B19: 분석 질환 | C19: analysis_id | D19: 분석 ID | E19: bigint | F19: PK · FK | G19: analyses.id | H19: Y | K19: RG-05 · RG-05-E1 · R-6 | L19: 신규 | M19: v1.0 | N19: v1.0 신규 · 생활습관 가이드 조회 기준
A20: analysis_diseases | B20: 분석 질환 | C20: disease_code | D20: 상병 코드 | E20: varchar(10) | F20: PK · FK | G20: diseases.code | H20: Y | K20: RG-05 · RG-05-E1 · R-6 | L20: 신규 | M20: v1.0
A21: analysis_diseases | B21: 분석 질환 | C21: origin | D21: 출처 구분 | E21: varchar(20) | H21: Y | J21: prescription(처방전 코드) / user(RG-05-E1에서 직접 선택) | K21: RG-05 · RG-05-E1 · R-6 | L21: 신규 | M21: v1.0
A22: analysis_warnings | B22: 안전성 경고 | C22: id | D22: ID | E22: bigint | F22: PK | H22: Y | K22: RG-02 · RG-02-E1 · RG-03 · R-4 · R-5 | L22: 기존 | M22: v0.1 | N22: DB 조회로 결정적으로 산출. 0건이면 RG-02-E1
A23: analysis_warnings | B23: 안전성 경고 | C23: analysis_id | D23: 분석 ID | E23: bigint | F23: FK | G23: analyses.id | H23: Y | K23: RG-02 · RG-02-E1 · RG-03 · R-4 · R-5 | L23: 기존 | M23: v0.1
A24: analysis_warnings | B24: 안전성 경고 | C24: warning_type | D24: 경고 종류 | E24: varchar(30) | H24: Y | J24: interaction / duplicate_ingredient / duplicate_efficacy / elderly / age / pregnancy / dose_exceed / polypharmacy(v1.0 🟡) | K24: RG-02 · RG-02-E1 · RG-03 · R-4 · R-5 | L24: 수정 | M24: v1.0
A25: analysis_warnings | B25: 안전성 경고 | C25: severity | D25: 경고 등급 | E25: varchar(10) | H25: Y | J25: danger / caution / info | K25: RG-02 · RG-02-E1 · RG-03 · R-4 · R-5 | L25: 수정 | M25: v1.0
A26: analysis_warnings | B26: 안전성 경고 | C26: item_id_a | D26: 대상 약 항목 ID | E26: bigint | F26: FK | G26: prescription_items.id | H26: N | J26: 약 이름 대신 항목 참조 (처방 병원 표시용) | K26: RG-02 · RG-02-E1 · RG-03 · R-4 · R-5 | L26: 신규 | M26: v1.0
A27: analysis_warnings | B27: 안전성 경고 | C27: item_id_b | D27: 상대 약 항목 ID | E27: bigint | F27: FK | G27: prescription_items.id | H27: N | J27: 상대 약 (병용금기 · 중복) | K27: RG-02 · RG-02-E1 · RG-03 · R-4 · R-5 | L27: 신규 | M27: v1.0
A28: analysis_warnings | B28: 안전성 경고 | C28: reason | D28: 사유 | E28: text | H28: N | J28: DUR 금기 사유 원문 | K28: RG-02 · RG-02-E1 · RG-03 · R-4 · R-5 | L28: 수정 | M28: v1.0
A29: analysis_warnings | B29: 안전성 경고 | C29: summary | D29: 화면 표시 문장 | E29: text | H29: N | J29: 화면 표시 문장 (템플릿, AI 생성 아님 · NFR-032) | K29: RG-02 · RG-02-E1 · RG-03 · R-4 · R-5 | L29: 신규 | M29: v1.0
A30: analysis_warnings | B30: 안전성 경고 | C30: source | D30: 고시명 | E30: varchar(100) | H30: N | J30: 식약처 고시명 | K30: RG-02 · RG-02-E1 · RG-03 · R-4 · R-5 | L30: 수정 | M30: v1.0
A31: analysis_warnings | B31: 안전성 경고 | C31: notice_date | D31: 고시일 | E31: date | H31: N | K31: RG-02 · RG-02-E1 · RG-03 · R-4 · R-5 | L31: 신규 | M31: v1.0
A32: analysis_warnings | B32: 안전성 경고 | C32: daily_total | D32: 1일 총 복용량 | E32: decimal(12,3) | H32: N | J32: 1일 최대용량 초과일 때만 | K32: RG-02 · RG-02-E1 · RG-03 · R-4 · R-5 | L32: 신규 | M32: v1.0
A33: analysis_warnings | B33: 안전성 경고 | C33: max_daily | D33: 1일 최대 기준량 | E33: decimal(12,3) | H33: N | K33: RG-02 · RG-02-E1 · RG-03 · R-4 · R-5 | L33: 신규 | M33: v1.0
A34: analysis_warnings | B34: 안전성 경고 | C34: detail | D34: 경고 세부 | E34: jsonb | H34: N | J34: 약이 3개 이상인 경고의 전체 항목 번호, 성분, 근거 구분 | K34: RG-02 / R-4 | L34: 신규 | M34: v1.5
A35: guides | B35: 복약 · 생활습관 안내문 | C35: id | D35: ID | E35: bigint | F35: PK | H35: Y | K35: RG-04 · RG-05 · R-4 · R-10 | L35: 기존 | M35: v0.1
A36: guides | B36: 복약 · 생활습관 안내문 | C36: analysis_id | D36: 분석 ID | E36: bigint | F36: FK | G36: analyses.id | H36: Y | K36: RG-04 · RG-05 · R-4 · R-10 | L36: 기존 | M36: v0.1
A37: guides | B37: 복약 · 생활습관 안내문 | C37: section | D37: 안내 구분 | E37: varchar(30) | H37: N | J37: medication / lifestyle | K37: RG-04 · RG-05 · R-4 · R-10 | L37: 수정 | M37: v1.0
A38: guides | B38: 복약 · 생활습관 안내문 | C38: status | D38: 상태 | E38: varchar(20) | H38: N | J38: done / failed (부분 결과 RG-01-E1 → RG-04 · RG-05 "만들지 못했어요") | K38: RG-04 · RG-05 · R-4 · R-10 | L38: 신규 | M38: v1.0
A39: guides | B39: 복약 · 생활습관 안내문 | C39: content | D39: 안내 내용 (JSON) | E39: jsonb | H39: N | J39: 항목 고정 JSON (약별 purpose · howToTake · caution · source) — 결과 일관성 NFR-030 | K39: RG-04 · RG-05 · R-4 · R-10 | L39: 수정 | M39: v1.0
A40: guides | B40: 복약 · 생활습관 안내문 | C40: prompt_ver | D40: 프롬프트 버전 | E40: varchar(20) | H40: N | K40: RG-04 · RG-05 · R-4 · R-10 | L40: 수정 | M40: v1.0
A41: guides | B41: 복약 · 생활습관 안내문 | C41: model_name | D41: 모델 이름 | E41: varchar(50) | H41: N | K41: RG-04 · RG-05 · R-4 · R-10 | L41: 수정 | M41: v1.0
...

Sheet 챗봇
A1: ERD v1.3 · 챗봇
A2: 수인 · 대화 · 메시지
A4: 테이블 (영문) | B4: 테이블 (한글) | C4: 필드 (영문) | D4: 필드 (한글) | E4: 타입 | F4: 키 | G4: 참조 | H4: 필수 | I4: 기본값 | J4: 설명 | K4: 관련 화면 · API | L4: 변경 | M4: 최종 수정 | N4: 비고 (테이블 설명)
A5: chat_sessions | B5: 대화 | C5: id | D5: ID | E5: bigint | F5: PK | H5: Y | K5: CB-01~03 · H-1 · H-4 · H-5 | L5: 기존 | M5: v1.3 | N5: 날짜별 여러 대화 구조 (PR #3 10/2 답변으로 확정). 1단계는 하루 한 대화로 쓰고, 분석 결과에서 들어오면 맥락 카드를 붙임 (H-7)
A6: chat_sessions | B6: 대화 | C6: user_id | D6: 사용자 ID | E6: bigint | F6: FK | G6: users.id | H6: Y | K6: CB-01~03 · H-1 · H-4 · H-5 | L6: 기존 | M6: v0.1
A7: chat_sessions | B7: 대화 | C7: analysis_id | D7: 분석 ID | E7: bigint | F7: FK | G7: analyses.id | H7: N | J7: null이면 일반 질문 모드 (분석 전) | K7: CB-01~03 · H-1 · H-4 · H-5 | L7: 수정 | M7: v1.0
A8: chat_sessions | B8: 대화 | C8: context_type | D8: 시작 맥락 종류 | E8: varchar(20) | H8: N | J8: warning / drug (CB-01-E2에서 무엇을 알고 시작했는지) | K8: CB-01~03 · H-1 · H-4 · H-5 | L8: 신규 | M8: v1.0
A9: chat_sessions | B9: 대화 | C9: context_ref | D9: 시작 맥락 ID | E9: bigint | H9: N | J9: analysis_warnings.id 또는 prescription_items.id | K9: CB-01~03 · H-1 · H-4 · H-5 | L9: 신규 | M9: v1.0
A10: chat_sessions | B10: 대화 | C10: title | D10: 대화 제목 | E10: varchar(100) | H10: N | J10: 🟡 수인 확인 · 대화 제목 자동 생성 · 수정 (CB-03) | K10: CB-01~03 · H-1 · H-4 · H-5 | L10: 신규 | M10: v1.0
A11: chat_sessions | B11: 대화 | C11: summary | D11: 대화 요약 | E11: text | H11: N | J11: 🟡 수인 확인 · 오래된 대화 요약 (맥락 압축) | K11: CB-01~03 · H-1 · H-4 · H-5 | L11: 신규 | M11: v1.0
A12: chat_sessions | B12: 대화 | C12: created_at | D12: 생성 일시 | E12: timestamp | H12: N | I12: now() | K12: CB-01~03 · H-1 · H-4 · H-5 | L12: 기존 | M12: v0.1
A13: chat_sessions | B13: 대화 | C13: updated_at | D13: 수정 일시 | E13: timestamp | H13: N | K13: CB-01~03 · H-1 · H-4 · H-5 | L13: 신규 | M13: v1.0
A14: chat_sessions | B14: 대화 | C14: client_request_id | D14: 요청 번호 | E14: varchar(64) | H14: N | J14: 앱이 만든 요청 번호 — H-1을 다시 보내도 대화를 새로 만들지 않음. (user_id, client_request_id) UQ | K14: CB-01~03 · H-1 · H-4 · H-5 | L14: 신규 | M14: v1.3
A15: chat_sessions | B15: 대화 | C15: safety_mode_until | D15: 안전 모드 종료 시각 | E15: timestamp | H15: N | J15: 자해 표현 뒤 안전 모드가 끝나는 시각. null이면 안전 모드 아님 (이슈 #88) | K15: CB-01~03 / H-1 | L15: 신규 | M15: v1.5
A16: chat_messages | B16: 대화 메시지 | C16: id | D16: ID | E16: bigint | F16: PK | H16: Y | K16: CB-01 · H-2 · H-3 | L16: 기존 | M16: v0.1
A17: chat_messages | B17: 대화 메시지 | C17: session_id | D17: 대화 ID | E17: bigint | F17: FK | G17: chat_sessions.id | H17: Y | K17: CB-01 · H-2 · H-3 | L17: 기존 | M17: v0.1
A18: chat_messages | B18: 대화 메시지 | C18: role | D18: 발화자 | E18: varchar(10) | H18: N | J18: user / assistant | K18: CB-01 · H-2 · H-3 | L18: 기존 | M18: v0.1
A19: chat_messages | B19: 대화 메시지 | C19: content | D19: 메시지 내용 | E19: text | H19: N | K19: CB-01 · H-2 · H-3 | L19: 기존 | M19: v0.1
A20: chat_messages | B20: 대화 메시지 | C20: answer_type | D20: 답변 종류 | E20: varchar(20) | H20: N | J20: normal / clarify(정보 확인) / partial(일부만 확인됐어요) / no_evidence(확인이 어렵습니다) / refer(의료진 상담 필요) / emergency(긴급 안내) / crisis(도움 연결) — error는 프론트 전용이라 저장 안 함 (API v1.3 H-3) | K20: CB-01 · H-2 · H-3 | L20: 신규 | M20: v1.3
A21: chat_messages | B21: 대화 메시지 | C21: sources | D21: 답변 출처 | E21: jsonb | H21: N | J21: 답변 근거 출처 — [{ title, basedOn }] 형식 (API v1.3 H-3) | K21: CB-01 · H-2 · H-3 | L21: 신규 | M21: v1.3
A22: chat_messages | B22: 대화 메시지 | C22: client_request_id | D22: 요청 번호 | E22: varchar(64) | H22: N | J22: 앱이 만든 요청 번호 — 다시 시도(CB-01-E6) 때 같은 질문을 두 번 저장하지 않음. (session_id, client_request_id) UQ | K22: CB-01 · H-2 · H-3 · H-7 | L22: 신규 | M22: v1.3
A23: chat_messages | B23: 대화 메시지 | C23: context_card | D23: 맥락 카드 | E23: jsonb | H23: N | J23: 1단계 하루 한 대화에서 붙인 분석 맥락 { analysisId, context } — 다시 들어왔을 때 카드를 그대로 그림 (H-7) | K23: CB-01 · H-2 · H-3 · H-7 | L23: 신규 | M23: v1.3
A24: chat_messages | B24: 대화 메시지 | C24: safety_card | D24: 안전성 점검 카드 | E24: jsonb | H24: N | J24: 안전성 점검 결과 카드 { analysisId, warningIds }. 카드가 붙는 답도 answer_type은 normal. 카드가 없으면 비어 있음 (이슈 #88) | K24: CB-01 / H-2 / H-3 | L24: 신규 | M24: v1.5
A25: chat_messages | B25: 대화 메시지 | C25: status | D25: 답변 상태 | E25: varchar(20) | H25: Y | I25: 'done' | J25: generating 또는 done. 화면을 나갔다 와도 만드는 중인 답을 알 수 있게 함. 사용자 줄은 늘 done. 실패는 두지 않음: 서버가 실패하면 답을 저장하지 않고 앱이 E6을 보여 줌 (이슈 #88) | K25: CB-01 / H-2 / H-3 | L25: 신규 | M25: v1.5
A26: chat_messages | B26: 대화 메시지 | C26: model | D26: 모델 이름 | E26: varchar(50) | H26: N | J26: 답을 만든 모델 이름 (예: gpt-4o-mini). 답변마다 비용과 시간을 재려고 둠. assistant 줄만 채움 (이슈 #88) | K26: CB-01 / H-2 / H-3 | L26: 신규 | M26: v1.5
A27: chat_messages | B27: 대화 메시지 | C27: prompt_tokens | D27: 입력 토큰 수 | E27: int | H27: N | J27: 답 하나에 AI를 여러 번 부르면 합친 값. assistant 줄만 채움 (이슈 #88) | K27: CB-01 / H-2 / H-3 | L27: 신규 | M27: v1.5
A28: chat_messages | B28: 대화 메시지 | C28: completion_tokens | D28: 출력 토큰 수 | E28: int | H28: N | J28: 출력 토큰 수 합친 값. assistant 줄만 채움 (이슈 #88) | K28: CB-01 / H-2 / H-3 | L28: 신규 | M28: v1.5
A29: chat_messages | B29: 대화 메시지 | C29: latency_ms | D29: 걸린 시간(ms) | E29: int | H29: N | J29: 질문을 받은 때부터 답을 저장할 때까지 걸린 시간, 밀리초. assistant 줄만 채움 (이슈 #88) | K29: CB-01 / H-2 / H-3 | L29: 신규 | M29: v1.5
A30: chat_messages | B30: 대화 메시지 | C30: created_at | D30: 생성 일시 | E30: timestamp | H30: N | I30: now() | K30: CB-01 · H-2 · H-3 | L30: 기존 | M30: v0.1

Sheet 실천·보상
A1: ERD v1.3 · 실천·보상
A2: 성규 · 추천 · 목표 · 기록 · 포인트
A4: 테이블 (영문) | B4: 테이블 (한글) | C4: 필드 (영문) | D4: 필드 (한글) | E4: 타입 | F4: 키 | G4: 참조 | H4: 필수 | I4: 기본값 | J4: 설명 | K4: 관련 화면 · API | L4: 변경 | M4: 최종 수정 | N4: 비고 (테이블 설명)
A5: recommendations | B5: 생활습관 추천 | C5: id | D5: ID | E5: bigint | F5: PK | H5: Y | K5: RW-01 · RG-05 · P-1 | L5: 신규 | M5: v1.0 | N5: AI 추천만으로는 목표가 되지 않음 — 사용자가 골라야 habit_goals 생성 (REQ-110)
A6: recommendations | B6: 생활습관 추천 | C6: analysis_id | D6: 분석 ID | E6: bigint | F6: FK | G6: analyses.id | H6: Y | K6: RW-01 · RG-05 · P-1 | L6: 신규 | M6: v1.0
A7: recommendations | B7: 생활습관 추천 | C7: guide_id | D7: 생활습관 팩트 ID | E7: bigint | F7: FK | G7: lifestyle_guides.id | H7: N | J7: 질환 기준 추천일 때 | K7: RW-01 · RG-05 · P-1 | L7: 신규 | M7: v1.0
A8: recommendations | B8: 생활습관 추천 | C8: medication_link_id | D8: 약-생활수칙 연결 ID | E8: bigint | F8: FK | G8: lifestyle_medication_links.id | H8: N | J8: 약 기준 추천일 때 | K8: RW-01 · RG-05 · P-1 | L8: 신규 | M8: v1.0
A9: recommendations | B9: 생활습관 추천 | C9: action_id | D9: 실천 항목 ID | E9: bigint | F9: FK | G9: lifestyle_guide_actions.id | H9: N | J9: 어떤 실천 항목(출처 포함)에서 나온 추천인지 | K9: RW-01 · RG-05 · P-1 | L9: 신규 | M9: v1.2
A10: recommendations | B10: 생활습관 추천 | C10: title | D10: 제목 | E10: varchar(100) | H10: Y | J10: 국물 남기기 등 | K10: RW-01 · RG-05 · P-1 | L10: 신규 | M10: v1.0
A11: recommendations | B11: 생활습관 추천 | C11: reason_label | D11: 추천 이유 라벨 | E11: varchar(50) | H11: N | J11: 고혈압 / 약과 함께 등 (화면 라벨) | K11: RW-01 · RG-05 · P-1 | L11: 신규 | M11: v1.0
A12: recommendations | B12: 생활습관 추천 | C12: goal_type | D12: 목표 유형 | E12: varchar(20) | H12: N | J12: check / quantity | K12: RW-01 · RG-05 · P-1 | L12: 신규 | M12: v1.0
A13: recommendations | B13: 생활습관 추천 | C13: target_value | D13: 목표 수치 | E13: decimal(10,2) | H13: N | J13: 수량형 목표 (예: 30) | K13: RW-01 · RG-05 · P-1 | L13: 신규 | M13: v1.0
A14: recommendations | B14: 생활습관 추천 | C14: unit | D14: 단위 | E14: varchar(20) | H14: N | J14: 분 등 | K14: RW-01 · RG-05 · P-1 | L14: 신규 | M14: v1.0
A15: recommendations | B15: 생활습관 추천 | C15: rank | D15: 순위 | E15: smallint | H15: N | K15: RW-01 · RG-05 · P-1 | L15: 신규 | M15: v1.0
A16: habit_goals | B16: 실천 목표 | C16: id | D16: ID | E16: bigint | F16: PK | H16: Y | K16: RW-02 · P-2 · P-3 | L16: 신규 | M16: v1.0 | N16: 최대 3개 활성 (REQ-111)
A17: habit_goals | B17: 실천 목표 | C17: user_id | D17: 사용자 ID | E17: bigint | F17: FK | G17: users.id | H17: Y | K17: RW-02 · P-2 · P-3 | L17: 신규 | M17: v1.0
A18: habit_goals | B18: 실천 목표 | C18: recommendation_id | D18: 추천 ID | E18: bigint | F18: FK | G18: recommendations.id | H18: N | J18: 추천(분석)이 지워지면 비움 (ON DELETE SET NULL) — 목표 · 기록 · 포인트는 남김 (기록 삭제 · 동의 철회) | K18: RW-02 · P-2 · P-3 | L18: 신규 | M18: v1.3
A19: habit_goals | B19: 실천 목표 | C19: title | D19: 제목 | E19: varchar(100) | H19: Y | K19: RW-02 · P-2 · P-3 | L19: 신규 | M19: v1.0
A20: habit_goals | B20: 실천 목표 | C20: goal_type | D20: 목표 유형 | E20: varchar(20) | H20: Y | J20: check / quantity | K20: RW-02 · P-2 · P-3 | L20: 신규 | M20: v1.0
A21: habit_goals | B21: 실천 목표 | C21: target_value | D21: 목표 수치 | E21: decimal(10,2) | H21: N | K21: RW-02 · P-2 · P-3 | L21: 신규 | M21: v1.0
A22: habit_goals | B22: 실천 목표 | C22: unit | D22: 단위 | E22: varchar(20) | H22: N | K22: RW-02 · P-2 · P-3 | L22: 신규 | M22: v1.0
A23: habit_goals | B23: 실천 목표 | C23: start_date | D23: 시작일 | E23: date | H23: Y | K23: RW-02 · P-2 · P-3 | L23: 신규 | M23: v1.0
A24: habit_goals | B24: 실천 목표 | C24: end_date | D24: 종료일 | E24: date | H24: N | J24: 주 단위 (REQ-116 재선택 흐름 🟡) | K24: RW-02 · P-2 · P-3 | L24: 신규 | M24: v1.0
A25: habit_goals | B25: 실천 목표 | C25: status | D25: 상태 | E25: varchar(20) | H25: N | J25: active / ended | K25: RW-02 · P-2 · P-3 | L25: 신규 | M25: v1.0
A26: habit_goals | B26: 실천 목표 | C26: created_at | D26: 생성 일시 | E26: timestamp | H26: N | I26: now() | K26: RW-02 · P-2 · P-3 | L26: 신규 | M26: v1.0
A27: habit_records | B27: 실천 기록 | C27: id | D27: ID | E27: bigint | F27: PK | H27: Y | K27: RW-03 · RW-04 · P-4 · P-5 | L27: 신규 | M27: v1.0
A28: habit_records | B28: 실천 기록 | C28: goal_id | D28: 목표 ID | E28: bigint | F28: FK | G28: habit_goals.id | H28: Y | K28: RW-03 · RW-04 · P-4 · P-5 | L28: 신규 | M28: v1.0
A29: habit_records | B29: 실천 기록 | C29: record_date | D29: 기록일 | E29: date | H29: Y | K29: RW-03 · RW-04 · P-4 · P-5 | L29: 신규 | M29: v1.0
A30: habit_records | B30: 실천 기록 | C30: value | D30: 기록 수치 | E30: decimal(10,2) | H30: N | J30: 수량형 누적값 | K30: RW-03 · RW-04 · P-4 · P-5 | L30: 신규 | M30: v1.0
A31: habit_records | B31: 실천 기록 | C31: completed | D31: 완료 여부 | E31: boolean | H31: Y | I31: false | K31: RW-03 · RW-04 · P-4 · P-5 | L31: 신규 | M31: v1.0
A32: habit_records | B32: 실천 기록 | C32: created_at | D32: 생성 일시 | E32: timestamp | H32: N | I32: now() | K32: RW-03 · RW-04 · P-4 · P-5 | L32: 신규 | M32: v1.0 | N32: 인덱스: (goal_id, record_date) [unique, note: '같은 날 중복 완료 방지']
A33: rewards | B33: 포인트 | C33: id | D33: ID | E33: bigint | F33: PK | H33: Y | K33: RW-05 · RW-06 · P-6 | L33: 신규 | M33: v1.0
A34: rewards | B34: 포인트 | C34: user_id | D34: 사용자 ID | E34: bigint | F34: FK | G34: users.id | H34: Y | K34: RW-05 · RW-06 · P-6 | L34: 신규 | M34: v1.0
A35: rewards | B35: 포인트 | C35: record_id | D35: 실천 기록 ID | E35: bigint | F35: FK | G35: habit_records.id | H35: N | J35: 목표 완료 보상일 때 (all_done은 비움) | K35: RW-05 · RW-06 · P-6 | L35: 신규 | M35: v1.3
A36: rewards | B36: 포인트 | C36: reward_type | D36: 보상 종류 | E36: varchar(20) | H36: Y | J36: goal_done / all_done(하루 전체 완료 보너스) | K36: RW-05 · RW-06 · P-6 | L36: 신규 | M36: v1.0
A37: rewards | B37: 포인트 | C37: points | D37: 포인트 | E37: int | H37: Y | K37: RW-05 · RW-06 · P-6 | L37: 신규 | M37: v1.0
A38: rewards | B38: 포인트 | C38: reward_date | D38: 지급일 | E38: date | H38: Y | K38: RW-05 · RW-06 · P-6 | L38: 신규 | M38: v1.0
A39: rewards | B39: 포인트 | C39: created_at | D39: 생성 일시 | E39: timestamp | H39: N | I39: now() | K39: RW-05 · RW-06 · P-6 | L39: 신규 | M39: v1.0 | N39: 인덱스: (user_id, reward_date, reward_type, record_id) [unique, NULLS NOT DISTINCT] — 중복 지급 방지 (REQ-113). record_id가 빈 all_done도 하루 1번만 (PostgreSQL 15+, Tortoise로 안 만들어져 마이그레이션에 SQL 직접)

Sheet 마스터
A1: ERD v1.3 · 마스터
A2: 채연 · 공공데이터 사전 적재 (의약품 · DUR · 중복 · 질병 · 생활습관)
A4: 테이블 (영문) | B4: 테이블 (한글) | C4: 필드 (영문) | D4: 필드 (한글) | E4: 타입 | F4: 키 | G4: 참조 | H4: 필수 | I4: 기본값 | J4: 설명 | K4: 관련 화면 · API | L4: 변경 | M4: 최종 수정 | N4: 비고 (테이블 설명)
A5: drug_products | B5: 의약품 제품 | C5: edi_code | D5: EDI 제품코드 | E5: varchar(9) | F5: PK | H5: Y | J5: 심평원 제품코드 = 식약처 EDI_CODE (허가정보를 넣을 때 item_seq를 채우는 열쇠) | K5: O-3 · O-4 | L5: 수정 | M5: v1.3 | N5: 약제급여목록 22,045품목 (2026.9.1.). 규격 · 단위는 포장 단위(예: 1 · 정)라 복용 총량 계산에는 제품명의 함량(예: "_(3.39mg/1정)")을 씀
A6: drug_products | B6: 의약품 제품 | C6: item_seq | D6: 품목기준코드 | E6: varchar(9) | F6: FK | G6: drug_details.item_seq | H6: N | J6: 식약처 품목기준코드 — 허가정보와 잇는 칸. 한 허가 품목에 EDI 제품이 여러 개일 수 있음 | K6: O-3 · O-4 | L6: 수정 | M6: v1.3
A7: drug_products | B7: 의약품 제품 | C7: item_name | D7: 제품명 | E7: varchar(300) | H7: Y | K7: O-3 · O-4 | L7: 기존 | M7: v0.1
A8: drug_products | B8: 의약품 제품 | C8: item_name_norm | D8: 정규화 제품명 | E8: varchar(300) | H8: N | J8: 정규화된 이름 (괄호·규격 제거) — 매칭용 인덱스 | K8: O-3 · O-4 | L8: 기존 | M8: v0.1
A9: drug_products | B9: 의약품 제품 | C9: entp_name | D9: 업체명 | E9: varchar(200) | H9: N | K9: O-3 · O-4 | L9: 기존 | M9: v0.1
A10: drug_products | B10: 의약품 제품 | C10: ingr_code | D10: 성분 코드 | E10: varchar(9) | F10: FK | G10: drug_ingredients.ingr_code | H10: N | J10: 심평원 주성분코드 | K10: O-3 · O-4 | L10: 기존 | M10: v0.1
A11: drug_products | B11: 의약품 제품 | C11: ingr_group | D11: 동일성분 그룹 | E11: varchar(9) | H11: N | J11: 주성분코드_동일제형 — 제형 무관 동일성분 그룹 | K11: O-3 · O-4 | L11: 기존 | M11: v0.1
A12: drug_products | B12: 의약품 제품 | C12: etc_otc | D12: 전문/일반 | E12: varchar(10) | H12: N | J12: 전문 / 일반 | K12: O-3 · O-4 | L12: 기존 | M12: v0.1
A13: drug_products | B13: 의약품 제품 | C13: class_code | D13: 약효분류 | E13: varchar(10) | H13: N | J13: 약효분류 | K13: O-3 · O-4 | L13: 기존 | M13: v0.1
A14: drug_products | B14: 의약품 제품 | C14: spec_value | D14: 규격 | E14: decimal(12,3) | H14: N | J14: 포장 규격 숫자 (예: 1, 95(1) → 95) — 성분 함량 아님 | K14: O-3 · O-4 | L14: 수정 | M14: v1.3
A15: drug_products | B15: 의약품 제품 | C15: spec_unit | D15: 규격 단위 | E15: varchar(30) | H15: N | J15: 포장 단위 (예: 정, mL/병) | K15: O-3 · O-4 | L15: 수정 | M15: v1.3
A16: drug_products | B16: 의약품 제품 | C16: price | D16: 급여 상한금액 | E16: int | H16: N | J16: 급여 상한금액 | K16: O-3 · O-4 | L16: 기존 | M16: v0.1
A17: drug_products | B17: 의약품 제품 | C17: route | D17: 투여 경로 | E17: varchar(10) | H17: N | J17: 내복 / 주사 / 외용 | K17: O-3 · O-4 | L17: 기존 | M17: v0.1
A18: drug_ingredients | B18: 의약품 성분 | C18: ingr_code | D18: 성분 코드 | E18: varchar(9) | F18: PK | H18: Y | J18: 앞6=성분, 뒤3=제형 (ATB정제 ACH캡슐 BIJ주사) | K18: — | L18: 기존 | M18: v0.1
A19: drug_ingredients | B19: 의약품 성분 | C19: ingr_name | D19: 성분명 (영문) | E19: varchar(300) | H19: N | J19: 영문 성분명 | K19: — | L19: 기존 | M19: v0.1
A20: drug_ingredients | B20: 의약품 성분 | C20: ingr_name_kr | D20: 성분명 (한글) | E20: varchar(300) | H20: N | K20: — | L20: 기존 | M20: v0.1
A21: drug_details | B21: 의약품 상세 (허가정보) | C21: item_seq | D21: 품목기준코드 | E21: varchar(9) | F21: PK | H21: Y | J21: 식약처 품목기준코드 — 허가 품목 1개 = 1행 (EDI 제품코드 기준이 아님) | K21: R-4 (RAG 검색) | L21: 수정 | M21: v1.3 | N21: XML 파싱 시 <ARTICLE title="..."> 속성과 CDATA 양쪽에서 내용 추출 필요. 허가정보는 EDI 코드가 없는 품목이 많고(10/2에 받은 42,707건 중 허가가 살아 있는 35,194건 가운데 14,436건) 한 품목에 EDI 코드가 여러 개인 경우도 있어서(858건) item_seq를 키로 씀. 허가 취소 품목은 뺌
A22: drug_details | B22: 의약품 상세 (허가정보) | C22: item_name | D22: 제품명 | E22: varchar(300) | H22: Y | J22: 허가 제품명 — 급여목록에 없는 약의 이름 맞추기 · 표시용 (O-4) | K22: O-4 · R-4 (RAG 검색) | L22: 신규 | M22: v1.3
A23: drug_details | B23: 의약품 상세 (허가정보) | C23: item_name_norm | D23: 정규화 제품명 | E23: varchar(300) | H23: N | J23: 정규화된 이름 (drug_products와 같은 함수) — 매칭용 인덱스 | K23: O-4 · R-4 (RAG 검색) | L23: 신규 | M23: v1.3
A24: drug_details | B24: 의약품 상세 (허가정보) | C24: entp_name | D24: 업체명 | E24: varchar(200) | H24: N | K24: O-4 · R-4 (RAG 검색) | L24: 신규 | M24: v1.3
A25: drug_details | B25: 의약품 상세 (허가정보) | C25: etc_otc | D25: 전문 · 일반 구분 | E25: varchar(10) | H25: N | J25: 전문 / 일반 | K25: O-4 · R-4 (RAG 검색) | L25: 신규 | M25: v1.3
A26: drug_details | B26: 의약품 상세 (허가정보) | C26: efficacy | D26: 효능효과 | E26: text | H26: N | J26: 효능효과 (식약처 EE_DOC_DATA 파싱) | K26: R-4 (RAG 검색) | L26: 기존 | M26: v0.1
A27: drug_details | B27: 의약품 상세 (허가정보) | C27: usage_dose | D27: 용법용량 | E27: text | H27: N | J27: 용법용량 (UD_DOC_DATA) | K27: R-4 (RAG 검색) | L27: 기존 | M27: v0.1
A28: drug_details | B28: 의약품 상세 (허가정보) | C28: precautions | D28: 사용상 주의사항 | E28: text | H28: N | J28: 사용상의주의사항 (NB_DOC_DATA) | K28: R-4 (RAG 검색) | L28: 기존 | M28: v0.1
A29: drug_details | B29: 의약품 상세 (허가정보) | C29: storage | D29: 보관법 | E29: varchar(300) | H29: N | J29: 보관법 | K29: R-4 (RAG 검색) | L29: 기존 | M29: v0.1
A30: drug_details | B30: 의약품 상세 (허가정보) | C30: chart | D30: 성상 | E30: varchar(300) | H30: N | J30: 성상 — 낱알 식별에 활용 가능 | K30: R-4 (RAG 검색) | L30: 기존 | M30: v0.1
A31: drug_details | B31: 의약품 상세 (허가정보) | C31: embedding_id | D31: 벡터DB 문서 ID | E31: varchar(100) | H31: N | J31: 벡터DB 문서 ID (RAG 검색용) | K31: R-4 (RAG 검색) | L31: 기존 | M31: v0.1
A32: dur_interaction | B32: DUR 병용금기 | C32: ingr_code_a | D32: 성분 코드 A | E32: varchar(9) | F32: PK | H32: Y | J32: 정렬 후 저장 (A<B) — 양방향 중복 제거 | K32: R-4 · R-5 | L32: 기존 | M32: v0.1 | N32: m.db TBJBD43 기준 성분쌍 97,326건 (제품 단위 CSV 873,147행을 정규화)
A33: dur_interaction | B33: DUR 병용금기 | C33: ingr_code_b | D33: 성분 코드 B | E33: varchar(9) | F33: PK | H33: Y | K33: R-4 · R-5 | L33: 기존 | M33: v0.1
A34: dur_interaction | B34: DUR 병용금기 | C34: effective_from | D34: 적용 시작일 | E34: date | H34: N | K34: R-4 · R-5 | L34: 기존 | M34: v0.1
A35: dur_interaction | B35: DUR 병용금기 | C35: effective_to | D35: 적용 종료일 | E35: date | H35: N | J35: 99991231 = 현행 | K35: R-4 · R-5 | L35: 기존 | M35: v0.1
A36: dur_interaction | B36: DUR 병용금기 | C36: reason | D36: 사유 | E36: text | H36: N | J36: 금기 사유 (DUR_SD_EFT) | K36: R-4 · R-5 | L36: 기존 | M36: v0.1
A37: dur_interaction | B37: DUR 병용금기 | C37: notice_date | D37: 고시일 | E37: date | H37: N | J37: 고시일자 | K37: R-4 · R-5 | L37: 기존 | M37: v0.1
A38: dur_interaction | B38: DUR 병용금기 | C38: notice_no | D38: 고시 번호 | E38: varchar(10) | H38: N | K38: R-4 · R-5 | L38: 기존 | M38: v0.1
A39: dur_interaction_exception | B39: DUR 병용금기 예외 | C39: ingr_code_a | D39: 성분 코드 A | E39: varchar(9) | F39: PK | H39: Y | K39: R-4 | L39: 기존 | M39: v0.1 | N39: m.db TBJBD46. CSV에는 없는 데이터 — 없으면 오탐 발생
A40: dur_interaction_exception | B40: DUR 병용금기 예외 | C40: ingr_code_b | D40: 성분 코드 B | E40: varchar(9) | F40: PK | H40: Y | K40: R-4 | L40: 기존 | M40: v0.1
A41: dur_interaction_exception | B41: DUR 병용금기 예외 | C41: edi_code | D41: EDI 제품코드 | E41: varchar(9) | F41: PK | H41: Y | J41: 이 제품은 금기에서 제외 | K41: R-4 | L41: 기존 | M41: v0.1
...

Sheet FHIR 대응
A1: ERD v1.3 · FHIR 대응
A2: HL7 FHIR R4 (4.0.1) 기준 · R5는 표시. 우리 구조는 국내 공공데이터 코드(KCD · 심평원 EDI · 식약처 DUR) 기준이고, 병원 시스템과 연동하거나 표준으로 내보낼 때 아래 대응을 씀
A3: 대응 수준 — 일치: 그대로 옮김 (초록) / 변환: 값 · 구조를 바꿔 옮김 / 확장: 표준 요소 없음 → extension · 자체 코드 (노랑) / FHIR 외: 서비스 내부 정보라 옮기지 않음 (회색)
A5: 영역 | B5: 테이블 | C5: 필드 | D5: FHIR 리소스 | E5: FHIR 요소 (경로) | F5: 값 변환 · 코드 | G5: 대응 수준 | H5: 비고
A6: 사용자 | B6: users | C6: (테이블) | D6: Patient | E6: Patient | G6: 변환 | H6: 서비스 사용자 = 환자(Patient). 인증 정보는 FHIR 범위 밖
A7: 사용자 | B7: users | C7: id | D7: Patient | E7: Patient.id | G7: 일치
A8: 사용자 | B8: users | C8: birth_year | D8: Patient | E8: Patient.birthDate | F8: 연도만 "1955" 형식 (FHIR date는 YYYY 허용) | G8: 일치 | H8: 최소 수집 원칙과 FHIR 모두 충족
A9: 사용자 | B9: users | C9: sex | D9: Patient | E9: Patient.gender | F9: M → male / F → female | G9: 변환 | H9: AdministrativeGender 값셋
A10: 사용자 | B10: users | C10: deleted_at | D10: Patient | E10: Patient.active | F10: 탈퇴 시 active = false | G10: 변환
A11: 사용자 | B11: users | C11: updated_at | D11: Patient | E11: Patient.meta.lastUpdated | G11: 일치
A12: 사용자 | B12: users | C12: login_id · password_hash · failed_login_count · locked_until | D12: — | E12: — | G12: FHIR 외 | H12: 계정 · 인증 정보 (FHIR 리소스에 넣지 않음)
A13: 사용자 | B13: user_consents | C13: (테이블) | D13: Consent | E13: Consent | G13: 변환 | H13: 동의 1건 = Consent 1개
A14: 사용자 | B14: user_consents | C14: user_id | D14: Consent | E14: Consent.patient | F14: Reference(Patient) | G14: 일치
A15: 사용자 | B15: user_consents | C15: consent_type | D15: Consent | E15: Consent.category | F15: terms / privacy / sensitive_health → 자체 코드 | G15: 확장 | H15: 국내 개인정보 동의 구분은 표준 코드 없음
A16: 사용자 | B16: user_consents | C16: agreed | D16: Consent | E16: Consent.provision.type | F16: true → permit / false → deny | G16: 변환
A17: 사용자 | B17: user_consents | C17: agreed_at | D17: Consent | E17: Consent.dateTime | G17: 일치
A18: 사용자 | B18: user_consents | C18: withdrawn_at | D18: Consent | E18: Consent.status | F18: 철회 시 status = inactive (철회 시각은 새 Consent의 dateTime) | G18: 변환
A19: 입력 | B19: prescriptions | C19: (테이블) | D19: MedicationRequest 묶음 · DocumentReference | E19: MedicationRequest.groupIdentifier | F19: 처방전 1장 = 같은 groupIdentifier를 가진 MedicationRequest 여러 개 | G19: 변환 | H19: 사진 · OCR 원문은 DocumentReference로 분리
A20: 입력 | B20: prescriptions | C20: doc_type | D20: MedicationRequest / MedicationDispense | E20: — | F20: prescription(처방전) → MedicationRequest / pill_bag(약봉투) → MedicationDispense | G20: 변환 | H20: 처방전은 "처방", 약봉투는 "조제" 기록이라 FHIR 리소스가 다름
A21: 입력 | B21: prescriptions | C21: issued_date | D21: MedicationRequest | E21: MedicationRequest.authoredOn | G21: 일치 | H21: 약봉투는 MedicationDispense.whenHandedOver
A22: 입력 | B22: prescriptions | C22: hospital_name | D22: Organization | E22: MedicationRequest.requester → Organization.name | G22: 변환 | H22: 병원을 Organization으로 참조
A23: 입력 | B23: prescriptions | C23: ocr_raw_text | D23: DocumentReference | E23: DocumentReference.content.attachment | F23: 텍스트 첨부 (원본 이미지는 저장하지 않음) | G23: 변환 | H23: 10/15부터 원문을 저장하지 않아 비어 있음
A24: 입력 | B24: prescriptions | C24: ocr_confidence · quality_flag | D24: — | E24: extension | G24: 확장 | H24: OCR 품질 정보는 표준 요소 없음
A25: 입력 | B25: prescriptions | C25: notices | D25: — | E25: extension | G25: 확장 | H25: OCR 읽기 확인 표시는 내부 처리 정보
A26: 입력 | B26: prescriptions | C26: content_key | D26: — | E26: — | G26: FHIR 외 | H26: 같은 처방전 판별용 내부 값
A27: 입력 | B27: ocr_jobs | C27: (테이블) | D27: Task | E27: Task | F27: queued → requested / running → in-progress / done → completed / failed → failed | G27: 변환 | H27: v1.2 · OCR 비동기 작업
A28: 입력 | B28: ocr_jobs | C28: duplicates | D28: — | E28: extension | G28: 확장 | H28: 중복 사진 기록은 내부 처리 정보
A29: 입력 | B29: prescription_diseases | C29: (테이블) | D29: Condition | E29: Condition | F29: 처방전 질병분류기호 1개 = Condition 1개 | G29: 변환 | H29: MedicationRequest.reasonReference로 연결
A30: 입력 | B30: prescription_diseases | C30: disease_code | D30: Condition | E30: Condition.code.coding | F30: system = KCD (코드 시스템 URI 팀 정의 필요) | G30: 변환 | H30: KCD는 ICD-10 기반이라 ICD-10 코드 병기 가능
A31: 입력 | B31: prescription_diseases | C31: is_main | D31: Encounter | E31: Encounter.diagnosis.rank | F31: 주상병 → rank 1 | G31: 변환 | H31: 진료(Encounter) 정보가 없으면 extension
A32: 입력 | B32: prescription_items | C32: (테이블) | D32: MedicationRequest | E32: MedicationRequest | F32: 약 1줄 = MedicationRequest 1개 | G32: 일치
A33: 입력 | B33: prescription_items | C33: edi_code | D33: MedicationRequest | E33: MedicationRequest.medicationCodeableConcept.coding | F33: system = 심평원 EDI 제품코드 | G33: 변환
A34: 입력 | B34: prescription_items | C34: raw_name | D34: MedicationRequest | E34: MedicationRequest.medicationCodeableConcept.text | F34: OCR이 읽은 원문 약품명 | G34: 일치 | H34: 매칭 실패해도 text는 남음
A35: 입력 | B35: prescription_items | C35: dose_per_time | D35: MedicationRequest | E35: MedicationRequest.dosageInstruction.doseAndRate.doseQuantity | G35: 일치
A36: 입력 | B36: prescription_items | C36: times_per_day | D36: MedicationRequest | E36: MedicationRequest.dosageInstruction.timing.repeat.frequency | F36: period = 1, periodUnit = d | G36: 변환
A37: 입력 | B37: prescription_items | C37: total_days | D37: MedicationRequest | E37: MedicationRequest.dispenseRequest.expectedSupplyDuration | F37: 단위 d(일) | G37: 변환
A38: 입력 | B38: prescription_items | C38: timing | D38: MedicationRequest | E38: MedicationRequest.dosageInstruction.timing.repeat.when | F38: 아침 식후 → PCM, 저녁 식후 → PCV, 취침 전 → HS 등 + text 원문 | G38: 변환
A39: 입력 | B39: prescription_items | C39: guidance | D39: MedicationRequest | E39: MedicationRequest.dosageInstruction.patientInstruction | F39: 문장 목록 → 줄바꿈으로 이어 붙인 text | G39: 변환
A40: 입력 | B40: prescription_items | C40: suggested_by | D40: — | E40: — | G40: FHIR 외 | H40: 화면 표시용 추천 출처
A41: 입력 | B41: prescription_items | C41: match_status · match_score | D41: — | E41: extension | G41: 확장 | H41: 약품 매칭 상태는 내부 처리 정보
...
