Workbook

Sheet 작성 규칙
A1: 작성 규칙
A3: 탭 구성 | B3: 작성 규칙 / 변경 이력 / 요약 / 공통 / OCR / RAG / 챗봇 / 실천·보상 / 비기능 — 규칙과 변경 이력을 먼저 확인한 뒤 피처(담당자)별 탭을 수정. 요구사항 하나가 여러 화면에 걸치므로 화면별이 아닌 피처별로 나눔
A4: ID | B4: REQ-000 기능 / NFR-000 비기능. 번호대 — 회원 001~ · 업로드 010~ · OCR 020~ · 약품매칭 030~ · 안전성 040~ · 안내문 050~ · 생활습관 060~ · 챗봇 070~ · 이력 080~ · 피드백 090~ · 음성 100~ · 실천·보상 110~ · 공통화면 120~
A5: 관련 화면 | B5: Figma 통합 와이어프레임의 화면 ID (CM 공통 · OC OCR · RG RAG · CB 챗봇 · RW 실천·보상, 예외는 -E1)
A6: 관련 API | B6: API 명세서 번호 (A 인증 · U 회원 · O OCR · R 분석 · H 챗봇 · P 실천·보상)
A7: 우선순위 | B7: High = 피처 핵심 기능(OCR · RAG · 챗봇 · 보상, 참여기업 필수 · 기술 깊이) · 평가 기준(응답 속도 등) / Medium = 피처 보조 기능 · 예외 처리 · 최소 회원 기능 / Low = 개인정보 · 보안 · 일반 프론트 · 백엔드 구현 (최소 구현, 여유 있을 때) — 일반 구현은 AI 도구로 처리하므로 평가 · 설계 비중은 피처에 둔다
A8: 상태 | B8: 확정 / 팀 확인 필요 (9/29 전 결정) / 선택 구현 / 보류 (멘토링 · 외부 확인 대기)
A9: 변경 | B9: 초안(69건) 대비 — 기존 / 수정 (노란 배경) / 신규 (파란 배경)
A10: 최종 수정 | B10: 그 요구사항이 마지막으로 바뀐 버전. 바꿀 때마다 변경 이력 탭에 버전 요약 한 줄 + 위치 · 현행(As-Is) · 개정(To-Be) 세부 행을 추가 — 현행에는 바꾸기 전 값을 그대로 적음
A11: 새 행 추가 | B11: 해당 탭 맨 아래에 추가 (요약 탭은 각 탭 50행 여유분까지 자동 집계)
A12: 예시 | B12: REQ-033 · 약품매칭 · 확인 전 분석 시작 제한 · High · OC-02 · R-1 (409) · 채연 · 확정 · 신규 · v1.0
A13: MVP (제안) | B13: MVP = 스프린트 안에 반드시 만드는 것 / 후순위 = MVP 끝난 뒤. v1.3 기준 제안값이며 다음 팀 회의에서 확정

Sheet 변경 이력
A1: 변경 이력
A2: ※ 왼쪽 행 번호 옆 [+] / [-] 버튼으로 세부사항을 펼치고 접을 수 있습니다. 바꿀 때마다 버전 요약 한 줄 + 아래에 위치 · 현행(As-Is) · 개정(To-Be)을 적고, 현행에는 바꾸기 전 값을 그대로 남겨 주세요.
A3: 버전 | B3: 일자 | C3: 변경 내용 | E3: 담당
A4: v0.1 | B4: 2026-09-22 | C4: 최초 작성 — 요구사항 69건(REQ-001~NFR-051). 참여기업 요구사항 · 공공데이터 확보 결과 기준 | E4: 이형준
A5: v1.0 | B5: 2026-09-24 | C5: 통합 와이어프레임(45개 화면) · API 명세서 v1.0 반영 — 칸 추가, 기존 15건 상세 보완 · 비고 10건 정리, 신규 32건 추가 | E5: 이형준
B6: 위치 | C6: 현행 (As-Is) | D6: 개정 (To-Be)
B7: 전체 / 표 칸 구성 | C7: ID · 기능/비기능 · 카테고리 · 요구사항 명칭 · 상세 내용 · 우선순위 · 비고 (7칸) | D7: ID · 구분 · 카테고리 · 요구사항 명칭 · 상세 내용 · 우선순위 · 관련 화면 · 관련 API · 담당 · 상태 · 변경 · 최종 수정 · 비고 (13칸) 사유: 통합 와이어프레임(45개 화면) · API 명세서와 연결
B8: 공통 / REQ-001 회원가입 / 상세 내용 | C8: 사용자는 이메일과 비밀번호로 회원가입할 수 있어야 한다. 출생연도와 성별을 필수로 입력한다. | D8: 사용자는 이메일과 비밀번호로 회원가입할 수 있어야 한다. 출생연도와 성별은 필수, 이름(별명)은 선택으로 입력한다. 사유: 와이어프레임 화면 흐름에 맞춤
B9: 공통 / REQ-002 로그인 / 상세 내용 | C9: 사용자는 가입한 계정으로 로그인할 수 있어야 한다. 로그인 실패 5회 시 10분간 잠금 처리한다. | D9: 사용자는 가입한 계정으로 로그인할 수 있어야 한다. 틀릴 때마다 남은 횟수를 안내하고, 5회 실패 시 10분간 잠그며 남은 시간을 표시한다. 사유: 와이어프레임 화면 흐름에 맞춤
B10: 공통 / REQ-004 회원 탈퇴 / 상세 내용 | C10: 사용자는 탈퇴할 수 있어야 하며 탈퇴 시 업로드한 진료기록과 생성된 안내문은 즉시 삭제된다. | D10: 사용자는 탈퇴 전 지워지는 정보 목록을 확인하고 동의해야 하며, 탈퇴 시 진료 정보 · 분석 결과 · 안내문 · 실천 기록 · 챗봇 대화가 즉시 삭제된다. 사유: 와이어프레임 화면 흐름에 맞춤
B11: 공통 / REQ-006 — 신규 행 추가 | C11: (없음) | D11: 내 정보 조회 · 수정 · Low 사용자는 이름(별명) · 출생연도 · 성별을 확인하고 수정할 수 있어야 한다. 이메일은 수정할 수 없고, 출생연도 · 성별 변경은 다음 분석부터 반영된다. 사유: 와이어프레임에서 새로 나온 기능
B12: 공통 / REQ-007 — 신규 행 추가 | C12: (없음) | D12: 동의 내역 조회 · 철회 · Low 사용자는 동의한 약관과 동의 일시를 확인하고 민감정보 수집 동의를 철회할 수 있어야 한다. 철회하면 업로드 · 분석을 이용할 수 없다. 사유: 와이어프레임에서 새로 나온 기능 [팀 확인 필요]
B13: 공통 / REQ-008 — 신규 행 추가 | C13: (없음) | D13: 로그인 만료 처리 · Low 시스템은 로그인이 만료되면 사유를 안내하고 로그인 화면으로 이동시켜야 한다. 사유: 와이어프레임에서 새로 나온 기능 [팀 확인 필요]
B14: OCR / REQ-011 카메라 촬영 업로드 / 상세 내용 | C14: 사용자는 모바일에서 카메라로 직접 촬영하여 업로드할 수 있어야 한다. | D14: 사용자는 모바일에서 카메라로 직접 촬영하여 업로드할 수 있어야 한다. 카메라 권한이 없으면 설정 이동 또는 갤러리 선택으로 계속할 수 있다. 사유: 와이어프레임 화면 흐름에 맞춤
B15: OCR / REQ-013 다중 업로드 / 상세 내용 | C15: 사용자는 처방전을 한 번에 최대 5장까지 업로드할 수 있어야 한다. | D15: 사용자는 처방전 · 약봉투를 최대 5장까지 이어서 촬영 · 선택하고 한 번에 인식을 시작할 수 있어야 한다. 사유: 와이어프레임 화면 흐름에 맞춤 [팀 확인 필요]
B16: OCR / REQ-016 — 신규 행 추가 | C16: (없음) | D16: 촬영 품질 사전 검사 · High 시스템은 촬영 직후 초점 · 밝기 · 문서 잘림을 검사하고, 기준에 못 미치면 사유를 알리고 다시 찍도록 안내해야 한다. 사용자가 원하면 "확인 필요" 상태로 계속 진행할 수 있다. 사유: 와이어프레임에서 새로 나온 기능
B17: OCR / REQ-017 — 신규 행 추가 | C17: (없음) | D17: 관련 없는 사진 감지 · Medium 시스템은 처방전 · 약봉투가 아닌 사진을 걸러내고 다시 찍도록 안내해야 한다. 사유: 와이어프레임에서 새로 나온 기능 [팀 확인 필요]
... B64: 비기능 / NFR-023 일관된 UI / 비고 | C64: 참여기업 평가 기준 4-2 | D64: Figma 00 톤앤매너 가이드
A65: v1.1 | B65: 2026-09-24 | C65: 한 시트 → 피처(담당자)별 탭으로 분리 | E65: 이형준
B66: 위치 | C66: 현행 (As-Is) | D66: 개정 (To-Be)
B67: 전체 / 시트 구성 | C67: 요구사항 정의서 한 시트 (101건) | D67: 작성 규칙 → 변경 이력 → 요약 → 공통 · OCR · RAG · 챗봇 · 실천·보상 · 비기능 (9개 탭) 사유: 담당자별로 자기 탭만 관리하도록
A68: v1.2 | B68: 2026-09-24 | C68: 우선순위 기준 정리 — 피처 핵심 High, 개인정보 · 보안 · 일반 구현은 Low로 조정 (20건) | E68: 이형준
B69: 위치 | C69: 현행 (As-Is) | D69: 개정 (To-Be)
B70: 작성 규칙 / 우선순위 기준 | C70: High / Medium / Low 등급만 표기 (등급별 기준 문구 없음) | D70: 피처 핵심 High / 보조 · 예외 Medium / 개인정보 · 보안 · 일반 구현 Low 사유: 멘토링 방향: 피처를 깊게. 개인정보 · 보안 · 프론트 · 백엔드 일반 구현은 AI 도구로 처리하므로 비중 축소
B71: 공통 / REQ-001 회원가입 / 우선순위 | C71: High | D71: Medium (비고에 "우선순위 조정" 문구 추가) 사유: 최소 구현 — 가입은 있어야 하지만 피처가 아님
B72: 공통 / REQ-002 로그인 / 우선순위 | C72: High | D72: Medium (비고에 "우선순위 조정" 문구 추가) 사유: 최소 구현 — 로그인만 우선, 5회 잠금은 여유 있을 때
B73: 공통 / REQ-003 로그아웃 / 우선순위 | C73: High | D73: Low (비고에 "우선순위 조정" 문구 추가) 사유: 일반 구현
B74: 공통 / REQ-004 회원 탈퇴 / 우선순위 | C74: High | D74: Low (비고에 "우선순위 조정" 문구 추가) 사유: 개인정보 · 일반 구현
B75: 공통 / REQ-005 개인정보 처리방침 동의 / 우선순위 | C75: High | D75: Low (비고에 "우선순위 조정" 문구 추가) 사유: 개인정보 — 동의 체크만 최소 구현
B76: 공통 / REQ-006 내 정보 조회 · 수정 / 우선순위 | C76: Medium | D76: Low (비고에 "우선순위 조정" 문구 추가) 사유: 일반 구현
B77: 공통 / REQ-007 동의 내역 조회 · 철회 / 우선순위 | C77: Medium | D77: Low (비고에 "우선순위 조정" 문구 추가) 사유: 개인정보
B78: 공통 / REQ-008 로그인 만료 처리 / 우선순위 | C78: Medium | D78: Low (비고에 "우선순위 조정" 문구 추가) 사유: 보안 · 일반 구현
B79: 공통 / REQ-081 이력 삭제 / 우선순위 | C79: Medium | D79: Low (비고에 "우선순위 조정" 문구 추가) 사유: 일반 구현
B80: 공통 / REQ-082 실패한 분석 다시 하기 / 우선순위 | C80: Medium | D80: Low (비고에 "우선순위 조정" 문구 추가) 사유: 일반 구현
... B90: 비기능 / NFR-041 API 사용량 제한 / 우선순위 | C90: Medium | D90: Low (비고에 "우선순위 조정" 문구 추가) 사유: 일반 구현
A91: v1.3 | B91: 2026-09-28 | C91: 리뷰 반영 — 생활습관 출처 · 칼륨 "의료진 확인", OCR 비동기, 파기 범위 제안, RW-01 · RW-03~05 정리 제안, MVP (제안) 칸 추가 | E91: 이형준
B92: 위치 | C92: 현행 (As-Is) | D92: 개정 (To-Be)
B93: RAG / REQ-060 질환별 생활습관 가이드 / 상세 내용 | C93: 시스템은 인식된 상병코드에 해당하는 생활습관 개선 가이드를 제공해야 한다. | D93: 시스템은 인식된 상병코드에 해당하는 생활습관 개선 가이드를 제공해야 한다. 실천 항목마다 근거 출처(기관 · 문서명 · 판 · 발행일 · URL)를 함께 표시한다. 사유: 출처가 "질병관리청 · 관련 학회 지침" 한 줄이면 검증 · 갱신 불가 (리뷰 지적 5 · ERD v1.2 lifestyle_guide_sources)
B94: RAG / REQ-061 복약 연계 가이드 / 상세 내용 | C94: 시스템은 복용 중인 약물군과 연계한 생활습관 주의사항을 제공해야 한다. | D94: 시스템은 복용 중인 약물군과 연계한 생활습관 주의사항을 제공해야 한다. 칼륨처럼 신장 기능 · 병용 약에 따라 권고가 달라지는 항목은 "의료진 확인" 안내로만 표시하고 실천 목표로 만들지 않는다. 사유: 이뇨제 + 칼륨 섭취 권고는 신장 기능 · 이뇨제 종류 · ACE억제제/ARB 병용에 따라 고칼륨혈증 위험 (리뷰 지적 3)
B95: RAG / REQ-061 복약 연계 가이드 / 비고 | C95: 예: 이뇨제 복용 시 칼륨 / 와파린 복용 시 비타민K | D95: 예: 이뇨제 · ACE억제제/ARB와 칼륨 (의료진 확인) / 와파린 복용 시 비타민K
...

Sheet 요약
A1: 요구사항 정의서 v1.4 · 5팀 · 진료 기록 기반 복약 안내 및 생활습관 개선 가이드 자동 생성 시스템
A2: 작성 2026-09-24 · 탭별로 담당자가 관리 · 아래 숫자는 각 탭에서 자동 집계 (행을 추가해도 반영됨)
A4: 탭 | B4: 담당 · 범위 | C4: 전체 | D4: 확정 | E4: 팀 확인 필요 | F4: 선택 구현 | G4: 보류 | H4: High | I4: 신규 | J4: 수정 | K4: MVP (제안)
A5: 공통 | B5: 형준 · 회원 · 지난 기록 · 홈 · 공통 오류 | C5: =COUNTA('공통'!$A$5:$A$67) | D5: =COUNTIF('공통'!$J$5:$J$67,"확정") | E5: =COUNTIF('공통'!$J$5:$J$67,"팀 확인 필요") | F5: =COUNTIF('공통'!$J$5:$J$67,"선택 구현") | G5: =COUNTIF('공통'!$J$5:$J$67,"보류") | H5: =COUNTIF('공통'!$F$5:$F$67,"High") | I5: =COUNTIF('공통'!$K$5:$K$67,"신규") | J5: =COUNTIF('공통'!$K$5:$K$67,"수정") | K5: =COUNTIF('공통'!$N$5:$N$67,"MVP")
A6: OCR | B6: 채연 · 촬영 · 업로드 · 인식 · 약품 매칭 | C6: =COUNTA('OCR'!$A$5:$A$73) | D6: =COUNTIF('OCR'!$J$5:$J$73,"확정") | E6: =COUNTIF('OCR'!$J$5:$J$73,"팀 확인 필요") | F6: =COUNTIF('OCR'!$J$5:$J$73,"선택 구현") | G6: =COUNTIF('OCR'!$J$5:$J$73,"보류") | H6: =COUNTIF('OCR'!$F$5:$F$73,"High") | I6: =COUNTIF('OCR'!$K$5:$K$73,"신규") | J6: =COUNTIF('OCR'!$K$5:$K$73,"수정") | K6: =COUNTIF('OCR'!$N$5:$N$73,"MVP")
A7: RAG | B7: 형준 · 안전성 점검 · 복약 안내 · 생활습관 · 피드백 | C7: =COUNTA('RAG'!$A$5:$A$82) | D7: =COUNTIF('RAG'!$J$5:$J$82,"확정") | E7: =COUNTIF('RAG'!$J$5:$J$82,"팀 확인 필요") | F7: =COUNTIF('RAG'!$J$5:$J$82,"선택 구현") | G7: =COUNTIF('RAG'!$J$5:$J$82,"보류") | H7: =COUNTIF('RAG'!$F$5:$F$82,"High") | I7: =COUNTIF('RAG'!$K$5:$K$82,"신규") | J7: =COUNTIF('RAG'!$K$5:$K$82,"수정") | K7: =COUNTIF('RAG'!$N$5:$N$82,"MVP")
A8: 챗봇 | B8: 수인 · 실시간 챗봇 | C8: =COUNTA('챗봇'!$A$5:$A$64) | D8: =COUNTIF('챗봇'!$J$5:$J$64,"확정") | E8: =COUNTIF('챗봇'!$J$5:$J$64,"팀 확인 필요") | F8: =COUNTIF('챗봇'!$J$5:$J$64,"선택 구현") | G8: =COUNTIF('챗봇'!$J$5:$J$64,"보류") | H8: =COUNTIF('챗봇'!$F$5:$F$64,"High") | I8: =COUNTIF('챗봇'!$K$5:$K$64,"신규") | J8: =COUNTIF('챗봇'!$K$5:$K$64,"수정") | K8: =COUNTIF('챗봇'!$N$5:$N$64,"MVP")
A9: 실천·보상 | B9: 성규 · 추천 · 목표 · 실천 기록 · 포인트 | C9: =COUNTA('실천·보상'!$A$5:$A$62) | D9: =COUNTIF('실천·보상'!$J$5:$J$62,"확정") | E9: =COUNTIF('실천·보상'!$J$5:$J$62,"팀 확인 필요") | F9: =COUNTIF('실천·보상'!$J$5:$J$62,"선택 구현") | G9: =COUNTIF('실천·보상'!$J$5:$J$62,"보류") | H9: =COUNTIF('실천·보상'!$F$5:$F$62,"High") | I9: =COUNTIF('실천·보상'!$K$5:$K$62,"신규") | J9: =COUNTIF('실천·보상'!$K$5:$K$62,"수정") | K9: =COUNTIF('실천·보상'!$N$5:$N$62,"MVP")
A10: 비기능 | B10: 공통 · 성능 · 보안 · 사용성 · 품질 · 운영 · 확장성 | C10: =COUNTA('비기능'!$A$5:$A$77) | D10: =COUNTIF('비기능'!$J$5:$J$77,"확정") | E10: =COUNTIF('비기능'!$J$5:$J$77,"팀 확인 필요") | F10: =COUNTIF('비기능'!$J$5:$J$77,"선택 구현") | G10: =COUNTIF('비기능'!$J$5:$J$77,"보류") | H10: =COUNTIF('비기능'!$F$5:$F$77,"High") | I10: =COUNTIF('비기능'!$K$5:$K$77,"신규") | J10: =COUNTIF('비기능'!$K$5:$K$77,"수정") | K10: =COUNTIF('비기능'!$N$5:$N$77,"MVP")
A11: 합계 | C11: =SUM(C5:C10) | D11: =SUM(D5:D10) | E11: =SUM(E5:E10) | F11: =SUM(F5:F10) | G11: =SUM(G5:G10) | H11: =SUM(H5:H10) | I11: =SUM(I5:I10) | J11: =SUM(J5:J10) | K11: =SUM(K5:K10)
A13: 참고 문서
A14: 와이어프레임 | B14: https://www.figma.com/design/iq3FaNYUqVxysGb1FatARS (화면 ID · 기능설명서 · 화면 이동)
A15: API 명세서 | B15: API 명세서_6기_5팀_v1.2.md
A16: ERD | B16: ERD_6기_5팀_v1.2.xlsx · ERD_6기_5팀_v1.2.dbml
A17: 화면 번호 통합표 | B17: screen_id_table.md

Sheet 공통
A1: 요구사항 정의서 v1.4 · 공통
A2: 형준 · 회원 · 지난 기록 · 홈 · 공통 오류 · 관련 화면 CM · 행을 바꾸면 "변경 이력" 탭에 한 줄 추가
A4: ID | B4: 구분 | C4: 카테고리 | D4: 요구사항 명칭 | E4: 상세 내용 | F4: 우선순위 | G4: 관련 화면 | H4: 관련 API | I4: 담당 | J4: 상태 | K4: 변경 | L4: 최종 수정 | M4: 비고 | N4: MVP (제안)
A5: REQ-001 | B5: 기능 | C5: 회원 | D5: 회원가입 | E5: 사용자는 이메일과 비밀번호로 회원가입할 수 있어야 한다. 출생연도와 성별은 필수, 이름(별명)은 선택으로 입력한다. | F5: Medium | G5: CM-02 · CM-02-E1 | H5: A-1 | I5: 형준 | J5: 확정 | K5: 수정 | L5: v1.2 | M5: 출생연도·성별은 노인주의/연령금기 판정에 필요 · 우선순위 조정: 최소 구현 — 가입은 있어야 하지만 피처가 아님 | N5: MVP
A6: REQ-002 | B6: 기능 | C6: 회원 | D6: 로그인 | E6: 사용자는 가입한 계정으로 로그인할 수 있어야 한다. 틀릴 때마다 남은 횟수를 안내하고, 5회 실패 시 10분간 잠그며 남은 시간을 표시한다. | F6: Medium | G6: CM-01 · CM-01-E1 · CM-01-E2 | H6: A-2 | I6: 형준 | J6: 확정 | K6: 수정 | L6: v1.2 | M6: 예외: 비밀번호 5회 오류 · 우선순위 조정: 최소 구현 — 로그인만 우선, 5회 잠금은 여유 있을 때 | N6: MVP
A7: REQ-003 | B7: 기능 | C7: 회원 | D7: 로그아웃 | E7: 사용자는 로그아웃할 수 있어야 하며 발급된 토큰은 즉시 무효화된다. | F7: Low | G7: CM-05 | H7: A-3 | I7: 형준 | J7: 확정 | K7: 수정 | L7: v1.2 | M7: 우선순위 조정: 일반 구현 | N7: MVP
A8: REQ-004 | B8: 기능 | C8: 회원 | D8: 회원 탈퇴 | E8: 사용자는 탈퇴 전 지워지는 정보 목록을 확인하고 동의해야 하며, 탈퇴 시 진료 정보 · 분석 결과 · 안내문 · 피드백 · 챗봇 대화 · 실천 목표 · 실천 기록 · 포인트 · 동의 기록이 즉시 삭제된다. | F8: Low | G8: CM-07 | H8: U-3 | I8: 형준 | J8: 팀 확인 필요 | K8: 수정 | L8: v1.3 | M8: 민감정보 파기 의무 · 우선순위 조정: 개인정보 · 일반 구현 | N8: MVP
A9: REQ-005 | B9: 기능 | C9: 회원 | D9: 개인정보 처리방침 동의 | E9: 사용자는 회원가입 시 민감정보(진료기록) 수집·이용에 대해 별도 동의해야 한다. | F9: Low | G9: CM-02 · CM-02-E1 | H9: A-1 · U-4 | I9: 형준 | J9: 확정 | K9: 수정 | L9: v1.2 | M9: 동의 없이 업로드 불가 · 우선순위 조정: 개인정보 — 동의 체크만 최소 구현 | N9: MVP
A10: REQ-006 | B10: 기능 | C10: 회원 | D10: 내 정보 조회 · 수정 | E10: 사용자는 이름(별명) · 출생연도 · 성별을 확인하고 수정할 수 있어야 한다. 이메일은 수정할 수 없고, 출생연도 · 성별 변경은 다음 분석부터 반영된다. | F10: Low | G10: CM-05 · CM-06 | H10: U-1 · U-2 | I10: 형준 | J10: 확정 | K10: 신규 | L10: v1.2 | M10: 와이어프레임에서 추가 · 우선순위 조정: 일반 구현 | N10: MVP
A11: REQ-007 | B11: 기능 | C11: 회원 | D11: 동의 내역 조회 · 철회 | E11: 사용자는 동의한 약관과 동의 일시를 확인하고 민감정보 수집 동의를 철회할 수 있어야 한다. 철회하면 업로드 · 분석을 이용할 수 없고, 처방전 · 분석 · 안내문 · 피드백 · 챗봇 대화는 삭제된다. 실천 목표는 종료하되 기록 · 포인트는 남긴다(질환 라벨은 지움). | F11: Low | G11: CM-05 | H11: U-4 · U-5 | I11: 형준 | J11: 팀 확인 필요 | K11: 신규 | L11: v1.3 | M11: 파기 범위 제안 v1.3 — 다음 팀 회의 확인 · 우선순위 조정: 개인정보 | N11: MVP
A12: REQ-008 | B12: 기능 | C12: 회원 | D12: 로그인 만료 처리 | E12: 시스템은 로그인이 만료되면 사유를 안내하고 로그인 화면으로 이동시켜야 한다. | F12: Low | G12: CM-08 · CM-01 | H12: 전체 (401 TOKEN_EXPIRED) | I12: 형준 | J12: 팀 확인 필요 | K12: 신규 | L12: v1.2 | M12: 토큰 만료 시간 · 재발급 도입 여부 미정 · 우선순위 조정: 보안 · 일반 구현 | N12: MVP
A13: REQ-080 | B13: 기능 | C13: 이력 | D13: 분석 이력 조회 | E13: 사용자는 과거에 분석한 처방전과 안내문 목록을 조회할 수 있어야 한다. | F13: Medium | G13: CM-04 · CM-04-E2 · CM-03 | H13: R-7 | I13: 형준 | J13: 확정 | K13: 기존 | L13: v0.1 | N13: MVP
A14: REQ-081 | B14: 기능 | C14: 이력 | D14: 이력 삭제 | E14: 사용자는 개별 분석 기록을 삭제할 수 있어야 하며, 삭제 전 확인 창을 거친다. 지운 기록은 되돌릴 수 없다. 이 분석에만 쓰인 처방전도 함께 지우고, 이미 만든 실천 목표 · 기록 · 포인트는 남긴다. | F14: Low | G14: CM-04-E1 | H14: R-8 | I14: 형준 | J14: 팀 확인 필요 | K14: 수정 | L14: v1.3 | M14: 실천 목표 · 포인트는 남기고 추천 연결만 끊는 안 → 성규 확인 · 우선순위 조정: 일반 구현 | N14: MVP
A15: REQ-082 | B15: 기능 | C15: 이력 | D15: 실패한 분석 다시 하기 | E15: 사용자는 분석에 실패한 기록에서 다시 분석을 시작할 수 있어야 한다. 원본 사진을 저장하지 않으므로 다시 촬영한다. | F15: Low | G15: CM-04 | H15: O-1 | I15: 형준 | J15: 확정 | K15: 신규 | L15: v1.2 | M15: NFR-011 연계 · 우선순위 조정: 일반 구현 | N15: MVP
A16: REQ-120 | B16: 기능 | C16: 공통화면 | D16: 홈 요약 | E16: 시스템은 홈에서 오늘의 실천 진행률, 최근 분석 결과 요약, 챗봇 진입, 새 분석 버튼을 한 화면에 보여줘야 한다. 기록이 없으면 이용 순서를 안내한다. | F16: High | G16: CM-03 · CM-03-E1 | H16: U-1 · R-7 · GET /habit-goals/today | I16: 형준 | J16: 확정 | K16: 신규 | L16: v1.0 | M16: 4개 피처 진입점 | N16: MVP
A17: REQ-121 | B17: 기능 | C17: 공통화면 | D17: 공통 오류 화면 | E17: 시스템은 네트워크 · 서버 오류 · 로그인 만료 시 공통 오류 화면에서 사유를 글자로 안내하고 다시 시도 · 홈 이동을 제공해야 한다. | F17: Medium | G17: CM-08 | H17: 전체 (공통 에러 형식) | I17: 형준 | J17: 확정 | K17: 신규 | L17: v1.2 | M17: 피처별 실패는 각 예외 화면에서 처리 · 우선순위 조정: 공통 예외 처리 | N17: MVP

Sheet OCR
A1: 요구사항 정의서 v1.4 · OCR
A2: 채연 · 촬영 · 업로드 · 인식 · 약품 매칭 · 관련 화면 OC · 행을 바꾸면 "변경 이력" 탭에 한 줄 추가
A4: ID | B4: 구분 | C4: 카테고리 | D4: 요구사항 명칭 | E4: 상세 내용 | F4: 우선순위 | G4: 관련 화면 | H4: 관련 API | I4: 담당 | J4: 상태 | K4: 변경 | L4: 최종 수정 | M4: 비고 | N4: MVP (제안)
A5: REQ-010 | B5: 기능 | C5: 업로드 | D5: 처방전 이미지 업로드 | E5: 사용자는 처방전을 이미지(JPG/PNG) 또는 PDF로 업로드할 수 있어야 한다. 파일 1건당 최대 10MB. | F5: High | G5: OC-01 | H5: O-1 · O-5 | I5: 채연 | J5: 확정 | K5: 기존 | L5: v1.3 | M5: 참여기업 필수 요구사항 | N5: MVP
A6: REQ-011 | B6: 기능 | C6: 업로드 | D6: 카메라 촬영 업로드 | E6: 사용자는 모바일에서 카메라로 직접 촬영하여 업로드할 수 있어야 한다. 카메라 권한이 없으면 설정 이동 또는 갤러리 선택으로 계속할 수 있다. | F6: High | G6: OC-01 · OC-01-E2 | H6: O-1 · O-5 | I6: 채연 | J6: 확정 | K6: 수정 | L6: v1.3 | M6: 타겟 사용 맥락이 모바일 | N6: MVP
A7: REQ-012 | B7: 기능 | C7: 업로드 | D7: 약봉투 업로드 | E7: 사용자는 약봉투를 촬영하여 업로드할 수 있어야 한다. | F7: High | G7: OC-01 | H7: O-1 · O-5 | I7: 채연 | J7: 확정 | K7: 기존 | L7: v1.3 | M7: 약봉투에는 질병분류기호가 없어 생활습관 안내는 RG-05-E1로 이어짐 | N7: MVP
A8: REQ-013 | B8: 기능 | C8: 업로드 | D8: 다중 업로드 | E8: 사용자는 처방전 · 약봉투를 최대 5장까지 이어서 촬영 · 선택하고 한 번에 인식을 시작할 수 있어야 한다. | F8: High | G8: OC-01 | H8: O-1 · O-5 | I8: 채연 | J8: 팀 확인 필요 | K8: 수정 | L8: v1.3 | M8: 여러 병원 처방전 동시 점검이 핵심 시나리오. 와이어프레임을 여러 장 흐름으로 바꿈 → 채연 확인 | N8: MVP
A9: REQ-014 | B9: 기능 | C9: 업로드 | D9: 업로드 실패 안내 | E9: 시스템은 지원하지 않는 형식이거나 용량을 초과한 경우 사유를 화면에 표시해야 한다. | F9: High | G9: OC-01-E1 · OC-01-E3 | H9: O-1 | I9: 채연 | J9: 확정 | K9: 기존 | L9: v0.1 | M9: 예외 처리 | N9: MVP
A10: REQ-015 | B10: 기능 | C10: 업로드 | D10: 건강검진 결과통보서 업로드 | E10: 사용자는 국가건강검진 결과통보서를 업로드할 수 있어야 한다. | F10: Medium | G10: — | H10: — | I10: 채연 | J10: 보류 | K10: 기존 | L10: v0.1 | M10: ※ 멘토링 확인 필요 - 입력 범위 확정 후 결정 | N10: 후순위
A11: REQ-016 | B11: 기능 | C11: 업로드 | D11: 촬영 품질 사전 검사 | E11: 시스템은 촬영 직후 초점 · 밝기 · 문서 잘림을 검사하고, 기준에 못 미치면 사유를 알리고 다시 찍도록 안내해야 한다. 사용자가 원하면 "확인 필요" 상태로 계속 진행할 수 있다. | F11: High | G11: OC-01-E1 | H11: O-5 (IMAGE_QUALITY_LOW) | I11: 채연 | J11: 확정 | K11: 신규 | L11: v1.3 | M11: 와이어프레임에서 추가 | N11: MVP
A12: REQ-017 | B12: 기능 | C12: 업로드 | D12: 관련 없는 사진 감지 | E12: 시스템은 처방전 · 약봉투가 아닌 사진을 걸러내고 다시 찍도록 안내해야 한다. | F12: Medium | G12: OC-01-E3 | H12: O-5 (NOT_A_DOCUMENT) | I12: 채연 | J12: 팀 확인 필요 | K12: 신규 | L12: v1.3 | M12: 잘못 걸러내는 경우를 줄이는 기준 필요 | N12: MVP
A13: REQ-020 | B13: 기능 | C13: OCR | D13: 처방전 텍스트 추출 | E13: 시스템은 업로드된 이미지·PDF에서 약품명 용법 용량 투약일수 질병분류기호를 자동 추출해야 한다. | F13: High | G13: OC-02 | H13: O-2 | I13: 채연 | J13: 확정 | K13: 기존 | L13: v0.1 | M13: 참여기업 필수 요구사항 (CLOVA OCR) | N13: MVP
A14: REQ-021 | B14: 기능 | C14: OCR | D14: 용법용량 구조화 | E14: 시스템은 추출된 용법 문자열을 1회량 1일횟수 총일수 복용시점으로 구조화해야 한다. | F14: High | G14: OC-02 | H14: O-2 · O-3 | I14: 채연 | J14: 확정 | K14: 기존 | L14: v0.1 | M14: 1일 총량 계산에 필요 | N14: MVP
A15: REQ-022 | B15: 기능 | C15: OCR | D15: 상병코드 인식 | E15: 시스템은 처방전의 질병분류기호(KCD)를 인식하여 질병명으로 변환해야 한다. | F15: High | G15: OC-02 | H15: O-2 | I15: 채연 | J15: 확정 | K15: 기존 | L15: v0.1 | M15: 심평원 상병마스터 47798건 활용 | N15: MVP
... A23: REQ-034 | B23: 기능 | C23: 약품매칭 | D23: 약 이름 검색 · 자동완성 | E23: 사용자는 인식되지 않은 약을 이름으로 검색해 직접 추가할 수 있어야 하며, 입력 중 비슷한 약 이름을 추천받는다. | F23: High | G23: OC-02 · OC-02-E1 | H23: O-4 | I23: 채연 | J23: 확정 | K23: 신규 | L23: v1.0 | M23: 와이어프레임에서 추가 | N23: MVP

Sheet RAG
A1: 요구사항 정의서 v1.4 · RAG
A2: 형준 · 안전성 점검 · 복약 안내 · 생활습관 · 피드백 · 관련 화면 RG · 행을 바꾸면 "변경 이력" 탭에 한 줄 추가
A4: ID | B4: 구분 | C4: 카테고리 | D4: 요구사항 명칭 | E4: 상세 내용 | F4: 우선순위 | G4: 관련 화면 | H4: 관련 API | I4: 담당 | J4: 상태 | K4: 변경 | L4: 최종 수정 | M4: 비고 | N4: MVP (제안)
A5: REQ-040 | B5: 기능 | C5: 안전성점검 | D5: 병용금기 점검 | E5: 시스템은 복용 약품 조합에 대해 식약처 고시 병용금기 해당 여부를 점검해야 한다. | F5: High | G5: RG-02 | H5: R-4 | I5: 형준 | J5: 확정 | K5: 기존 | L5: v0.1 | M5: DUR 성분쌍 97326건. DB 조회로 결정적 판정 | N5: MVP
A6: REQ-041 | B6: 기능 | C6: 안전성점검 | D6: 병용금기 예외 반영 | E6: 시스템은 병용금기 예외 규칙에 해당하는 제품은 경고에서 제외해야 한다. | F6: High | G6: RG-02 | H6: R-4 | I6: 형준 | J6: 확정 | K6: 기존 | L6: v0.1 | M6: 예외 규칙 미반영 시 오탐 발생 | N6: MVP
A7: REQ-042 | B7: 기능 | C7: 안전성점검 | D7: 동일성분 중복 점검 | E7: 시스템은 서로 다른 제품이 동일 성분인 경우 중복 복용으로 판정해야 한다. | F7: High | G7: RG-02 | H7: R-4 | I7: 형준 | J7: 확정 | K7: 기존 | L7: v0.1 | M7: DUR성분코드 기준 29051품목 | N7: MVP
A8: REQ-043 | B8: 기능 | C8: 안전성점검 | D8: 효능군 중복 점검 | E8: 시스템은 서로 다른 제품이 동일 효능군인 경우 중복으로 판정해야 한다. | F8: High | G8: RG-02 | H8: R-4 | I8: 형준 | J8: 확정 | K8: 기존 | L8: v0.1 | M8: 효능군중복점검코드 278개 | N8: MVP
A9: REQ-044 | B9: 기능 | C9: 안전성점검 | D9: 노인주의 점검 | E9: 시스템은 사용자가 65세 이상인 경우 노인주의 대상 약품을 식별하여 안내해야 한다. | F9: High | G9: RG-02 | H9: R-4 | I9: 형준 | J9: 확정 | K9: 기존 | L9: v0.1 | M9: 고령 타겟의 핵심 기능 | N9: MVP
A10: REQ-045 | B10: 기능 | C10: 안전성점검 | D10: 연령금기 점검 | E10: 시스템은 사용자 연령이 금기 조건에 해당하는 약품을 식별해야 한다. | F10: Medium | G10: RG-02 | H10: R-4 | I10: 형준 | J10: 확정 | K10: 기존 | L10: v0.1 | N10: MVP
A11: REQ-046 | B11: 기능 | C11: 안전성점검 | D11: 1일 최대용량 초과 점검 | E11: 시스템은 동일 성분 중복 시 1일 총 투여량을 합산하여 최대 투여기준량 초과 여부를 판정해야 한다. | F11: Medium | G11: RG-02 · RG-03 | H11: R-4 · R-5 | I11: 형준 | J11: 확정 | K11: 기존 | L11: v0.1 | M11: REQ-021 구조화 결과에 의존 | N11: MVP
A12: REQ-047 | B12: 기능 | C12: 안전성점검 | D12: 경고 근거 표시 | E12: 시스템은 경고마다 관련 약(처방 병원 · 성분), 쉬운 설명, 금기 사유 원문, 고시명 · 고시일, 판정 방식(DB 조회)을 상세 화면에서 보여줘야 한다. | F12: High | G12: RG-03 | H12: R-5 | I12: 형준 | J12: 확정 | K12: 수정 | L12: v1.0 | M12: 근거 제시가 서비스 신뢰도의 핵심 | N12: MVP
A13: REQ-048 | B13: 기능 | C13: 안전성점검 | D13: 경고 등급 구분 | E13: 시스템은 경고를 위험 / 주의 / 참고 3단계로 구분하고, 등급을 색과 함께 글자 라벨로 표시해야 한다. | F13: Medium | G13: RG-02 | H13: R-4 | I13: 형준 | J13: 확정 | K13: 수정 | L13: v1.0 | N13: MVP
A14: REQ-049 | B14: 기능 | C14: 안전성점검 | D14: 다제약물 경고 | E14: 시스템은 복용 약이 기준 개수 이상이면 여러 약을 함께 먹고 있다는 사실과 약사 상담을 안내해야 한다. | F14: Medium | G14: RG-02 | H14: R-4 | I14: 형준 | J14: 팀 확인 필요 | K14: 신규 | L14: v1.0 | M14: 기준 개수 5개 검토 중 | N14: MVP
A15: REQ-050 | B15: 기능 | C15: 안내문생성 | D15: 복약 안내문 생성 | E15: 시스템은 약품별로 무엇에 쓰나요 / 어떻게 먹나요 / 주의할 점 / 출처를 같은 순서로, 비전문가가 이해할 수 있는 문장으로 생성해야 한다. | F15: High | G15: RG-04 | H15: R-4 | I15: 형준 | J15: 확정 | K15: 수정 | L15: v1.0 | M15: 참여기업 필수 요구사항 | N15: MVP
A16: REQ-051 | B16: 기능 | C16: 안내문생성 | D16: 근거 기반 생성 | E16: 시스템은 식약처 허가정보에 근거한 내용만 생성해야 하며 근거가 없는 내용은 생성하지 않아야 한다. | F16: High | G16: RG-04 | H16: R-4 | I16: 형준 | J16: 확정 | K16: 기존 | L16: v0.1 | M16: 환각 방지 (RAG) | N16: MVP
A17: REQ-052 | B17: 기능 | C17: 안내문생성 | D17: 출처 표시 | E17: 시스템은 생성된 안내문에 근거 출처(식약처 허가정보 등)를 표시해야 한다. | F17: High | G17: RG-03 · RG-04 | H17: R-4 · R-5 | I17: 형준 | J17: 확정 | K17: 기존 | L17: v0.1 | N17: MVP
A18: REQ-053 | B18: 기능 | C18: 안내문생성 | D18: 면책 문구 표시 | E18: 시스템은 모든 안내문에 의학적 진단·처방이 아님을 명시하는 문구를 표시해야 한다. | F18: High | G18: CM-03 · RG-02~05 | H18: R-4 | I18: 형준 | J18: 확정 | K18: 기존 | L18: v0.1 | M18: 의료 서비스 필수 | N18: MVP
A19: REQ-054 | B19: 기능 | C19: 안내문생성 | D19: 생성 진행 상태 표시 | E19: 시스템은 분석 중 약 정보 확인 / 안전성 점검 / 안내문 작성 단계와 각 상태(완료 · 진행 중 · 대기)를 화면에 표시해야 한다. | F19: High | G19: RG-01 | H19: R-2 | I19: 형준 | J19: 확정 | K19: 수정 | L19: v1.0 | M19: 수십 초 소요 - 비동기 처리 | N19: MVP
A20: REQ-055 | B20: 기능 | C20: 안내문생성 | D20: 생성 실패 처리 | E20: 시스템은 분석 실패 시 실패한 단계와 사유를 안내하고, 실패한 단계부터 다시 시도할 수 있게 해야 한다. 3회 연속 실패 시 재시도를 막는다. | F20: High | G20: RG-01-E1 | H20: R-2 · R-3 | I20: 형준 | J20: 확정 | K20: 수정 | L20: v1.0 | M20: 예외 처리 | N20: MVP
A21: REQ-056 | B21: 기능 | C21: 안내문생성 | D21: 부분 결과 제공 | E21: 시스템은 안내문 작성만 실패한 경우에도 이미 끝난 안전성 점검 결과를 먼저 보여줄 수 있어야 한다. | F21: High | G21: RG-01-E1 · RG-02 | H21: R-2 · R-4 | I21: 형준 | J21: 확정 | K21: 신규 | L21: v1.0 | M21: 경고는 AI를 거치지 않아 먼저 나올 수 있음 | N21: MVP
A22: REQ-057 | B22: 기능 | C22: 안내문생성 | D22: 확인된 위험 없음 안내 | E22: 시스템은 경고가 0건일 때 "안전하다"고 단정하지 않고 "확인된 위험이 없다"는 문구, 점검한 항목 목록, 자료의 한계를 함께 보여줘야 한다. | F22: High | G22: RG-02-E1 | H22: R-4 | I22: 형준 | J22: 확정 | K22: 신규 | L22: v1.0 | M22: 와이어프레임에서 추가 | N22: MVP
A23: REQ-058 | B23: 기능 | C23: 안내문생성 | D23: 분석 중 화면 이탈 허용 | E23: 사용자는 분석 중 화면을 떠날 수 있어야 하며, 분석은 계속 진행되고 홈의 최근 분석 카드에 "분석 중"으로 표시된다. | F23: Medium | G23: RG-01 · CM-03 | H23: R-2 · R-7 | I23: 형준 | J23: 확정 | K23: 신규 | L23: v1.0 | M23: 비동기 처리(NFR-002) | N23: MVP
A24: REQ-060 | B24: 기능 | C24: 생활습관 | D24: 질환별 생활습관 가이드 | E24: 시스템은 인식된 상병코드에 해당하는 생활습관 개선 가이드를 제공해야 한다. 실천 항목마다 근거 출처(기관 · 문서명 · 판 · 발행일 · URL)를 함께 표시한다. | F24: High | G24: RG-05 | H24: R-4 | I24: 형준 | J24: 확정 | K24: 수정 | L24: v1.3 | M24: 참여기업 필수 요구사항 | N24: MVP
A25: REQ-061 | B25: 기능 | C25: 생활습관 | D25: 복약 연계 가이드 | E25: 시스템은 복용 중인 약물군과 연계한 생활습관 주의사항을 제공해야 한다. 칼륨처럼 신장 기능 · 병용 약에 따라 권고가 달라지는 항목은 "의료진 확인" 안내로만 표시하고 실천 목표로 만들지 않는다. | F25: High | G25: RG-05 | H25: R-4 | I25: 형준 | J25: 확정 | K25: 수정 | L25: v1.3 | M25: 예: 이뇨제 · ACE억제제/ARB와 칼륨 (의료진 확인) / 와파린 복용 시 비타민K | N25: MVP
A26: REQ-062 | B26: 기능 | C26: 생활습관 | D26: 상충 권고 처리 | E26: 시스템은 복수 질환으로 권고가 상충하는 경우 안전한 쪽을 우선하고 의료진 상담을 안내해야 한다. | F26: Medium | G26: RG-05 | H26: R-4 | I26: 형준 | J26: 확정 | K26: 기존 | L26: v0.1 | M26: 예: 고혈압(칼륨 권장) + 신장병(칼륨 제한) | N26: MVP
A27: REQ-063 | B27: 기능 | C27: 생활습관 | D27: 질환 정보 없을 때 처리 | E27: 시스템은 질병분류기호가 없을 때(약봉투 등) 약 기준 주의사항은 그대로 보여주고, 사용자가 해당 질환을 직접 고를 수 있게 해야 한다. 직접 고른 질환은 처방전 코드와 구분해 표시한다. | F27: Medium | G27: RG-05-E1 | H27: R-6 | I27: 형준 | J27: 팀 확인 필요 | K27: 신규 | L27: v1.0 | M27: 질환 선택이 진단처럼 보이지 않도록 문구 검토 | N27: MVP
A28: REQ-090 | B28: 기능 | C28: 피드백 | D28: 안내문 평가 | E28: 사용자는 생성된 안내문에 대해 도움됨/도움안됨을 평가할 수 있어야 한다. | F28: High | G28: RG-04 | H28: R-9 | I28: 형준 | J28: 확정 | K28: 기존 | L28: v0.1 | M28: 평가항목 3-4 대응 | N28: MVP
A29: REQ-091 | B29: 기능 | C29: 피드백 | D29: 의견 입력 | E29: 사용자는 평가와 함께 의견을 텍스트로 입력할 수 있어야 한다. | F29: Medium | G29: RG-04 | H29: R-9 | I29: 형준 | J29: 확정 | K29: 기존 | L29: v0.1 | N29: MVP
A30: REQ-092 | B30: 기능 | C30: 피드백 | D30: 피드백 저장·활용 | E30: 시스템은 수집된 피드백을 저장하고 프롬프트 개선에 활용할 수 있어야 한다. | F30: Medium | G30: — | H30: R-9 | I30: 형준 | J30: 확정 | K30: 기존 | L30: v0.1 | M30: 평가항목 3-4 대응 | N30: MVP
A31: REQ-100 | B31: 기능 | C31: 음성변환 | D31: 안내문 음성 변환 | E31: 사용자는 생성된 안내문을 음성으로 들을 수 있어야 한다. | F31: Low | G31: RG-04 | H31: R-10 | I31: 형준 | J31: 선택 구현 | K31: 기존 | L31: v0.1 | M31: 선택 구현 - 고령 타겟 접근성 | N31: 후순위
A32: REQ-101 | B32: 기능 | C32: 음성변환 | D32: 재생 제어 | E32: 사용자는 음성 재생을 일시정지하고 재생 속도를 조절할 수 있어야 한다. | F32: Low | G32: RG-04 | H32: R-10 | I32: 형준 | J32: 선택 구현 | K32: 기존 | L32: v0.1 | M32: 선택 구현 | N32: 후순위

Sheet 챗봇
A1: 요구사항 정의서 v1.4 · 챗봇
A2: 수인 · 실시간 챗봇 · 관련 화면 CB · 행을 바꾸면 "변경 이력" 탭에 한 줄 추가
A4: ID | B4: 구분 | C4: 카테고리 | D4: 요구사항 명칭 | E4: 상세 내용 | F4: 우선순위 | G4: 관련 화면 | H4: 관련 API | I4: 담당 | J4: 상태 | K4: 변경 | L4: 최종 수정 | M4: 비고 | N4: MVP (제안)
A5: REQ-070 | B5: 기능 | C5: 챗봇 | D5: 실시간 질의응답 | E5: 사용자는 복용 중인 약과 건강에 대해 챗봇으로 질문하고 답변을 받을 수 있어야 한다. | F5: High | G5: CB-01 · CB-01-E1 | H5: H-1 · H-3 | I5: 수인 | J5: 확정 | K5: 기존 | L5: v0.1 | M5: 참여기업 필수 요구사항 | N5: MVP
A6: REQ-071 | B6: 기능 | C6: 챗봇 | D6: 대화 맥락 반영 | E6: 챗봇은 동일 세션의 이전 대화 내용을 반영하여 답변해야 한다. | F6: High | G6: CB-01 | H6: H-2 · H-3 | I6: 수인 | J6: 확정 | K6: 기존 | L6: v0.1 | M6: 참여기업 필수 요구사항에 명시 | N6: MVP
A7: REQ-072 | B7: 기능 | C7: 챗봇 | D7: 분석 결과 연계 | E7: 챗봇은 사용자의 복약 정보와 안전성 점검 결과를 근거로 답변해야 한다. | F7: High | G7: CB-01 · CB-01-E2 | H7: H-1 | I7: 수인 | J7: 확정 | K7: 기존 | L7: v0.1 | N7: MVP
A8: REQ-073 | B8: 기능 | C8: 챗봇 | D8: 답변 불가 처리 | E8: 챗봇은 근거를 찾지 못한 질문에 대해 임의로 답변하지 않고 의료진 상담을 안내해야 한다. | F8: High | G8: CB-01 | H8: H-3 | I8: 수인 | J8: 팀 확인 필요 | K8: 기존 | L8: v0.1 | M8: "확인이 어렵습니다" 처리 조건 · 문구 팀 논의 | N8: MVP
A9: REQ-074 | B9: 기능 | C9: 챗봇 | D9: 진단·처방 요청 거절 | E9: 챗봇은 진단이나 처방 변경을 요구하는 질문에 대해 답변하지 않고 의료진 상담을 안내해야 한다. | F9: High | G9: CB-01 | H9: H-3 | I9: 수인 | J9: 팀 확인 필요 | K9: 기존 | L9: v0.1 | M9: "의료진 상담 필요" 처리 조건 · 문구 팀 논의 | N9: MVP
A10: REQ-075 | B10: 기능 | C10: 챗봇 | D10: 분석 결과 맥락으로 대화 시작 | E10: 사용자가 경고 · 약 화면에서 챗봇으로 넘어가면, 챗봇은 해당 분석 결과와 질문 대상(경고 · 약)을 알고 대화를 시작하고 이를 화면에 표시해야 한다. | F10: High | G10: CB-01-E2 | H10: H-1 | I10: 수인 | J10: 확정 | K10: 신규 | L10: v1.0 | M10: 와이어프레임에서 추가 (REQ-072 연계) | N10: MVP
A11: REQ-076 | B11: 기능 | C11: 챗봇 | D11: 추천 질문 | E11: 시스템은 대화 기록이 없을 때 추천 질문을 보여주고, 누르면 그 질문으로 대화를 시작해야 한다. | F11: Low | G11: CB-01-E1 | H11: H-1 | I11: 수인 | J11: 팀 확인 필요 | K11: 신규 | L11: v1.0 | M11: 추천 질문 문구 확정 필요 | N11: 후순위
A12: REQ-077 | B12: 기능 | C12: 챗봇 | D12: 대화 기록 달력 · 목록 | E12: 사용자는 날짜별로 지난 대화를 찾아보고, 대화 제목을 수정 · 공유 · 내보낼 수 있어야 한다. 공유 시 건강 정보가 함께 전달된다는 경고를 표시한다. | F12: Low | G12: CB-02 · CB-03 | H12: 추가 필요 | I12: 수인 | J12: 선택 구현 | K12: 신규 | L12: v1.0 | M12: 날짜별 여러 대화 구조로 바꿀지 팀 확정 필요 (API · ERD 영향) | N12: 후순위
A13: REQ-078 | B13: 기능 | C13: 챗봇 | D13: 음성 질문 입력 | E13: 사용자는 말로 질문을 입력할 수 있어야 하며, 인식에 실패하면 다시 말하기 또는 글자 입력을 선택할 수 있다. | F13: Low | G13: CB-05 · CB-05-E1 | H13: — | I13: 수인 | J13: 선택 구현 | K13: 신규 | L13: v1.0 | M13: REQ-100(안내문 읽어주기)와 별개 | N13: 후순위
A14: REQ-079 | B14: 기능 | C14: 챗봇 | D14: 사진 · 파일 첨부 | E14: 사용자는 대화 중 사진 · 파일을 첨부할 수 있어야 한다. 처방전 · 약봉투는 촬영 · 업로드 화면에서 올리도록 안내한다. | F14: Low | G14: CB-04 | H14: 미정 | I14: 수인 | J14: 선택 구현 | K14: 신규 | L14: v1.0 | M14: 구현 여부 미정 (스트레치) | N14: 후순위

Sheet 실천·보상
A1: 요구사항 정의서 v1.4 · 실천·보상
A2: 성규 · 추천 · 목표 · 실천 기록 · 포인트 · 관련 화면 RW · 행을 바꾸면 "변경 이력" 탭에 한 줄 추가
A4: ID | B4: 구분 | C4: 카테고리 | D4: 요구사항 명칭 | E4: 상세 내용 | F4: 우선순위 | G4: 관련 화면 | H4: 관련 API | I4: 담당 | J4: 상태 | K4: 변경 | L4: 최종 수정 | M4: 비고 | N4: MVP (제안)
A5: REQ-110 | B5: 기능 | C5: 실천·보상 | D5: 생활습관 추천 결과 | E5: 시스템은 분석 결과의 질환 · 복용 약을 기준으로 생활습관 팩트 테이블에서 실천 목표를 최대 3개 추천하고, 추천 이유(질환 · 약)를 라벨로 표시해야 한다. | F5: High | G5: RG-05 | H5: GET /recommendations | I5: 성규 | J5: 팀 확인 필요 | K5: 신규 | L5: v1.4 | M5: RW-01 제외 확정 (2026-09-28, 한성규) — RG-05 [이 목표로 실천 시작하기]에서 RW-02로 바로 연결. 원 REQ-HABIT-001 | N5: MVP
A6: REQ-111 | B6: 기능 | C6: 실천·보상 | D6: 실천 목표 선택 | E6: 사용자는 추천 중 최대 3개를 이번 주 실천 목표로 직접 선택할 수 있어야 한다. 0개면 시작할 수 없다. | F6: High | G6: RW-02 | H6: POST /habit-goals | I6: 성규 | J6: 확정 | K6: 신규 | L6: v1.0 | M6: 원 REQ-HABIT-002 | N6: MVP
A7: REQ-112 | B7: 기능 | C7: 실천·보상 | D7: 오늘의 실천 기록 | E7: 사용자는 오늘의 목표를 체크형(완료) 또는 수량형(걷기 분 등)으로 기록할 수 있어야 한다. 같은 날 같은 목표의 중복 완료는 무시하고, 목표가 없으면 분석을 안내한다. | F7: High | G7: RW-03 · RW-03-E2 · RW-04 | H7: GET /habit-goals/today · POST /habit-goals/{id}/records | I7: 성규 | J7: 확정 | K7: 신규 | L7: v1.3 | M7: RW-03 · RW-04 · RW-05를 한 화면의 상태(미실천 · 일부 완료 · 전체 완료)로 합치는 안 (v1.3 · 성규 확인). 원 REQ-HABIT-003 · 004 | N7: MVP
A8: REQ-113 | B8: 기능 | C8: 실천·보상 | D8: 포인트 지급 | E8: 시스템은 목표 완료 시 포인트를 지급하고, 하루 목표를 모두 완료하면 추가 포인트를 지급하되 같은 날 중복 지급하지 않아야 한다. | F8: High | G8: RW-04 · RW-05 | H8: POST /habit-goals/{id}/records · GET /rewards/summary | I8: 성규 | J8: 확정 | K8: 신규 | L8: v1.0 | M8: 원 REQ-REWARD-001 · 002 | N8: 후순위
A9: REQ-114 | B9: 기능 | C9: 실천·보상 | D9: 달성 현황 | E9: 사용자는 이번 주 요일별 실천 여부, 달성률, 연속 실천일, 이번 주 · 누적 포인트를 확인할 수 있어야 한다. 기록이 없으면 다음 할 일을 안내한다. | F9: Medium | G9: RW-06 · RW-06-E1 | H9: GET /habit-goals/history · GET /rewards/summary | I9: 성규 | J9: 확정 | K9: 신규 | L9: v1.0 | M9: 원 REQ-HABIT-005 · REWARD-003 | N9: 후순위
A10: REQ-115 | B10: 기능 | C10: 실천·보상 | D10: 기록 저장 실패 재시도 | E10: 시스템은 실천 기록 저장에 실패하면 화면 안 배너로 알리고 같은 요청을 다시 시도할 수 있게 해야 한다. | F10: Medium | G10: RW-03-E1 | H10: POST /habit-goals/{id}/records | I10: 성규 | J10: 확정 | K10: 신규 | L10: v1.0 | M10: 신규 | N10: MVP
A11: REQ-116 | B11: 기능 | C11: 실천·보상 | D11: 주간 목표 다시 고르기 | E11: 사용자는 한 주가 끝나면 목표를 이어가거나 다시 고를 수 있어야 한다. | F11: Medium | G11: RW-02 | H11: POST /habit-goals | I11: 성규 | J11: 팀 확인 필요 | K11: 신규 | L11: v1.0 | M11: 흐름 미정 | N11: 후순위
A12: REQ-117 | B12: 기능 | C12: 실천·보상 | D12: 실천 기록 검증 | E12: 시스템은 몰아서 체크하는 등 비정상 기록 패턴을 감지해 표시할 수 있어야 한다. | F12: Low | G12: RW-03 | H12: — | I12: 성규 | J12: 팀 확인 필요 | K12: 신규 | L12: v1.0 | M12: 기술 깊이 확보용 · 팀 논의 | N12: 후순위

Sheet 비기능
A1: 요구사항 정의서 v1.4 · 비기능
A2: 공통 · 성능 · 보안 · 사용성 · 품질 · 운영 · 확장성 · 관련 화면 전 화면 · 행을 바꾸면 "변경 이력" 탭에 한 줄 추가
A4: ID | B4: 구분 | C4: 카테고리 | D4: 요구사항 명칭 | E4: 상세 내용 | F4: 우선순위 | G4: 관련 화면 | H4: 관련 API | I4: 담당 | J4: 상태 | K4: 변경 | L4: 최종 수정 | M4: 비고 | N4: MVP (제안)
A5: NFR-001 | B5: 비기능 | C5: 성능 | D5: API 응답 시간 | E5: 전체 API의 P95 Latency는 3초 이내여야 한다. | F5: High | G5: — | H5: 전체 | I5: 성규 | J5: 확정 | K5: 기존 | L5: v0.1 | M5: 참여기업 평가 기준 | N5: MVP
A6: NFR-002 | B6: 비기능 | C6: 성능 | D6: 비동기 처리 | E6: 안내문 생성 · OCR 요청은 즉시 작업 ID를 반환하고 결과는 폴링으로 조회한다. | F6: High | G6: RG-01 · OC-01 | H6: R-1 · R-2 · O-1 · O-5 | I6: 형준 | J6: 확정 | K6: 수정 | L6: v1.3 | M6: NFR-001 충족 수단 | N6: MVP
A7: NFR-003 | B7: 비기능 | C7: 성능 | D7: 안전성 점검 응답 | E7: 병용금기 등 DB 조회 기반 점검은 1초 이내에 완료되어야 한다. | F7: High | G7: RG-02 | H7: R-4 | I7: 형준 | J7: 확정 | K7: 기존 | L7: v0.1 | M7: 관계형 조회 | N7: MVP
A8: NFR-004 | B8: 비기능 | C8: 성능 | D8: 동시 사용자 | E8: 시스템은 동시 접속 30명 환경에서 정상 동작해야 한다. | F8: Low | G8: — | H8: 전체 | I8: 성규 | J8: 확정 | K8: 수정 | L8: v1.2 | M8: 데모데이 대비 · 우선순위 조정: 일반 구현 | N8: MVP
A9: NFR-005 | B9: 비기능 | C9: 성능 | D9: 캐싱 | E9: 동일 약품에 대한 조회 결과는 캐싱하여 중복 API 호출을 방지한다. 단 개인 맞춤 안내문은 캐싱하지 않는다. | F9: Low | G9: — | H9: 전체 | I9: 형준 | J9: 확정 | K9: 수정 | L9: v1.2 | M9: 우선순위 조정: 일반 구현 | N9: MVP
A10: NFR-010 | B10: 비기능 | C10: 보안 | D10: 인증·인가 | E10: 시스템은 JWT 기반 인증을 적용하고 본인의 진료기록만 조회할 수 있어야 한다. | F10: Medium | G10: — | H10: 전체 | I10: 성규 | J10: 확정 | K10: 수정 | L10: v1.2 | M10: 평가 기준 5-4 · 우선순위 조정: 보안 — 본인 데이터만 조회하는 기본만 | N10: MVP
A11: NFR-011 | B11: 비기능 | C11: 보안 | D11: 원본 이미지 미저장 | E11: 업로드된 원본 이미지는 OCR 처리 후 즉시 폐기하며 저장하지 않는다. | F11: Low | G11: OC-01 · CM-04 | H11: O-1 | I11: 채연 | J11: 팀 확인 필요 | K11: 수정 | L11: v1.2 | M11: ※ 멘토링 확인 필요. 원본을 저장하지 않으면 실패 기록은 다시 찍어야 함 (CM-04) · 우선순위 조정: 개인정보 | N11: MVP
A12: NFR-012 | B12: 비기능 | C12: 보안 | D12: 추출 정보 암호화 | E12: 추출된 진료 정보는 암호화하여 저장해야 한다. | F12: Low | G12: — | H12: 전체 | I12: 성규 | J12: 확정 | K12: 수정 | L12: v1.2 | M12: 우선순위 조정: 보안 | N12: MVP
A13: NFR-013 | B13: 비기능 | C13: 보안 | D13: 식별정보 마스킹 | E13: 성명 주민등록번호 등 식별정보는 저장 전 마스킹 처리한다. | F13: Low | G13: — | H13: O-1 | I13: 채연 | J13: 확정 | K13: 수정 | L13: v1.2 | M13: 우선순위 조정: 개인정보 | N13: MVP
A14: NFR-014 | B14: 비기능 | C14: 보안 | D14: 통신 암호화 | E14: 모든 통신은 HTTPS로 암호화한다. | F14: Low | G14: — | H14: 전체 | I14: 성규 | J14: 확정 | K14: 수정 | L14: v1.2 | M14: 우선순위 조정: 보안 — 배포 환경 기본값 사용 | N14: MVP
A15: NFR-020 | B15: 비기능 | C15: 사용성 | D15: 모바일 우선 설계 | E15: 모든 화면은 모바일 폭 375px 기준으로 설계한다. 세로 길이는 내용에 따라 늘어난다. | F15: High | G15: 전 화면 | H15: — | I15: 공통 | J15: 확정 | K15: 수정 | L15: v1.0 | M15: 보류 해제 — 플랫폼 모바일 확정 | N15: MVP
... A27: NFR-051 | B27: 비기능 | C27: 확장성 | D27: 질환 확장 | E27: 생활습관 가이드는 질환 추가 시 데이터만 추가하면 되는 구조로 설계한다. | F27: Medium | G27: — | H27: — | I27: 형준 | J27: 확정 | K27: 기존 | L27: v0.1 | M27: 평가 기준 2-2 | N27: MVP
